Workbook
Name ___xlnm.Print_Area: NA()
Name __xlnm.Print_Area: NA()
Name _1150807A1: #REF!
Name _1150810A1: #REF!
Name _1150810A2: #REF!
Name _1150901A1: #REF!
Name _1150907A2: #REF!
Name _1150908A2: #REF!
Name _1150910A1: #REF!
Name _1150923A1: #REF!
Name _1151001A1: #REF!
Name _1151005A1: #REF!
Name _1151008A1: #REF!
Name _1151012A1: #REF!
Name _1151014A2: #REF!
Name _1151015A1: #REF!
Name _1151015A2: #REF!
Name _1151101A1: #REF!
Name _1151101A2: #REF!
Name _1151102A1: #REF!
Name _1151103A1: #REF!
Name _1151104A2: #REF!
Name _1151106A1: #REF!
Name _1151109A1: #REF!
Name _1151110A2: #REF!
Name _1151112A1: #REF!
Name _1151113A1: #REF!
Name _1151113A2: #REF!
Name _1151201A1: #REF!
Name _1151201A2: #REF!
Name _1151203A1: #REF!
Name _1160502B1: #REF!
Name _200X: #REF!
Name _2151113B2: #REF!
Name _2151113B3: #REF!
Name _2151113B4: #REF!
Name _215111B1: #REF!
Name _215111B2: #REF!
Name _215111B3_4: #REF!
Name _2151201B1_2: #REF!
Name _2151201B3_4: #REF!
Name _2151201B5_6: #REF!
Name _2151201B7_8: #REF!
Name _2151201B9_10: #REF!
Name _2151202B4: #REF!
Name _2151202B5: #REF!
Name _2151205B1_2: #REF!
Name _2151205B3: #REF!
Name _2151205B4: #REF!
Name _2151205B5: #REF!
Name _2151209B1: #REF!
Name _2151209B2: #REF!
Name _2151209B3: #REF!
Name _2160105B1: #REF!
Name _2160105B6: #REF!
Name _2160105B7: #REF!
Name _2160105B8: #REF!
Name _2160106B1: #REF!
Name _2160106B4: #REF!
Name _2160106B5: #REF!

Sheet 0831.
A1: PT咬蝕量量測記錄表 | G1: PT咬蝕量量測記錄表 | R1: QE咬蝕量量測記錄表 | X1: QE咬蝕量量測記錄表
A2: PT-01 | G2: PT-02 | R2: QE-01 | X2: QE-02
A3: OP | B3: 1 | C3: 2 | D3: 3 | E3: 4 | F3: 5 | G3: OP | H3: 1 | I3: 2 | J3: 3 | K3: 4 | L3: 5 | M3: 6 | N3: 7 | O3: 8 | P3: 9 | Q3: 10 | R3: OP | S3: 1 | T3: 2 | U3: 3 | V3: 4 | W3: 5 | X3: OP | Y3: 1 | Z3: 2 | AA3: 3 | AB3: 4 | AC3: 5 | AD3: 6 | AE3: 7 | AF3: 8 | AG3: 9 | AH3: 10
A4: BEFORE | G4: BEFORE | R4: BEFORE | X4: BEFORE
A14: AFTER | G14: AFTER | R14: AFTER | X14: AFTER
A25: 項次 | B25: 單位 | C25: 規格 | E25: 數值 | G25: 項次 | H25: 單位 | I25: 規格 | K25: 數值 | R25: 項次 | S25: 單位 | T25: 規格 | V25: 數值 | X25: 項次 | Y25: 單位 | Z25: 規格 | AB25: 數值
A26: 咬蝕量 | B26: um | C26: 0.3 | D26: ±0.1 | E26: =AVERAGE(B4:F13)-AVERAGE(B14:F23) -> #DIV/0! | G26: 咬蝕量 | H26: um | I26: 0.3 | J26: ±0.1 | K26: =AVERAGE(H4:Q13)-AVERAGE(H14:Q23) -> #DIV/0! | R26: 咬蝕量 | S26: um | T26: 1.07 | U26: ±0.21 | V26: =AVERAGE(S4:W13)-AVERAGE(S14:W23) -> #DIV/0! | X26: 咬蝕量 | Y26: um | Z26: 1.38 | AA26: ±0.23 | AB26: =AVERAGE(Y4:AH13)-AVERAGE(Y14:AH23) -> #DIV/0!
A27: 線速 | B27: M/min | C27: ="--" -> -- | E27: 1.7 | G27: 線速 | H27: M/min | I27: ="--" -> -- | K27: 1.5 | R27: 線速 | S27: M/min | T27: ="--" -> -- | V27: 1.4 | X27: 線速 | Y27: M/min | Z27: ="--" -> -- | AB27: 1.5
A28: 咬蝕速率 | B28: um/min | C28: 0.52±0.15 | E28: =(E26/(0.975/E27)) -> #DIV/0! | G28: 咬蝕速率 | H28: um/min | I28: 0.46±0.10 | K28: =(K26/(0.975/K27)) -> #DIV/0! | R28: 咬蝕速率 | S28: um/min | T28: 0.77±0.15 | V28: =(V26/(1.944/V27)) -> #DIV/0! | X28: 咬蝕速率 | Y28: um/min | Z28: 0.9±0.15 | AB28: =(AB26/(2.268/AB27)) -> #DIV/0!
A29: 生產速度(SPEED) | B29: M/min | C29: =0.972*E28/C26 -> #DIV/0! | E29: 以咬蝕量0.3um計算線速 | G29: 生產速度(SPEED) | H29: M/min | I29: =0.972*K28/I26 -> #DIV/0! | K29: 以咬蝕量0.3um計算線速 | R29: 生產速度(SPEED) | S29: M/min | T29: =1.944*V28/1.8 -> #DIV/0! | V29: 以咬蝕量1.8um計算線速 | X29: 生產速度(SPEED) | Y29: M/min | Z29: =2.268*AB28/1.5 -> #DIV/0! | AB29: 以咬蝕量1.5um計算線速
A30: 量測日期 | C30: =TODAY() -> 46251 | R30: 量測日期 | T30: =TODAY() -> 46251
A31: PT-01 | G31: PT-02 | R31: QE-01 | X31: QE-02
A32: 咬蝕量 | G32: 咬蝕量 | R32: 咬蝕量 | X32: 咬蝕量
A33: PT1+ | B33: =B4-B14 -> 0 | C33: =C4-C14 -> 0 | D33: =D4-D14 -> 0 | E33: =E4-E14 -> 0 | F33: =F4-F14 -> 0 | G33: PT2+ | H33: =H4-H14 -> 0 | I33: =I4-I14 -> 0 | J33: =J4-J14 -> 0 | K33: =K4-K14 -> 0 | L33: =L4-L14 -> 0 | M33: =M4-M14 -> 0 | N33: =N4-N14 -> 0 | O33: =O4-O14 -> 0 | ... Q33: =Q4-Q14 -> 0 | R33: PT1+ | S33: =S4-S14 -> 0 | T33: =T4-T14 -> 0 | U33: =U4-U14 -> 0 | V33: =V4-V14 -> 0 | W33: =W4-W14 -> 0 | X33: PT2+ | Y33: =Y4-Y14 -> 0 | Z33: =Z4-Z14 -> 0 | AA33: =AA4-AA14 -> 0 | AB33: =AB4-AB14 -> 0 | AC33: =AC4-AC14 -> 0 | AD33: =AD4-AD14 -> 0 | AE33: =AE4-AE14 -> 0 | AF33: =AF4-AF14 -> 0 | ... AH33: =AH4-AH14 -> 0
B34: =B5-B15 -> 0 | C34: =C5-C15 -> 0 | D34: =D5-D15 -> 0 | E34: =E5-E15 -> 0 | F34: =F5-F15 -> 0 | H34: =H5-H15 -> 0 | I34: =I5-I15 -> 0 | J34: =J5-J15 -> 0 | K34: =K5-K15 -> 0 | L34: =L5-L15 -> 0 | M34: =M5-M15 -> 0 | N34: =N5-N15 -> 0 | O34: =O5-O15 -> 0 | ... Q34: =Q5-Q15 -> 0 | S34: =S5-S15 -> 0 | T34: =T5-T15 -> 0 | U34: =U5-U15 -> 0 | V34: =V5-V15 -> 0 | W34: =W5-W15 -> 0 | Y34: =Y5-Y15 -> 0 | Z34: =Z5-Z15 -> 0 | AA34: =AA5-AA15 -> 0 | AB34: =AB5-AB15 -> 0 | AC34: =AC5-AC15 -> 0 | AD34: =AD5-AD15 -> 0 | AE34: =AE5-AE15 -> 0 | AF34: =AF5-AF15 -> 0 | ... AH34: =AH5-AH15 -> 0
B35: =B6-B16 -> 0 | C35: =C6-C16 -> 0 | D35: =D6-D16 -> 0 | E35: =E6-E16 -> 0 | F35: =F6-F16 -> 0 | H35: =H6-H16 -> 0 | I35: =I6-I16 -> 0 | J35: =J6-J16 -> 0 | K35: =K6-K16 -> 0 | L35: =L6-L16 -> 0 | M35: =M6-M16 -> 0 | N35: =N6-N16 -> 0 | O35: =O6-O16 -> 0 | ... Q35: =Q6-Q16 -> 0 | S35: =S6-S16 -> 0 | T35: =T6-T16 -> 0 | U35: =U6-U16 -> 0 | V35: =V6-V16 -> 0 | W35: =W6-W16 -> 0 | Y35: =Y6-Y16 -> 0 | Z35: =Z6-Z16 -> 0 | AA35: =AA6-AA16 -> 0 | AB35: =AB6-AB16 -> 0 | AC35: =AC6-AC16 -> 0 | AD35: =AD6-AD16 -> 0 | AE35: =AE6-AE16 -> 0 | AF35: =AF6-AF16 -> 0 | ... AH35: =AH6-AH16 -> 0
B36: =B7-B17 -> 0 | C36: =C7-C17 -> 0 | D36: =D7-D17 -> 0 | E36: =E7-E17 -> 0 | F36: =F7-F17 -> 0 | H36: =H7-H17 -> 0 | I36: =I7-I17 -> 0 | J36: =J7-J17 -> 0 | K36: =K7-K17 -> 0 | L36: =L7-L17 -> 0 | M36: =M7-M17 -> 0 | N36: =N7-N17 -> 0 | O36: =O7-O17 -> 0 | ... Q36: =Q7-Q17 -> 0 | S36: =S7-S17 -> 0 | T36: =T7-T17 -> 0 | U36: =U7-U17 -> 0 | V36: =V7-V17 -> 0 | W36: =W7-W17 -> 0 | Y36: =Y7-Y17 -> 0 | Z36: =Z7-Z17 -> 0 | AA36: =AA7-AA17 -> 0 | AB36: =AB7-AB17 -> 0 | AC36: =AC7-AC17 -> 0 | AD36: =AD7-AD17 -> 0 | AE36: =AE7-AE17 -> 0 | AF36: =AF7-AF17 -> 0 | ... AH36: =AH7-AH17 -> 0
B37: =B8-B18 -> 0 | C37: =C8-C18 -> 0 | D37: =D8-D18 -> 0 | E37: =E8-E18 -> 0 | F37: =F8-F18 -> 0 | H37: =H8-H18 -> 0 | I37: =I8-I18 -> 0 | J37: =J8-J18 -> 0 | K37: =K8-K18 -> 0 | L37: =L8-L18 -> 0 | M37: =M8-M18 -> 0 | N37: =N8-N18 -> 0 | O37: =O8-O18 -> 0 | ... Q37: =Q8-Q18 -> 0 | S37: =S8-S18 -> 0 | T37: =T8-T18 -> 0 | U37: =U8-U18 -> 0 | V37: =V8-V18 -> 0 | W37: =W8-W18 -> 0 | Y37: =Y8-Y18 -> 0 | Z37: =Z8-Z18 -> 0 | AA37: =AA8-AA18 -> 0 | AB37: =AB8-AB18 -> 0 | AC37: =AC8-AC18 -> 0 | AD37: =AD8-AD18 -> 0 | AE37: =AE8-AE18 -> 0 | AF37: =AF8-AF18 -> 0 | ... AH37: =AH8-AH18 -> 0
A38: PT1- | B38: =B9-B19 -> 0 | C38: =C9-C19 -> 0 | D38: =D9-D19 -> 0 | E38: =E9-E19 -> 0 | F38: =F9-F19 -> 0 | G38: PT2- | H38: =H9-H19 -> 0 | I38: =I9-I19 -> 0 | J38: =J9-J19 -> 0 | K38: =K9-K19 -> 0 | L38: =L9-L19 -> 0 | M38: =M9-M19 -> 0 | N38: =N9-N19 -> 0 | O38: =O9-O19 -> 0 | ... Q38: =Q9-Q19 -> 0 | R38: PT1- | S38: =S9-S19 -> 0 | T38: =T9-T19 -> 0 | U38: =U9-U19 -> 0 | V38: =V9-V19 -> 0 | W38: =W9-W19 -> 0 | X38: PT2- | Y38: =Y9-Y19 -> 0 | Z38: =Z9-Z19 -> 0 | AA38: =AA9-AA19 -> 0 | AB38: =AB9-AB19 -> 0 | AC38: =AC9-AC19 -> 0 | AD38: =AD9-AD19 -> 0 | AE38: =AE9-AE19 -> 0 | AF38: =AF9-AF19 -> 0 | ... AH38: =AH9-AH19 -> 0
B39: =B10-B20 -> 0 | C39: =C10-C20 -> 0 | D39: =D10-D20 -> 0 | E39: =E10-E20 -> 0 | F39: =F10-F20 -> 0 | H39: =H10-H20 -> 0 | I39: =I10-I20 -> 0 | J39: =J10-J20 -> 0 | K39: =K10-K20 -> 0 | L39: =L10-L20 -> 0 | M39: =M10-M20 -> 0 | N39: =N10-N20 -> 0 | O39: =O10-O20 -> 0 | ... Q39: =Q10-Q20 -> 0 | S39: =S10-S20 -> 0 | T39: =T10-T20 -> 0 | U39: =U10-U20 -> 0 | V39: =V10-V20 -> 0 | W39: =W10-W20 -> 0 | Y39: =Y10-Y20 -> 0 | Z39: =Z10-Z20 -> 0 | AA39: =AA10-AA20 -> 0 | AB39: =AB10-AB20 -> 0 | AC39: =AC10-AC20 -> 0 | AD39: =AD10-AD20 -> 0 | AE39: =AE10-AE20 -> 0 | AF39: =AF10-AF20 -> 0 | ... AH39: =AH10-AH20 -> 0
B40: =B11-B21 -> 0 | C40: =C11-C21 -> 0 | D40: =D11-D21 -> 0 | E40: =E11-E21 -> 0 | F40: =F11-F21 -> 0 | H40: =H11-H21 -> 0 | I40: =I11-I21 -> 0 | J40: =J11-J21 -> 0 | K40: =K11-K21 -> 0 | L40: =L11-L21 -> 0 | M40: =M11-M21 -> 0 | N40: =N11-N21 -> 0 | O40: =O11-O21 -> 0 | ... Q40: =Q11-Q21 -> 0 | S40: =S11-S21 -> 0 | T40: =T11-T21 -> 0 | U40: =U11-U21 -> 0 | V40: =V11-V21 -> 0 | W40: =W11-W21 -> 0 | Y40: =Y11-Y21 -> 0 | Z40: =Z11-Z21 -> 0 | AA40: =AA11-AA21 -> 0 | AB40: =AB11-AB21 -> 0 | AC40: =AC11-AC21 -> 0 | AD40: =AD11-AD21 -> 0 | AE40: =AE11-AE21 -> 0 | AF40: =AF11-AF21 -> 0 | ... AH40: =AH11-AH21 -> 0
B41: =B12-B22 -> 0 | C41: =C12-C22 -> 0 | D41: =D12-D22 -> 0 | E41: =E12-E22 -> 0 | F41: =F12-F22 -> 0 | H41: =H12-H22 -> 0 | I41: =I12-I22 -> 0 | J41: =J12-J22 -> 0 | K41: =K12-K22 -> 0 | L41: =L12-L22 -> 0 | M41: =M12-M22 -> 0 | N41: =N12-N22 -> 0 | O41: =O12-O22 -> 0 | ... Q41: =Q12-Q22 -> 0 | S41: =S12-S22 -> 0 | T41: =T12-T22 -> 0 | U41: =U12-U22 -> 0 | V41: =V12-V22 -> 0 | W41: =W12-W22 -> 0 | Y41: =Y12-Y22 -> 0 | Z41: =Z12-Z22 -> 0 | AA41: =AA12-AA22 -> 0 | AB41: =AB12-AB22 -> 0 | AC41: =AC12-AC22 -> 0 | AD41: =AD12-AD22 -> 0 | AE41: =AE12-AE22 -> 0 | AF41: =AF12-AF22 -> 0 | ... AH41: =AH12-AH22 -> 0
B42: =B13-B23 -> 0 | C42: =C13-C23 -> 0 | D42: =D13-D23 -> 0 | E42: =E13-E23 -> 0 | F42: =F13-F23 -> 0 | H42: =H13-H23 -> 0 | I42: =I13-I23 -> 0 | J42: =J13-J23 -> 0 | K42: =K13-K23 -> 0 | L42: =L13-L23 -> 0 | M42: =M13-M23 -> 0 | N42: =N13-N23 -> 0 | O42: =O13-O23 -> 0 | ... Q42: =Q13-Q23 -> 0 | S42: =S13-S23 -> 0 | T42: =T13-T23 -> 0 | U42: =U13-U23 -> 0 | V42: =V13-V23 -> 0 | W42: =W13-W23 -> 0 | Y42: =Y13-Y23 -> 0 | Z42: =Z13-Z23 -> 0 | AA42: =AA13-AA23 -> 0 | AB42: =AB13-AB23 -> 0 | AC42: =AC13-AC23 -> 0 | AD42: =AD13-AD23 -> 0 | AE42: =AE13-AE23 -> 0 | AF42: =AF13-AF23 -> 0 | ... AH42: =AH13-AH23 -> 0
A43: A side- EA | B43: =AVERAGE(B33:F37) -> 0 | C43: R | D43: =MAX(B33:F37)-MIN(B33:F37) -> 0 | E43: ER | F43: =B43/(0.975/E27) -> 0 | G43: A side- EA | H43: =AVERAGE(H33:Q37) -> 0 | I43: R | J43: =MAX(H33:Q37)-MIN(H33:Q37) -> 0 | K43: ER | L43: =H43/(0.975/K27) -> 0 | M43: % | N43: =1-(J43/2*H43) -> 1 | O43: T-R | P43: =MAX(H33:Q42)-MIN(H33:Q42) -> 0 | R43: A side- EA | S43: =AVERAGE(S33:W37) -> 0 | T43: R | U43: =MAX(S33:W37)-MIN(S33:W37) -> 0 | V43: ER | W43: =S43/(1.944/V27) -> 0 | X43: A side- EA | Y43: =AVERAGE(Y33:AH37) -> 0 | Z43: R | AA43: =MAX(Y33:AH37)-MIN(Y33:AH37) -> 0 | AB43: ER | AC43: =Y43/(2.268/AB27) -> 0 | AD43: % | AE43: =1-(AA43/2*Y43) -> 1 | AF43: T-R | AG43: =MAX(Y33:AH42)-MIN(Y33:AH42) -> 0
A44: B side- EA | B44: =AVERAGE(B39:F42) -> 0 | C44: R | D44: =MAX(B38:F42)-MIN(B38:F42) -> 0 | E44: ER | F44: =B44/(0.975/E27) -> 0 | G44: B side- EA | H44: =AVERAGE(H39:Q42) -> 0 | I44: R | J44: =MAX(H38:Q42)-MIN(H38:Q42) -> 0 | K44: ER | L44: =H44/(0.975/K27) -> 0 | M44: % | N44: =1-(J44/2*H44) -> 1 | O44: T-% | P44: =1-(P43/2*AVERAGE(H43:H44)) -> 1 | R44: B side- EA | S44: =AVERAGE(S39:W42) -> 0 | T44: R | U44: =MAX(S38:W42)-MIN(S38:W42) -> 0 | V44: ER | W44: =S44/(1.944/V27) -> 0 | X44: B side- EA | Y44: =AVERAGE(Y39:AH42) -> 0 | Z44: R | AA44: =MAX(Y38:AH42)-MIN(Y38:AH42) -> 0 | AB44: ER | AC44: =Y44/(2.268/AB27) -> 0 | AD44: % | AE44: =1-(AA44/2*Y44) -> 1 | AF44: T-% | AG44: =1-(AG43/2*AVERAGE(Y43:Y44)) -> 1
A46: PD-3-581-06B

Sheet 0828.
A1: PT咬蝕量量測記錄表 | G1: PT咬蝕量量測記錄表 | R1: QE咬蝕量量測記錄表 | X1: QE咬蝕量量測記錄表
A2: PT-01 | G2: PT-02 | R2: QE-01 | X2: QE-02
A3: OP | B3: 1 | C3: 2 | D3: 3 | E3: 4 | F3: 5 | G3: OP | H3: 1 | I3: 2 | J3: 3 | K3: 4 | L3: 5 | M3: 6 | N3: 7 | O3: 8 | P3: 9 | Q3: 10 | R3: OP | S3: 1 | T3: 2 | U3: 3 | V3: 4 | W3: 5 | X3: OP | Y3: 1 | Z3: 2 | AA3: 3 | AB3: 4 | AC3: 5 | AD3: 6 | AE3: 7 | AF3: 8 | AG3: 9 | AH3: 10
A4: BEFORE | G4: BEFORE | R4: BEFORE | X4: BEFORE
A14: AFTER | G14: AFTER | R14: AFTER | X14: AFTER
A25: 項次 | B25: 單位 | C25: 規格 | E25: 數值 | G25: 項次 | H25: 單位 | I25: 規格 | K25: 數值 | R25: 項次 | S25: 單位 | T25: 規格 | V25: 數值 | X25: 項次 | Y25: 單位 | Z25: 規格 | AB25: 數值
A26: 咬蝕量 | B26: um | C26: 0.3 | D26: ±0.1 | E26: =AVERAGE(B4:F13)-AVERAGE(B14:F23) -> #DIV/0! | G26: 咬蝕量 | H26: um | I26: 0.3 | J26: ±0.1 | K26: =AVERAGE(H4:Q13)-AVERAGE(H14:Q23) -> #DIV/0! | R26: 咬蝕量 | S26: um | T26: 1.07 | U26: ±0.21 | V26: =AVERAGE(S4:W13)-AVERAGE(S14:W23) -> #DIV/0! | X26: 咬蝕量 | Y26: um | Z26: 1.38 | AA26: ±0.23 | AB26: =AVERAGE(Y4:AH13)-AVERAGE(Y14:AH23) -> #DIV/0!
A27: 線速 | B27: M/min | C27: ="--" -> -- | E27: 1.7 | G27: 線速 | H27: M/min | I27: ="--" -> -- | K27: 1.5 | R27: 線速 | S27: M/min | T27: ="--" -> -- | V27: 1.4 | X27: 線速 | Y27: M/min | Z27: ="--" -> -- | AB27: 1.5
A28: 咬蝕速率 | B28: um/min | C28: 0.52±0.15 | E28: =(E26/(0.975/E27)) -> #DIV/0! | G28: 咬蝕速率 | H28: um/min | I28: 0.46±0.10 | K28: =(K26/(0.975/K27)) -> #DIV/0! | R28: 咬蝕速率 | S28: um/min | T28: 0.77±0.15 | V28: =(V26/(1.944/V27)) -> #DIV/0! | X28: 咬蝕速率 | Y28: um/min | Z28: 0.9±0.15 | AB28: =(AB26/(2.268/AB27)) -> #DIV/0!
A29: 生產速度(SPEED) | B29: M/min | C29: =0.972*E28/C26 -> #DIV/0! | E29: 以咬蝕量0.3um計算線速 | G29: 生產速度(SPEED) | H29: M/min | I29: =0.972*K28/I26 -> #DIV/0! | K29: 以咬蝕量0.3um計算線速 | R29: 生產速度(SPEED) | S29: M/min | T29: =1.944*V28/1.8 -> #DIV/0! | V29: 以咬蝕量1.8um計算線速 | X29: 生產速度(SPEED) | Y29: M/min | Z29: =2.268*AB28/1.5 -> #DIV/0! | AB29: 以咬蝕量1.5um計算線速
A30: 量測日期 | C30: =TODAY() -> 46251 | R30: 量測日期 | T30: =TODAY() -> 46251
A31: PT-01 | G31: PT-02 | R31: QE-01 | X31: QE-02
A32: 咬蝕量 | G32: 咬蝕量 | R32: 咬蝕量 | X32: 咬蝕量
A33: PT1+ | B33: =B4-B14 -> 0 | C33: =C4-C14 -> 0 | D33: =D4-D14 -> 0 | E33: =E4-E14 -> 0 | F33: =F4-F14 -> 0 | G33: PT2+ | H33: =H4-H14 -> 0 | I33: =I4-I14 -> 0 | J33: =J4-J14 -> 0 | K33: =K4-K14 -> 0 | L33: =L4-L14 -> 0 | M33: =M4-M14 -> 0 | N33: =N4-N14 -> 0 | O33: =O4-O14 -> 0 | ... Q33: =Q4-Q14 -> 0 | R33: PT1+ | S33: =S4-S14 -> 0 | T33: =T4-T14 -> 0 | U33: =U4-U14 -> 0 | V33: =V4-V14 -> 0 | W33: =W4-W14 -> 0 | X33: PT2+ | Y33: =Y4-Y14 -> 0 | Z33: =Z4-Z14 -> 0 | AA33: =AA4-AA14 -> 0 | AB33: =AB4-AB14 -> 0 | AC33: =AC4-AC14 -> 0 | AD33: =AD4-AD14 -> 0 | AE33: =AE4-AE14 -> 0 | AF33: =AF4-AF14 -> 0 | ... AH33: =AH4-AH14 -> 0
B34: =B5-B15 -> 0 | C34: =C5-C15 -> 0 | D34: =D5-D15 -> 0 | E34: =E5-E15 -> 0 | F34: =F5-F15 -> 0 | H34: =H5-H15 -> 0 | I34: =I5-I15 -> 0 | J34: =J5-J15 -> 0 | K34: =K5-K15 -> 0 | L34: =L5-L15 -> 0 | M34: =M5-M15 -> 0 | N34: =N5-N15 -> 0 | O34: =O5-O15 -> 0 | ... Q34: =Q5-Q15 -> 0 | S34: =S5-S15 -> 0 | T34: =T5-T15 -> 0 | U34: =U5-U15 -> 0 | V34: =V5-V15 -> 0 | W34: =W5-W15 -> 0 | Y34: =Y5-Y15 -> 0 | Z34: =Z5-Z15 -> 0 | AA34: =AA5-AA15 -> 0 | AB34: =AB5-AB15 -> 0 | AC34: =AC5-AC15 -> 0 | AD34: =AD5-AD15 -> 0 | AE34: =AE5-AE15 -> 0 | AF34: =AF5-AF15 -> 0 | ... AH34: =AH5-AH15 -> 0
B35: =B6-B16 -> 0 | C35: =C6-C16 -> 0 | D35: =D6-D16 -> 0 | E35: =E6-E16 -> 0 | F35: =F6-F16 -> 0 | H35: =H6-H16 -> 0 | I35: =I6-I16 -> 0 | J35: =J6-J16 -> 0 | K35: =K6-K16 -> 0 | L35: =L6-L16 -> 0 | M35: =M6-M16 -> 0 | N35: =N6-N16 -> 0 | O35: =O6-O16 -> 0 | ... Q35: =Q6-Q16 -> 0 | S35: =S6-S16 -> 0 | T35: =T6-T16 -> 0 | U35: =U6-U16 -> 0 | V35: =V6-V16 -> 0 | W35: =W6-W16 -> 0 | Y35: =Y6-Y16 -> 0 | Z35: =Z6-Z16 -> 0 | AA35: =AA6-AA16 -> 0 | AB35: =AB6-AB16 -> 0 | AC35: =AC6-AC16 -> 0 | AD35: =AD6-AD16 -> 0 | AE35: =AE6-AE16 -> 0 | AF35: =AF6-AF16 -> 0 | ... AH35: =AH6-AH16 -> 0
B36: =B7-B17 -> 0 | C36: =C7-C17 -> 0 | D36: =D7-D17 -> 0 | E36: =E7-E17 -> 0 | F36: =F7-F17 -> 0 | H36: =H7-H17 -> 0 | I36: =I7-I17 -> 0 | J36: =J7-J17 -> 0 | K36: =K7-K17 -> 0 | L36: =L7-L17 -> 0 | M36: =M7-M17 -> 0 | N36: =N7-N17 -> 0 | O36: =O7-O17 -> 0 | ... Q36: =Q7-Q17 -> 0 | S36: =S7-S17 -> 0 | T36: =T7-T17 -> 0 | U36: =U7-U17 -> 0 | V36: =V7-V17 -> 0 | W36: =W7-W17 -> 0 | Y36: =Y7-Y17 -> 0 | Z36: =Z7-Z17 -> 0 | AA36: =AA7-AA17 -> 0 | AB36: =AB7-AB17 -> 0 | AC36: =AC7-AC17 -> 0 | AD36: =AD7-AD17 -> 0 | AE36: =AE7-AE17 -> 0 | AF36: =AF7-AF17 -> 0 | ... AH36: =AH7-AH17 -> 0
B37: =B8-B18 -> 0 | C37: =C8-C18 -> 0 | D37: =D8-D18 -> 0 | E37: =E8-E18 -> 0 | F37: =F8-F18 -> 0 | H37: =H8-H18 -> 0 | I37: =I8-I18 -> 0 | J37: =J8-J18 -> 0 | K37: =K8-K18 -> 0 | L37: =L8-L18 -> 0 | M37: =M8-M18 -> 0 | N37: =N8-N18 -> 0 | O37: =O8-O18 -> 0 | ... Q37: =Q8-Q18 -> 0 | S37: =S8-S18 -> 0 | T37: =T8-T18 -> 0 | U37: =U8-U18 -> 0 | V37: =V8-V18 -> 0 | W37: =W8-W18 -> 0 | Y37: =Y8-Y18 -> 0 | Z37: =Z8-Z18 -> 0 | AA37: =AA8-AA18 -> 0 | AB37: =AB8-AB18 -> 0 | AC37: =AC8-AC18 -> 0 | AD37: =AD8-AD18 -> 0 | AE37: =AE8-AE18 -> 0 | AF37: =AF8-AF18 -> 0 | ... AH37: =AH8-AH18 -> 0
A38: PT1- | B38: =B9-B19 -> 0 | C38: =C9-C19 -> 0 | D38: =D9-D19 -> 0 | E38: =E9-E19 -> 0 | F38: =F9-F19 -> 0 | G38: PT2- | H38: =H9-H19 -> 0 | I38: =I9-I19 -> 0 | J38: =J9-J19 -> 0 | K38: =K9-K19 -> 0 | L38: =L9-L19 -> 0 | M38: =M9-M19 -> 0 | N38: =N9-N19 -> 0 | O38: =O9-O19 -> 0 | ... Q38: =Q9-Q19 -> 0 | R38: PT1- | S38: =S9-S19 -> 0 | T38: =T9-T19 -> 0 | U38: =U9-U19 -> 0 | V38: =V9-V19 -> 0 | W38: =W9-W19 -> 0 | X38: PT2- | Y38: =Y9-Y19 -> 0 | Z38: =Z9-Z19 -> 0 | AA38: =AA9-AA19 -> 0 | AB38: =AB9-AB19 -> 0 | AC38: =AC9-AC19 -> 0 | AD38: =AD9-AD19 -> 0 | AE38: =AE9-AE19 -> 0 | AF38: =AF9-AF19 -> 0 | ... AH38: =AH9-AH19 -> 0
B39: =B10-B20 -> 0 | C39: =C10-C20 -> 0 | D39: =D10-D20 -> 0 | E39: =E10-E20 -> 0 | F39: =F10-F20 -> 0 | H39: =H10-H20 -> 0 | I39: =I10-I20 -> 0 | J39: =J10-J20 -> 0 | K39: =K10-K20 -> 0 | L39: =L10-L20 -> 0 | M39: =M10-M20 -> 0 | N39: =N10-N20 -> 0 | O39: =O10-O20 -> 0 | ... Q39: =Q10-Q20 -> 0 | S39: =S10-S20 -> 0 | T39: =T10-T20 -> 0 | U39: =U10-U20 -> 0 | V39: =V10-V20 -> 0 | W39: =W10-W20 -> 0 | Y39: =Y10-Y20 -> 0 | Z39: =Z10-Z20 -> 0 | AA39: =AA10-AA20 -> 0 | AB39: =AB10-AB20 -> 0 | AC39: =AC10-AC20 -> 0 | AD39: =AD10-AD20 -> 0 | AE39: =AE10-AE20 -> 0 | AF39: =AF10-AF20 -> 0 | ... AH39: =AH10-AH20 -> 0
B40: =B11-B21 -> 0 | C40: =C11-C21 -> 0 | D40: =D11-D21 -> 0 | E40: =E11-E21 -> 0 | F40: =F11-F21 -> 0 | H40: =H11-H21 -> 0 | I40: =I11-I21 -> 0 | J40: =J11-J21 -> 0 | K40: =K11-K21 -> 0 | L40: =L11-L21 -> 0 | M40: =M11-M21 -> 0 | N40: =N11-N21 -> 0 | O40: =O11-O21 -> 0 | ... Q40: =Q11-Q21 -> 0 | S40: =S11-S21 -> 0 | T40: =T11-T21 -> 0 | U40: =U11-U21 -> 0 | V40: =V11-V21 -> 0 | W40: =W11-W21 -> 0 | Y40: =Y11-Y21 -> 0 | Z40: =Z11-Z21 -> 0 | AA40: =AA11-AA21 -> 0 | AB40: =AB11-AB21 -> 0 | AC40: =AC11-AC21 -> 0 | AD40: =AD11-AD21 -> 0 | AE40: =AE11-AE21 -> 0 | AF40: =AF11-AF21 -> 0 | ... AH40: =AH11-AH21 -> 0
B41: =B12-B22 -> 0 | C41: =C12-C22 -> 0 | D41: =D12-D22 -> 0 | E41: =E12-E22 -> 0 | F41: =F12-F22 -> 0 | H41: =H12-H22 -> 0 | I41: =I12-I22 -> 0 | J41: =J12-J22 -> 0 | K41: =K12-K22 -> 0 | L41: =L12-L22 -> 0 | M41: =M12-M22 -> 0 | N41: =N12-N22 -> 0 | O41: =O12-O22 -> 0 | ... Q41: =Q12-Q22 -> 0 | S41: =S12-S22 -> 0 | T41: =T12-T22 -> 0 | U41: =U12-U22 -> 0 | V41: =V12-V22 -> 0 | W41: =W12-W22 -> 0 | Y41: =Y12-Y22 -> 0 | Z41: =Z12-Z22 -> 0 | AA41: =AA12-AA22 -> 0 | AB41: =AB12-AB22 -> 0 | AC41: =AC12-AC22 -> 0 | AD41: =AD12-AD22 -> 0 | AE41: =AE12-AE22 -> 0 | AF41: =AF12-AF22 -> 0 | ... AH41: =AH12-AH22 -> 0
B42: =B13-B23 -> 0 | C42: =C13-C23 -> 0 | D42: =D13-D23 -> 0 | E42: =E13-E23 -> 0 | F42: =F13-F23 -> 0 | H42: =H13-H23 -> 0 | I42: =I13-I23 -> 0 | J42: =J13-J23 -> 0 | K42: =K13-K23 -> 0 | L42: =L13-L23 -> 0 | M42: =M13-M23 -> 0 | N42: =N13-N23 -> 0 | O42: =O13-O23 -> 0 | ... Q42: =Q13-Q23 -> 0 | S42: =S13-S23 -> 0 | T42: =T13-T23 -> 0 | U42: =U13-U23 -> 0 | V42: =V13-V23 -> 0 | W42: =W13-W23 -> 0 | Y42: =Y13-Y23 -> 0 | Z42: =Z13-Z23 -> 0 | AA42: =AA13-AA23 -> 0 | AB42: =AB13-AB23 -> 0 | AC42: =AC13-AC23 -> 0 | AD42: =AD13-AD23 -> 0 | AE42: =AE13-AE23 -> 0 | AF42: =AF13-AF23 -> 0 | ... AH42: =AH13-AH23 -> 0
A43: A side- EA | B43: =AVERAGE(B33:F37) -> 0 | C43: R | D43: =MAX(B33:F37)-MIN(B33:F37) -> 0 | E43: ER | F43: =B43/(0.975/E27) -> 0 | G43: A side- EA | H43: =AVERAGE(H33:Q37) -> 0 | I43: R | J43: =MAX(H33:Q37)-MIN(H33:Q37) -> 0 | K43: ER | L43: =H43/(0.975/K27) -> 0 | M43: % | N43: =1-(J43/2*H43) -> 1 | O43: T-R | P43: =MAX(H33:Q42)-MIN(H33:Q42) -> 0 | R43: A side- EA | S43: =AVERAGE(S33:W37) -> 0 | T43: R | U43: =MAX(S33:W37)-MIN(S33:W37) -> 0 | V43: ER | W43: =S43/(1.944/V27) -> 0 | X43: A side- EA | Y43: =AVERAGE(Y33:AH37) -> 0 | Z43: R | AA43: =MAX(Y33:AH37)-MIN(Y33:AH37) -> 0 | AB43: ER | AC43: =Y43/(2.268/AB27) -> 0 | AD43: % | AE43: =1-(AA43/2*Y43) -> 1 | AF43: T-R | AG43: =MAX(Y33:AH42)-MIN(Y33:AH42) -> 0
A44: B side- EA | B44: =AVERAGE(B39:F42) -> 0 | C44: R | D44: =MAX(B38:F42)-MIN(B38:F42) -> 0 | E44: ER | F44: =B44/(0.975/E27) -> 0 | G44: B side- EA | H44: =AVERAGE(H39:Q42) -> 0 | I44: R | J44: =MAX(H38:Q42)-MIN(H38:Q42) -> 0 | K44: ER | L44: =H44/(0.975/K27) -> 0 | M44: % | N44: =1-(J44/2*H44) -> 1 | O44: T-% | P44: =1-(P43/2*AVERAGE(H43:H44)) -> 1 | R44: B side- EA | S44: =AVERAGE(S39:W42) -> 0 | T44: R | U44: =MAX(S38:W42)-MIN(S38:W42) -> 0 | V44: ER | W44: =S44/(1.944/V27) -> 0 | X44: B side- EA | Y44: =AVERAGE(Y39:AH42) -> 0 | Z44: R | AA44: =MAX(Y38:AH42)-MIN(Y38:AH42) -> 0 | AB44: ER | AC44: =Y44/(2.268/AB27) -> 0 | AD44: % | AE44: =1-(AA44/2*Y44) -> 1 | AF44: T-% | AG44: =1-(AG43/2*AVERAGE(Y43:Y44)) -> 1
A46: PD-3-581-06B

Sheet 0827.
A1: PT咬蝕量量測記錄表 | G1: PT咬蝕量量測記錄表 | R1: QE咬蝕量量測記錄表 | X1: QE咬蝕量量測記錄表
A2: PT-01 | G2: PT-02 | R2: QE-01 | X2: QE-02
A3: OP | B3: 1 | C3: 2 | D3: 3 | E3: 4 | F3: 5 | G3: OP | H3: 1 | I3: 2 | J3: 3 | K3: 4 | L3: 5 | M3: 6 | N3: 7 | O3: 8 | P3: 9 | Q3: 10 | R3: OP | S3: 1 | T3: 2 | U3: 3 | V3: 4 | W3: 5 | X3: OP | Y3: 1 | Z3: 2 | AA3: 3 | AB3: 4 | AC3: 5 | AD3: 6 | AE3: 7 | AF3: 8 | AG3: 9 | AH3: 10
A4: BEFORE | G4: BEFORE | R4: BEFORE | X4: BEFORE
A14: AFTER | G14: AFTER | R14: AFTER | X14: AFTER
A25: 項次 | B25: 單位 | C25: 規格 | E25: 數值 | G25: 項次 | H25: 單位 | I25: 規格 | K25: 數值 | R25: 項次 | S25: 單位 | T25: 規格 | V25: 數值 | X25: 項次 | Y25: 單位 | Z25: 規格 | AB25: 數值
A26: 咬蝕量 | B26: um | C26: 0.3 | D26: ±0.1 | E26: =AVERAGE(B4:F13)-AVERAGE(B14:F23) -> #DIV/0! | G26: 咬蝕量 | H26: um | I26: 0.3 | J26: ±0.1 | K26: =AVERAGE(H4:Q13)-AVERAGE(H14:Q23) -> #DIV/0! | R26: 咬蝕量 | S26: um | T26: 1.07 | U26: ±0.21 | V26: =AVERAGE(S4:W13)-AVERAGE(S14:W23) -> #DIV/0! | X26: 咬蝕量 | Y26: um | Z26: 1.38 | AA26: ±0.23 | AB26: =AVERAGE(Y4:AH13)-AVERAGE(Y14:AH23) -> #DIV/0!
A27: 線速 | B27: M/min | C27: ="--" -> -- | E27: 1.7 | G27: 線速 | H27: M/min | I27: ="--" -> -- | K27: 1.5 | R27: 線速 | S27: M/min | T27: ="--" -> -- | V27: 1.4 | X27: 線速 | Y27: M/min | Z27: ="--" -> -- | AB27: 1.5
A28: 咬蝕速率 | B28: um/min | C28: 0.52±0.15 | E28: =(E26/(0.975/E27)) -> #DIV/0! | G28: 咬蝕速率 | H28: um/min | I28: 0.46±0.10 | K28: =(K26/(0.975/K27)) -> #DIV/0! | R28: 咬蝕速率 | S28: um/min | T28: 0.77±0.15 | V28: =(V26/(1.944/V27)) -> #DIV/0! | X28: 咬蝕速率 | Y28: um/min | Z28: 0.9±0.15 | AB28: =(AB26/(2.268/AB27)) -> #DIV/0!
A29: 生產速度(SPEED) | B29: M/min | C29: =0.972*E28/C26 -> #DIV/0! | E29: 以咬蝕量0.3um計算線速 | G29: 生產速度(SPEED) | H29: M/min | I29: =0.972*K28/I26 -> #DIV/0! | K29: 以咬蝕量0.3um計算線速 | R29: 生產速度(SPEED) | S29: M/min | T29: =1.944*V28/1.8 -> #DIV/0! | V29: 以咬蝕量1.8um計算線速 | X29: 生產速度(SPEED) | Y29: M/min | Z29: =2.268*AB28/1.5 -> #DIV/0! | AB29: 以咬蝕量1.5um計算線速
A30: 量測日期 | C30: =TODAY() -> 46251 | R30: 量測日期 | T30: =TODAY() -> 46251
A31: PT-01 | G31: PT-02 | R31: QE-01 | X31: QE-02
A32: 咬蝕量 | G32: 咬蝕量 | R32: 咬蝕量 | X32: 咬蝕量
A33: PT1+ | B33: =B4-B14 -> 0 | C33: =C4-C14 -> 0 | D33: =D4-D14 -> 0 | E33: =E4-E14 -> 0 | F33: =F4-F14 -> 0 | G33: PT2+ | H33: =H4-H14 -> 0 | I33: =I4-I14 -> 0 | J33: =J4-J14 -> 0 | K33: =K4-K14 -> 0 | L33: =L4-L14 -> 0 | M33: =M4-M14 -> 0 | N33: =N4-N14 -> 0 | O33: =O4-O14 -> 0 | ... Q33: =Q4-Q14 -> 0 | R33: PT1+ | S33: =S4-S14 -> 0 | T33: =T4-T14 -> 0 | U33: =U4-U14 -> 0 | V33: =V4-V14 -> 0 | W33: =W4-W14 -> 0 | X33: PT2+ | Y33: =Y4-Y14 -> 0 | Z33: =Z4-Z14 -> 0 | AA33: =AA4-AA14 -> 0 | AB33: =AB4-AB14 -> 0 | AC33: =AC4-AC14 -> 0 | AD33: =AD4-AD14 -> 0 | AE33: =AE4-AE14 -> 0 | AF33: =AF4-AF14 -> 0 | ... AH33: =AH4-AH14 -> 0
B34: =B5-B15 -> 0 | C34: =C5-C15 -> 0 | D34: =D5-D15 -> 0 | E34: =E5-E15 -> 0 | F34: =F5-F15 -> 0 | H34: =H5-H15 -> 0 | I34: =I5-I15 -> 0 | J34: =J5-J15 -> 0 | K34: =K5-K15 -> 0 | L34: =L5-L15 -> 0 | M34: =M5-M15 -> 0 | N34: =N5-N15 -> 0 | O34: =O5-O15 -> 0 | ... Q34: =Q5-Q15 -> 0 | S34: =S5-S15 -> 0 | T34: =T5-T15 -> 0 | U34: =U5-U15 -> 0 | V34: =V5-V15 -> 0 | W34: =W5-W15 -> 0 | Y34: =Y5-Y15 -> 0 | Z34: =Z5-Z15 -> 0 | AA34: =AA5-AA15 -> 0 | AB34: =AB5-AB15 -> 0 | AC34: =AC5-AC15 -> 0 | AD34: =AD5-AD15 -> 0 | AE34: =AE5-AE15 -> 0 | AF34: =AF5-AF15 -> 0 | ... AH34: =AH5-AH15 -> 0
B35: =B6-B16 -> 0 | C35: =C6-C16 -> 0 | D35: =D6-D16 -> 0 | E35: =E6-E16 -> 0 | F35: =F6-F16 -> 0 | H35: =H6-H16 -> 0 | I35: =I6-I16 -> 0 | J35: =J6-J16 -> 0 | K35: =K6-K16 -> 0 | L35: =L6-L16 -> 0 | M35: =M6-M16 -> 0 | N35: =N6-N16 -> 0 | O35: =O6-O16 -> 0 | ... Q35: =Q6-Q16 -> 0 | S35: =S6-S16 -> 0 | T35: =T6-T16 -> 0 | U35: =U6-U16 -> 0 | V35: =V6-V16 -> 0 | W35: =W6-W16 -> 0 | Y35: =Y6-Y16 -> 0 | Z35: =Z6-Z16 -> 0 | AA35: =AA6-AA16 -> 0 | AB35: =AB6-AB16 -> 0 | AC35: =AC6-AC16 -> 0 | AD35: =AD6-AD16 -> 0 | AE35: =AE6-AE16 -> 0 | AF35: =AF6-AF16 -> 0 | ... AH35: =AH6-AH16 -> 0
B36: =B7-B17 -> 0 | C36: =C7-C17 -> 0 | D36: =D7-D17 -> 0 | E36: =E7-E17 -> 0 | F36: =F7-F17 -> 0 | H36: =H7-H17 -> 0 | I36: =I7-I17 -> 0 | J36: =J7-J17 -> 0 | K36: =K7-K17 -> 0 | L36: =L7-L17 -> 0 | M36: =M7-M17 -> 0 | N36: =N7-N17 -> 0 | O36: =O7-O17 -> 0 | ... Q36: =Q7-Q17 -> 0 | S36: =S7-S17 -> 0 | T36: =T7-T17 -> 0 | U36: =U7-U17 -> 0 | V36: =V7-V17 -> 0 | W36: =W7-W17 -> 0 | Y36: =Y7-Y17 -> 0 | Z36: =Z7-Z17 -> 0 | AA36: =AA7-AA17 -> 0 | AB36: =AB7-AB17 -> 0 | AC36: =AC7-AC17 -> 0 | AD36: =AD7-AD17 -> 0 | AE36: =AE7-AE17 -> 0 | AF36: =AF7-AF17 -> 0 | ... AH36: =AH7-AH17 -> 0
B37: =B8-B18 -> 0 | C37: =C8-C18 -> 0 | D37: =D8-D18 -> 0 | E37: =E8-E18 -> 0 | F37: =F8-F18 -> 0 | H37: =H8-H18 -> 0 | I37: =I8-I18 -> 0 | J37: =J8-J18 -> 0 | K37: =K8-K18 -> 0 | L37: =L8-L18 -> 0 | M37: =M8-M18 -> 0 | N37: =N8-N18 -> 0 | O37: =O8-O18 -> 0 | ... Q37: =Q8-Q18 -> 0 | S37: =S8-S18 -> 0 | T37: =T8-T18 -> 0 | U37: =U8-U18 -> 0 | V37: =V8-V18 -> 0 | W37: =W8-W18 -> 0 | Y37: =Y8-Y18 -> 0 | Z37: =Z8-Z18 -> 0 | AA37: =AA8-AA18 -> 0 | AB37: =AB8-AB18 -> 0 | AC37: =AC8-AC18 -> 0 | AD37: =AD8-AD18 -> 0 | AE37: =AE8-AE18 -> 0 | AF37: =AF8-AF18 -> 0 | ... AH37: =AH8-AH18 -> 0
A38: PT1- | B38: =B9-B19 -> 0 | C38: =C9-C19 -> 0 | D38: =D9-D19 -> 0 | E38: =E9-E19 -> 0 | F38: =F9-F19 -> 0 | G38: PT2- | H38: =H9-H19 -> 0 | I38: =I9-I19 -> 0 | J38: =J9-J19 -> 0 | K38: =K9-K19 -> 0 | L38: =L9-L19 -> 0 | M38: =M9-M19 -> 0 | N38: =N9-N19 -> 0 | O38: =O9-O19 -> 0 | ... Q38: =Q9-Q19 -> 0 | R38: PT1- | S38: =S9-S19 -> 0 | T38: =T9-T19 -> 0 | U38: =U9-U19 -> 0 | V38: =V9-V19 -> 0 | W38: =W9-W19 -> 0 | X38: PT2- | Y38: =Y9-Y19 -> 0 | Z38: =Z9-Z19 -> 0 | AA38: =AA9-AA19 -> 0 | AB38: =AB9-AB19 -> 0 | AC38: =AC9-AC19 -> 0 | AD38: =AD9-AD19 -> 0 | AE38: =AE9-AE19 -> 0 | AF38: =AF9-AF19 -> 0 | ... AH38: =AH9-AH19 -> 0
B39: =B10-B20 -> 0 | C39: =C10-C20 -> 0 | D39: =D10-D20 -> 0 | E39: =E10-E20 -> 0 | F39: =F10-F20 -> 0 | H39: =H10-H20 -> 0 | I39: =I10-I20 -> 0 | J39: =J10-J20 -> 0 | K39: =K10-K20 -> 0 | L39: =L10-L20 -> 0 | M39: =M10-M20 -> 0 | N39: =N10-N20 -> 0 | O39: =O10-O20 -> 0 | ... Q39: =Q10-Q20 -> 0 | S39: =S10-S20 -> 0 | T39: =T10-T20 -> 0 | U39: =U10-U20 -> 0 | V39: =V10-V20 -> 0 | W39: =W10-W20 -> 0 | Y39: =Y10-Y20 -> 0 | Z39: =Z10-Z20 -> 0 | AA39: =AA10-AA20 -> 0 | AB39: =AB10-AB20 -> 0 | AC39: =AC10-AC20 -> 0 | AD39: =AD10-AD20 -> 0 | AE39: =AE10-AE20 -> 0 | AF39: =AF10-AF20 -> 0 | ... AH39: =AH10-AH20 -> 0
B40: =B11-B21 -> 0 | C40: =C11-C21 -> 0 | D40: =D11-D21 -> 0 | E40: =E11-E21 -> 0 | F40: =F11-F21 -> 0 | H40: =H11-H21 -> 0 | I40: =I11-I21 -> 0 | J40: =J11-J21 -> 0 | K40: =K11-K21 -> 0 | L40: =L11-L21 -> 0 | M40: =M11-M21 -> 0 | N40: =N11-N21 -> 0 | O40: =O11-O21 -> 0 | ... Q40: =Q11-Q21 -> 0 | S40: =S11-S21 -> 0 | T40: =T11-T21 -> 0 | U40: =U11-U21 -> 0 | V40: =V11-V21 -> 0 | W40: =W11-W21 -> 0 | Y40: =Y11-Y21 -> 0 | Z40: =Z11-Z21 -> 0 | AA40: =AA11-AA21 -> 0 | AB40: =AB11-AB21 -> 0 | AC40: =AC11-AC21 -> 0 | AD40: =AD11-AD21 -> 0 | AE40: =AE11-AE21 -> 0 | AF40: =AF11-AF21 -> 0 | ... AH40: =AH11-AH21 -> 0
B41: =B12-B22 -> 0 | C41: =C12-C22 -> 0 | D41: =D12-D22 -> 0 | E41: =E12-E22 -> 0 | F41: =F12-F22 -> 0 | H41: =H12-H22 -> 0 | I41: =I12-I22 -> 0 | J41: =J12-J22 -> 0 | K41: =K12-K22 -> 0 | L41: =L12-L22 -> 0 | M41: =M12-M22 -> 0 | N41: =N12-N22 -> 0 | O41: =O12-O22 -> 0 | ... Q41: =Q12-Q22 -> 0 | S41: =S12-S22 -> 0 | T41: =T12-T22 -> 0 | U41: =U12-U22 -> 0 | V41: =V12-V22 -> 0 | W41: =W12-W22 -> 0 | Y41: =Y12-Y22 -> 0 | Z41: =Z12-Z22 -> 0 | AA41: =AA12-AA22 -> 0 | AB41: =AB12-AB22 -> 0 | AC41: =AC12-AC22 -> 0 | AD41: =AD12-AD22 -> 0 | AE41: =AE12-AE22 -> 0 | AF41: =AF12-AF22 -> 0 | ... AH41: =AH12-AH22 -> 0
B42: =B13-B23 -> 0 | C42: =C13-C23 -> 0 | D42: =D13-D23 -> 0 | E42: =E13-E23 -> 0 | F42: =F13-F23 -> 0 | H42: =H13-H23 -> 0 | I42: =I13-I23 -> 0 | J42: =J13-J23 -> 0 | K42: =K13-K23 -> 0 | L42: =L13-L23 -> 0 | M42: =M13-M23 -> 0 | N42: =N13-N23 -> 0 | O42: =O13-O23 -> 0 | ... Q42: =Q13-Q23 -> 0 | S42: =S13-S23 -> 0 | T42: =T13-T23 -> 0 | U42: =U13-U23 -> 0 | V42: =V13-V23 -> 0 | W42: =W13-W23 -> 0 | Y42: =Y13-Y23 -> 0 | Z42: =Z13-Z23 -> 0 | AA42: =AA13-AA23 -> 0 | AB42: =AB13-AB23 -> 0 | AC42: =AC13-AC23 -> 0 | AD42: =AD13-AD23 -> 0 | AE42: =AE13-AE23 -> 0 | AF42: =AF13-AF23 -> 0 | ... AH42: =AH13-AH23 -> 0
A43: A side- EA | B43: =AVERAGE(B33:F37) -> 0 | C43: R | D43: =MAX(B33:F37)-MIN(B33:F37) -> 0 | E43: ER | F43: =B43/(0.975/E27) -> 0 | G43: A side- EA | H43: =AVERAGE(H33:Q37) -> 0 | I43: R | J43: =MAX(H33:Q37)-MIN(H33:Q37) -> 0 | K43: ER | L43: =H43/(0.975/K27) -> 0 | M43: % | N43: =1-(J43/2*H43) -> 1 | O43: T-R | P43: =MAX(H33:Q42)-MIN(H33:Q42) -> 0 | R43: A side- EA | S43: =AVERAGE(S33:W37) -> 0 | T43: R | U43: =MAX(S33:W37)-MIN(S33:W37) -> 0 | V43: ER | W43: =S43/(1.944/V27) -> 0 | X43: A side- EA | Y43: =AVERAGE(Y33:AH37) -> 0 | Z43: R | AA43: =MAX(Y33:AH37)-MIN(Y33:AH37) -> 0 | AB43: ER | AC43: =Y43/(2.268/AB27) -> 0 | AD43: % | AE43: =1-(AA43/2*Y43) -> 1 | AF43: T-R | AG43: =MAX(Y33:AH42)-MIN(Y33:AH42) -> 0
A44: B side- EA | B44: =AVERAGE(B39:F42) -> 0 | C44: R | D44: =MAX(B38:F42)-MIN(B38:F42) -> 0 | E44: ER | F44: =B44/(0.975/E27) -> 0 | G44: B side- EA | H44: =AVERAGE(H39:Q42) -> 0 | I44: R | J44: =MAX(H38:Q42)-MIN(H38:Q42) -> 0 | K44: ER | L44: =H44/(0.975/K27) -> 0 | M44: % | N44: =1-(J44/2*H44) -> 1 | O44: T-% | P44: =1-(P43/2*AVERAGE(H43:H44)) -> 1 | R44: B side- EA | S44: =AVERAGE(S39:W42) -> 0 | T44: R | U44: =MAX(S38:W42)-MIN(S38:W42) -> 0 | V44: ER | W44: =S44/(1.944/V27) -> 0 | X44: B side- EA | Y44: =AVERAGE(Y39:AH42) -> 0 | Z44: R | AA44: =MAX(Y38:AH42)-MIN(Y38:AH42) -> 0 | AB44: ER | AC44: =Y44/(2.268/AB27) -> 0 | AD44: % | AE44: =1-(AA44/2*Y44) -> 1 | AF44: T-% | AG44: =1-(AG43/2*AVERAGE(Y43:Y44)) -> 1
A46: PD-3-581-06B

Sheet 0826.
A1: PT咬蝕量量測記錄表 | G1: PT咬蝕量量測記錄表 | R1: QE咬蝕量量測記錄表 | X1: QE咬蝕量量測記錄表
A2: PT-01 | G2: PT-02 | R2: QE-01 | X2: QE-02
A3: OP | B3: 1 | C3: 2 | D3: 3 | E3: 4 | F3: 5 | G3: OP | H3: 1 | I3: 2 | J3: 3 | K3: 4 | L3: 5 | M3: 6 | N3: 7 | O3: 8 | P3: 9 | Q3: 10 | R3: OP | S3: 1 | T3: 2 | U3: 3 | V3: 4 | W3: 5 | X3: OP | Y3: 1 | Z3: 2 | AA3: 3 | AB3: 4 | AC3: 5 | AD3: 6 | AE3: 7 | AF3: 8 | AG3: 9 | AH3: 10
A4: BEFORE | G4: BEFORE | R4: BEFORE | X4: BEFORE
A14: AFTER | G14: AFTER | R14: AFTER | X14: AFTER
A25: 項次 | B25: 單位 | C25: 規格 | E25: 數值 | G25: 項次 | H25: 單位 | I25: 規格 | K25: 數值 | R25: 項次 | S25: 單位 | T25: 規格 | V25: 數值 | X25: 項次 | Y25: 單位 | Z25: 規格 | AB25: 數值
A26: 咬蝕量 | B26: um | C26: 0.3 | D26: ±0.1 | E26: =AVERAGE(B4:F13)-AVERAGE(B14:F23) -> #DIV/0! | G26: 咬蝕量 | H26: um | I26: 0.3 | J26: ±0.1 | K26: =AVERAGE(H4:Q13)-AVERAGE(H14:Q23) -> #DIV/0! | R26: 咬蝕量 | S26: um | T26: 1.07 | U26: ±0.21 | V26: =AVERAGE(S4:W13)-AVERAGE(S14:W23) -> #DIV/0! | X26: 咬蝕量 | Y26: um | Z26: 1.38 | AA26: ±0.23 | AB26: =AVERAGE(Y4:AH13)-AVERAGE(Y14:AH23) -> #DIV/0!
A27: 線速 | B27: M/min | C27: ="--" -> -- | E27: 1.7 | G27: 線速 | H27: M/min | I27: ="--" -> -- | K27: 1.5 | R27: 線速 | S27: M/min | T27: ="--" -> -- | V27: 1.4 | X27: 線速 | Y27: M/min | Z27: ="--" -> -- | AB27: 1.5
A28: 咬蝕速率 | B28: um/min | C28: 0.52±0.15 | E28: =(E26/(0.975/E27)) -> #DIV/0! | G28: 咬蝕速率 | H28: um/min | I28: 0.46±0.10 | K28: =(K26/(0.975/K27)) -> #DIV/0! | R28: 咬蝕速率 | S28: um/min | T28: 0.77±0.15 | V28: =(V26/(1.944/V27)) -> #DIV/0! | X28: 咬蝕速率 | Y28: um/min | Z28: 0.9±0.15 | AB28: =(AB26/(2.268/AB27)) -> #DIV/0!
A29: 生產速度(SPEED) | B29: M/min | C29: =0.972*E28/C26 -> #DIV/0! | E29: 以咬蝕量0.3um計算線速 | G29: 生產速度(SPEED) | H29: M/min | I29: =0.972*K28/I26 -> #DIV/0! | K29: 以咬蝕量0.3um計算線速 | R29: 生產速度(SPEED) | S29: M/min | T29: =1.944*V28/1.8 -> #DIV/0! | V29: 以咬蝕量1.8um計算線速 | X29: 生產速度(SPEED) | Y29: M/min | Z29: =2.268*AB28/1.5 -> #DIV/0! | AB29: 以咬蝕量1.5um計算線速
A30: 量測日期 | C30: =TODAY() -> 46251 | R30: 量測日期 | T30: =TODAY() -> 46251
A31: PT-01 | G31: PT-02 | R31: QE-01 | X31: QE-02
A32: 咬蝕量 | G32: 咬蝕量 | R32: 咬蝕量 | X32: 咬蝕量
A33: PT1+ | B33: =B4-B14 -> 0 | C33: =C4-C14 -> 0 | D33: =D4-D14 -> 0 | E33: =E4-E14 -> 0 | F33: =F4-F14 -> 0 | G33: PT2+ | H33: =H4-H14 -> 0 | I33: =I4-I14 -> 0 | J33: =J4-J14 -> 0 | K33: =K4-K14 -> 0 | L33: =L4-L14 -> 0 | M33: =M4-M14 -> 0 | N33: =N4-N14 -> 0 | O33: =O4-O14 -> 0 | ... Q33: =Q4-Q14 -> 0 | R33: PT1+ | S33: =S4-S14 -> 0 | T33: =T4-T14 -> 0 | U33: =U4-U14 -> 0 | V33: =V4-V14 -> 0 | W33: =W4-W14 -> 0 | X33: PT2+ | Y33: =Y4-Y14 -> 0 | Z33: =Z4-Z14 -> 0 | AA33: =AA4-AA14 -> 0 | AB33: =AB4-AB14 -> 0 | AC33: =AC4-AC14 -> 0 | AD33: =AD4-AD14 -> 0 | AE33: =AE4-AE14 -> 0 | AF33: =AF4-AF14 -> 0 | ... AH33: =AH4-AH14 -> 0
B34: =B5-B15 -> 0 | C34: =C5-C15 -> 0 | D34: =D5-D15 -> 0 | E34: =E5-E15 -> 0 | F34: =F5-F15 -> 0 | H34: =H5-H15 -> 0 | I34: =I5-I15 -> 0 | J34: =J5-J15 -> 0 | K34: =K5-K15 -> 0 | L34: =L5-L15 -> 0 | M34: =M5-M15 -> 0 | N34: =N5-N15 -> 0 | O34: =O5-O15 -> 0 | ... Q34: =Q5-Q15 -> 0 | S34: =S5-S15 -> 0 | T34: =T5-T15 -> 0 | U34: =U5-U15 -> 0 | V34: =V5-V15 -> 0 | W34: =W5-W15 -> 0 | Y34: =Y5-Y15 -> 0 | Z34: =Z5-Z15 -> 0 | AA34: =AA5-AA15 -> 0 | AB34: =AB5-AB15 -> 0 | AC34: =AC5-AC15 -> 0 | AD34: =AD5-AD15 -> 0 | AE34: =AE5-AE15 -> 0 | AF34: =AF5-AF15 -> 0 | ... AH34: =AH5-AH15 -> 0
B35: =B6-B16 -> 0 | C35: =C6-C16 -> 0 | D35: =D6-D16 -> 0 | E35: =E6-E16 -> 0 | F35: =F6-F16 -> 0 | H35: =H6-H16 -> 0 | I35: =I6-I16 -> 0 | J35: =J6-J16 -> 0 | K35: =K6-K16 -> 0 | L35: =L6-L16 -> 0 | M35: =M6-M16 -> 0 | N35: =N6-N16 -> 0 | O35: =O6-O16 -> 0 | ... Q35: =Q6-Q16 -> 0 | S35: =S6-S16 -> 0 | T35: =T6-T16 -> 0 | U35: =U6-U16 -> 0 | V35: =V6-V16 -> 0 | W35: =W6-W16 -> 0 | Y35: =Y6-Y16 -> 0 | Z35: =Z6-Z16 -> 0 | AA35: =AA6-AA16 -> 0 | AB35: =AB6-AB16 -> 0 | AC35: =AC6-AC16 -> 0 | AD35: =AD6-AD16 -> 0 | AE35: =AE6-AE16 -> 0 | AF35: =AF6-AF16 -> 0 | ... AH35: =AH6-AH16 -> 0
B36: =B7-B17 -> 0 | C36: =C7-C17 -> 0 | D36: =D7-D17 -> 0 | E36: =E7-E17 -> 0 | F36: =F7-F17 -> 0 | H36: =H7-H17 -> 0 | I36: =I7-I17 -> 0 | J36: =J7-J17 -> 0 | K36: =K7-K17 -> 0 | L36: =L7-L17 -> 0 | M36: =M7-M17 -> 0 | N36: =N7-N17 -> 0 | O36: =O7-O17 -> 0 | ... Q36: =Q7-Q17 -> 0 | S36: =S7-S17 -> 0 | T36: =T7-T17 -> 0 | U36: =U7-U17 -> 0 | V36: =V7-V17 -> 0 | W36: =W7-W17 -> 0 | Y36: =Y7-Y17 -> 0 | Z36: =Z7-Z17 -> 0 | AA36: =AA7-AA17 -> 0 | AB36: =AB7-AB17 -> 0 | AC36: =AC7-AC17 -> 0 | AD36: =AD7-AD17 -> 0 | AE36: =AE7-AE17 -> 0 | AF36: =AF7-AF17 -> 0 | ... AH36: =AH7-AH17 -> 0
B37: =B8-B18 -> 0 | C37: =C8-C18 -> 0 | D37: =D8-D18 -> 0 | E37: =E8-E18 -> 0 | F37: =F8-F18 -> 0 | H37: =H8-H18 -> 0 | I37: =I8-I18 -> 0 | J37: =J8-J18 -> 0 | K37: =K8-K18 -> 0 | L37: =L8-L18 -> 0 | M37: =M8-M18 -> 0 | N37: =N8-N18 -> 0 | O37: =O8-O18 -> 0 | ... Q37: =Q8-Q18 -> 0 | S37: =S8-S18 -> 0 | T37: =T8-T18 -> 0 | U37: =U8-U18 -> 0 | V37: =V8-V18 -> 0 | W37: =W8-W18 -> 0 | Y37: =Y8-Y18 -> 0 | Z37: =Z8-Z18 -> 0 | AA37: =AA8-AA18 -> 0 | AB37: =AB8-AB18 -> 0 | AC37: =AC8-AC18 -> 0 | AD37: =AD8-AD18 -> 0 | AE37: =AE8-AE18 -> 0 | AF37: =AF8-AF18 -> 0 | ... AH37: =AH8-AH18 -> 0
A38: PT1- | B38: =B9-B19 -> 0 | C38: =C9-C19 -> 0 | D38: =D9-D19 -> 0 | E38: =E9-E19 -> 0 | F38: =F9-F19 -> 0 | G38: PT2- | H38: =H9-H19 -> 0 | I38: =I9-I19 -> 0 | J38: =J9-J19 -> 0 | K38: =K9-K19 -> 0 | L38: =L9-L19 -> 0 | M38: =M9-M19 -> 0 | N38: =N9-N19 -> 0 | O38: =O9-O19 -> 0 | ... Q38: =Q9-Q19 -> 0 | R38: PT1- | S38: =S9-S19 -> 0 | T38: =T9-T19 -> 0 | U38: =U9-U19 -> 0 | V38: =V9-V19 -> 0 | W38: =W9-W19 -> 0 | X38: PT2- | Y38: =Y9-Y19 -> 0 | Z38: =Z9-Z19 -> 0 | AA38: =AA9-AA19 -> 0 | AB38: =AB9-AB19 -> 0 | AC38: =AC9-AC19 -> 0 | AD38: =AD9-AD19 -> 0 | AE38: =AE9-AE19 -> 0 | AF38: =AF9-AF19 -> 0 | ... AH38: =AH9-AH19 -> 0
B39: =B10-B20 -> 0 | C39: =C10-C20 -> 0 | D39: =D10-D20 -> 0 | E39: =E10-E20 -> 0 | F39: =F10-F20 -> 0 | H39: =H10-H20 -> 0 | I39: =I10-I20 -> 0 | J39: =J10-J20 -> 0 | K39: =K10-K20 -> 0 | L39: =L10-L20 -> 0 | M39: =M10-M20 -> 0 | N39: =N10-N20 -> 0 | O39: =O10-O20 -> 0 | ... Q39: =Q10-Q20 -> 0 | S39: =S10-S20 -> 0 | T39: =T10-T20 -> 0 | U39: =U10-U20 -> 0 | V39: =V10-V20 -> 0 | W39: =W10-W20 -> 0 | Y39: =Y10-Y20 -> 0 | Z39: =Z10-Z20 -> 0 | AA39: =AA10-AA20 -> 0 | AB39: =AB10-AB20 -> 0 | AC39: =AC10-AC20 -> 0 | AD39: =AD10-AD20 -> 0 | AE39: =AE10-AE20 -> 0 | AF39: =AF10-AF20 -> 0 | ... AH39: =AH10-AH20 -> 0
B40: =B11-B21 -> 0 | C40: =C11-C21 -> 0 | D40: =D11-D21 -> 0 | E40: =E11-E21 -> 0 | F40: =F11-F21 -> 0 | H40: =H11-H21 -> 0 | I40: =I11-I21 -> 0 | J40: =J11-J21 -> 0 | K40: =K11-K21 -> 0 | L40: =L11-L21 -> 0 | M40: =M11-M21 -> 0 | N40: =N11-N21 -> 0 | O40: =O11-O21 -> 0 | ... Q40: =Q11-Q21 -> 0 | S40: =S11-S21 -> 0 | T40: =T11-T21 -> 0 | U40: =U11-U21 -> 0 | V40: =V11-V21 -> 0 | W40: =W11-W21 -> 0 | Y40: =Y11-Y21 -> 0 | Z40: =Z11-Z21 -> 0 | AA40: =AA11-AA21 -> 0 | AB40: =AB11-AB21 -> 0 | AC40: =AC11-AC21 -> 0 | AD40: =AD11-AD21 -> 0 | AE40: =AE11-AE21 -> 0 | AF40: =AF11-AF21 -> 0 | ... AH40: =AH11-AH21 -> 0
B41: =B12-B22 -> 0 | C41: =C12-C22 -> 0 | D41: =D12-D22 -> 0 | E41: =E12-E22 -> 0 | F41: =F12-F22 -> 0 | H41: =H12-H22 -> 0 | I41: =I12-I22 -> 0 | J41: =J12-J22 -> 0 | K41: =K12-K22 -> 0 | L41: =L12-L22 -> 0 | M41: =M12-M22 -> 0 | N41: =N12-N22 -> 0 | O41: =O12-O22 -> 0 | ... Q41: =Q12-Q22 -> 0 | S41: =S12-S22 -> 0 | T41: =T12-T22 -> 0 | U41: =U12-U22 -> 0 | V41: =V12-V22 -> 0 | W41: =W12-W22 -> 0 | Y41: =Y12-Y22 -> 0 | Z41: =Z12-Z22 -> 0 | AA41: =AA12-AA22 -> 0 | AB41: =AB12-AB22 -> 0 | AC41: =AC12-AC22 -> 0 | AD41: =AD12-AD22 -> 0 | AE41: =AE12-AE22 -> 0 | AF41: =AF12-AF22 -> 0 | ... AH41: =AH12-AH22 -> 0
B42: =B13-B23 -> 0 | C42: =C13-C23 -> 0 | D42: =D13-D23 -> 0 | E42: =E13-E23 -> 0 | F42: =F13-F23 -> 0 | H42: =H13-H23 -> 0 | I42: =I13-I23 -> 0 | J42: =J13-J23 -> 0 | K42: =K13-K23 -> 0 | L42: =L13-L23 -> 0 | M42: =M13-M23 -> 0 | N42: =N13-N23 -> 0 | O42: =O13-O23 -> 0 | ... Q42: =Q13-Q23 -> 0 | S42: =S13-S23 -> 0 | T42: =T13-T23 -> 0 | U42: =U13-U23 -> 0 | V42: =V13-V23 -> 0 | W42: =W13-W23 -> 0 | Y42: =Y13-Y23 -> 0 | Z42: =Z13-Z23 -> 0 | AA42: =AA13-AA23 -> 0 | AB42: =AB13-AB23 -> 0 | AC42: =AC13-AC23 -> 0 | AD42: =AD13-AD23 -> 0 | AE42: =AE13-AE23 -> 0 | AF42: =AF13-AF23 -> 0 | ... AH42: =AH13-AH23 -> 0
A43: A side- EA | B43: =AVERAGE(B33:F37) -> 0 | C43: R | D43: =MAX(B33:F37)-MIN(B33:F37) -> 0 | E43: ER | F43: =B43/(0.975/E27) -> 0 | G43: A side- EA | H43: =AVERAGE(H33:Q37) -> 0 | I43: R | J43: =MAX(H33:Q37)-MIN(H33:Q37) -> 0 | K43: ER | L43: =H43/(0.975/K27) -> 0 | M43: % | N43: =1-(J43/2*H43) -> 1 | O43: T-R | P43: =MAX(H33:Q42)-MIN(H33:Q42) -> 0 | R43: A side- EA | S43: =AVERAGE(S33:W37) -> 0 | T43: R | U43: =MAX(S33:W37)-MIN(S33:W37) -> 0 | V43: ER | W43: =S43/(1.944/V27) -> 0 | X43: A side- EA | Y43: =AVERAGE(Y33:AH37) -> 0 | Z43: R | AA43: =MAX(Y33:AH37)-MIN(Y33:AH37) -> 0 | AB43: ER | AC43: =Y43/(2.268/AB27) -> 0 | AD43: % | AE43: =1-(AA43/2*Y43) -> 1 | AF43: T-R | AG43: =MAX(Y33:AH42)-MIN(Y33:AH42) -> 0
A44: B side- EA | B44: =AVERAGE(B39:F42) -> 0 | C44: R | D44: =MAX(B38:F42)-MIN(B38:F42) -> 0 | E44: ER | F44: =B44/(0.975/E27) -> 0 | G44: B side- EA | H44: =AVERAGE(H39:Q42) -> 0 | I44: R | J44: =MAX(H38:Q42)-MIN(H38:Q42) -> 0 | K44: ER | L44: =H44/(0.975/K27) -> 0 | M44: % | N44: =1-(J44/2*H44) -> 1 | O44: T-% | P44: =1-(P43/2*AVERAGE(H43:H44)) -> 1 | R44: B side- EA | S44: =AVERAGE(S39:W42) -> 0 | T44: R | U44: =MAX(S38:W42)-MIN(S38:W42) -> 0 | V44: ER | W44: =S44/(1.944/V27) -> 0 | X44: B side- EA | Y44: =AVERAGE(Y39:AH42) -> 0 | Z44: R | AA44: =MAX(Y38:AH42)-MIN(Y38:AH42) -> 0 | AB44: ER | AC44: =Y44/(2.268/AB27) -> 0 | AD44: % | AE44: =1-(AA44/2*Y44) -> 1 | AF44: T-% | AG44: =1-(AG43/2*AVERAGE(Y43:Y44)) -> 1
A46: PD-3-581-06B

Sheet 0825.
A1: PT咬蝕量量測記錄表 | G1: PT咬蝕量量測記錄表 | R1: QE咬蝕量量測記錄表 | X1: QE咬蝕量量測記錄表
A2: PT-01 | G2: PT-02 | R2: QE-01 | X2: QE-02
A3: OP | B3: 1 | C3: 2 | D3: 3 | E3: 4 | F3: 5 | G3: OP | H3: 1 | I3: 2 | J3: 3 | K3: 4 | L3: 5 | M3: 6 | N3: 7 | O3: 8 | P3: 9 | Q3: 10 | R3: OP | S3: 1 | T3: 2 | U3: 3 | V3: 4 | W3: 5 | X3: OP | Y3: 1 | Z3: 2 | AA3: 3 | AB3: 4 | AC3: 5 | AD3: 6 | AE3: 7 | AF3: 8 | AG3: 9 | AH3: 10
A4: BEFORE | G4: BEFORE | R4: BEFORE | X4: BEFORE
A14: AFTER | G14: AFTER | R14: AFTER | X14: AFTER
A25: 項次 | B25: 單位 | C25: 規格 | E25: 數值 | G25: 項次 | H25: 單位 | I25: 規格 | K25: 數值 | R25: 項次 | S25: 單位 | T25: 規格 | V25: 數值 | X25: 項次 | Y25: 單位 | Z25: 規格 | AB25: 數值
A26: 咬蝕量 | B26: um | C26: 0.3 | D26: ±0.1 | E26: =AVERAGE(B4:F13)-AVERAGE(B14:F23) -> #DIV/0! | G26: 咬蝕量 | H26: um | I26: 0.3 | J26: ±0.1 | K26: =AVERAGE(H4:Q13)-AVERAGE(H14:Q23) -> #DIV/0! | R26: 咬蝕量 | S26: um | T26: 1.07 | U26: ±0.21 | V26: =AVERAGE(S4:W13)-AVERAGE(S14:W23) -> #DIV/0! | X26: 咬蝕量 | Y26: um | Z26: 1.38 | AA26: ±0.23 | AB26: =AVERAGE(Y4:AH13)-AVERAGE(Y14:AH23) -> #DIV/0!
A27: 線速 | B27: M/min | C27: ="--" -> -- | E27: 1.7 | G27: 線速 | H27: M/min | I27: ="--" -> -- | K27: 1.5 | R27: 線速 | S27: M/min | T27: ="--" -> -- | V27: 1.4 | X27: 線速 | Y27: M/min | Z27: ="--" -> -- | AB27: 1.5
A28: 咬蝕速率 | B28: um/min | C28: 0.52±0.15 | E28: =(E26/(0.975/E27)) -> #DIV/0! | G28: 咬蝕速率 | H28: um/min | I28: 0.46±0.10 | K28: =(K26/(0.975/K27)) -> #DIV/0! | R28: 咬蝕速率 | S28: um/min | T28: 0.77±0.15 | V28: =(V26/(1.944/V27)) -> #DIV/0! | X28: 咬蝕速率 | Y28: um/min | Z28: 0.9±0.15 | AB28: =(AB26/(2.268/AB27)) -> #DIV/0!
A29: 生產速度(SPEED) | B29: M/min | C29: =0.972*E28/C26 -> #DIV/0! | E29: 以咬蝕量0.3um計算線速 | G29: 生產速度(SPEED) | H29: M/min | I29: =0.972*K28/I26 -> #DIV/0! | K29: 以咬蝕量0.3um計算線速 | R29: 生產速度(SPEED) | S29: M/min | T29: =1.944*V28/1.8 -> #DIV/0! | V29: 以咬蝕量1.8um計算線速 | X29: 生產速度(SPEED) | Y29: M/min | Z29: =2.268*AB28/1.5 -> #DIV/0! | AB29: 以咬蝕量1.5um計算線速
A30: 量測日期 | C30: =TODAY() -> 46251 | R30: 量測日期 | T30: =TODAY() -> 46251
A31: PT-01 | G31: PT-02 | R31: QE-01 | X31: QE-02
A32: 咬蝕量 | G32: 咬蝕量 | R32: 咬蝕量 | X32: 咬蝕量
A33: PT1+ | B33: =B4-B14 -> 0 | C33: =C4-C14 -> 0 | D33: =D4-D14 -> 0 | E33: =E4-E14 -> 0 | F33: =F4-F14 -> 0 | G33: PT2+ | H33: =H4-H14 -> 0 | I33: =I4-I14 -> 0 | J33: =J4-J14 -> 0 | K33: =K4-K14 -> 0 | L33: =L4-L14 -> 0 | M33: =M4-M14 -> 0 | N33: =N4-N14 -> 0 | O33: =O4-O14 -> 0 | ... Q33: =Q4-Q14 -> 0 | R33: PT1+ | S33: =S4-S14 -> 0 | T33: =T4-T14 -> 0 | U33: =U4-U14 -> 0 | V33: =V4-V14 -> 0 | W33: =W4-W14 -> 0 | X33: PT2+ | Y33: =Y4-Y14 -> 0 | Z33: =Z4-Z14 -> 0 | AA33: =AA4-AA14 -> 0 | AB33: =AB4-AB14 -> 0 | AC33: =AC4-AC14 -> 0 | AD33: =AD4-AD14 -> 0 | AE33: =AE4-AE14 -> 0 | AF33: =AF4-AF14 -> 0 | ... AH33: =AH4-AH14 -> 0
B34: =B5-B15 -> 0 | C34: =C5-C15 -> 0 | D34: =D5-D15 -> 0 | E34: =E5-E15 -> 0 | F34: =F5-F15 -> 0 | H34: =H5-H15 -> 0 | I34: =I5-I15 -> 0 | J34: =J5-J15 -> 0 | K34: =K5-K15 -> 0 | L34: =L5-L15 -> 0 | M34: =M5-M15 -> 0 | N34: =N5-N15 -> 0 | O34: =O5-O15 -> 0 | ... Q34: =Q5-Q15 -> 0 | S34: =S5-S15 -> 0 | T34: =T5-T15 -> 0 | U34: =U5-U15 -> 0 | V34: =V5-V15 -> 0 | W34: =W5-W15 -> 0 | Y34: =Y5-Y15 -> 0 | Z34: =Z5-Z15 -> 0 | AA34: =AA5-AA15 -> 0 | AB34: =AB5-AB15 -> 0 | AC34: =AC5-AC15 -> 0 | AD34: =AD5-AD15 -> 0 | AE34: =AE5-AE15 -> 0 | AF34: =AF5-AF15 -> 0 | ... AH34: =AH5-AH15 -> 0
B35: =B6-B16 -> 0 | C35: =C6-C16 -> 0 | D35: =D6-D16 -> 0 | E35: =E6-E16 -> 0 | F35: =F6-F16 -> 0 | H35: =H6-H16 -> 0 | I35: =I6-I16 -> 0 | J35: =J6-J16 -> 0 | K35: =K6-K16 -> 0 | L35: =L6-L16 -> 0 | M35: =M6-M16 -> 0 | N35: =N6-N16 -> 0 | O35: =O6-O16 -> 0 | ... Q35: =Q6-Q16 -> 0 | S35: =S6-S16 -> 0 | T35: =T6-T16 -> 0 | U35: =U6-U16 -> 0 | V35: =V6-V16 -> 0 | W35: =W6-W16 -> 0 | Y35: =Y6-Y16 -> 0 | Z35: =Z6-Z16 -> 0 | AA35: =AA6-AA16 -> 0 | AB35: =AB6-AB16 -> 0 | AC35: =AC6-AC16 -> 0 | AD35: =AD6-AD16 -> 0 | AE35: =AE6-AE16 -> 0 | AF35: =AF6-AF16 -> 0 | ... AH35: =AH6-AH16 -> 0
B36: =B7-B17 -> 0 | C36: =C7-C17 -> 0 | D36: =D7-D17 -> 0 | E36: =E7-E17 -> 0 | F36: =F7-F17 -> 0 | H36: =H7-H17 -> 0 | I36: =I7-I17 -> 0 | J36: =J7-J17 -> 0 | K36: =K7-K17 -> 0 | L36: =L7-L17 -> 0 | M36: =M7-M17 -> 0 | N36: =N7-N17 -> 0 | O36: =O7-O17 -> 0 | ... Q36: =Q7-Q17 -> 0 | S36: =S7-S17 -> 0 | T36: =T7-T17 -> 0 | U36: =U7-U17 -> 0 | V36: =V7-V17 -> 0 | W36: =W7-W17 -> 0 | Y36: =Y7-Y17 -> 0 | Z36: =Z7-Z17 -> 0 | AA36: =AA7-AA17 -> 0 | AB36: =AB7-AB17 -> 0 | AC36: =AC7-AC17 -> 0 | AD36: =AD7-AD17 -> 0 | AE36: =AE7-AE17 -> 0 | AF36: =AF7-AF17 -> 0 | ... AH36: =AH7-AH17 -> 0
B37: =B8-B18 -> 0 | C37: =C8-C18 -> 0 | D37: =D8-D18 -> 0 | E37: =E8-E18 -> 0 | F37: =F8-F18 -> 0 | H37: =H8-H18 -> 0 | I37: =I8-I18 -> 0 | J37: =J8-J18 -> 0 | K37: =K8-K18 -> 0 | L37: =L8-L18 -> 0 | M37: =M8-M18 -> 0 | N37: =N8-N18 -> 0 | O37: =O8-O18 -> 0 | ... Q37: =Q8-Q18 -> 0 | S37: =S8-S18 -> 0 | T37: =T8-T18 -> 0 | U37: =U8-U18 -> 0 | V37: =V8-V18 -> 0 | W37: =W8-W18 -> 0 | Y37: =Y8-Y18 -> 0 | Z37: =Z8-Z18 -> 0 | AA37: =AA8-AA18 -> 0 | AB37: =AB8-AB18 -> 0 | AC37: =AC8-AC18 -> 0 | AD37: =AD8-AD18 -> 0 | AE37: =AE8-AE18 -> 0 | AF37: =AF8-AF18 -> 0 | ... AH37: =AH8-AH18 -> 0
A38: PT1- | B38: =B9-B19 -> 0 | C38: =C9-C19 -> 0 | D38: =D9-D19 -> 0 | E38: =E9-E19 -> 0 | F38: =F9-F19 -> 0 | G38: PT2- | H38: =H9-H19 -> 0 | I38: =I9-I19 -> 0 | J38: =J9-J19 -> 0 | K38: =K9-K19 -> 0 | L38: =L9-L19 -> 0 | M38: =M9-M19 -> 0 | N38: =N9-N19 -> 0 | O38: =O9-O19 -> 0 | ... Q38: =Q9-Q19 -> 0 | R38: PT1- | S38: =S9-S19 -> 0 | T38: =T9-T19 -> 0 | U38: =U9-U19 -> 0 | V38: =V9-V19 -> 0 | W38: =W9-W19 -> 0 | X38: PT2- | Y38: =Y9-Y19 -> 0 | Z38: =Z9-Z19 -> 0 | AA38: =AA9-AA19 -> 0 | AB38: =AB9-AB19 -> 0 | AC38: =AC9-AC19 -> 0 | AD38: =AD9-AD19 -> 0 | AE38: =AE9-AE19 -> 0 | AF38: =AF9-AF19 -> 0 | ... AH38: =AH9-AH19 -> 0
B39: =B10-B20 -> 0 | C39: =C10-C20 -> 0 | D39: =D10-D20 -> 0 | E39: =E10-E20 -> 0 | F39: =F10-F20 -> 0 | H39: =H10-H20 -> 0 | I39: =I10-I20 -> 0 | J39: =J10-J20 -> 0 | K39: =K10-K20 -> 0 | L39: =L10-L20 -> 0 | M39: =M10-M20 -> 0 | N39: =N10-N20 -> 0 | O39: =O10-O20 -> 0 | ... Q39: =Q10-Q20 -> 0 | S39: =S10-S20 -> 0 | T39: =T10-T20 -> 0 | U39: =U10-U20 -> 0 | V39: =V10-V20 -> 0 | W39: =W10-W20 -> 0 | Y39: =Y10-Y20 -> 0 | Z39: =Z10-Z20 -> 0 | AA39: =AA10-AA20 -> 0 | AB39: =AB10-AB20 -> 0 | AC39: =AC10-AC20 -> 0 | AD39: =AD10-AD20 -> 0 | AE39: =AE10-AE20 -> 0 | AF39: =AF10-AF20 -> 0 | ... AH39: =AH10-AH20 -> 0
B40: =B11-B21 -> 0 | C40: =C11-C21 -> 0 | D40: =D11-D21 -> 0 | E40: =E11-E21 -> 0 | F40: =F11-F21 -> 0 | H40: =H11-H21 -> 0 | I40: =I11-I21 -> 0 | J40: =J11-J21 -> 0 | K40: =K11-K21 -> 0 | L40: =L11-L21 -> 0 | M40: =M11-M21 -> 0 | N40: =N11-N21 -> 0 | O40: =O11-O21 -> 0 | ... Q40: =Q11-Q21 -> 0 | S40: =S11-S21 -> 0 | T40: =T11-T21 -> 0 | U40: =U11-U21 -> 0 | V40: =V11-V21 -> 0 | W40: =W11-W21 -> 0 | Y40: =Y11-Y21 -> 0 | Z40: =Z11-Z21 -> 0 | AA40: =AA11-AA21 -> 0 | AB40: =AB11-AB21 -> 0 | AC40: =AC11-AC21 -> 0 | AD40: =AD11-AD21 -> 0 | AE40: =AE11-AE21 -> 0 | AF40: =AF11-AF21 -> 0 | ... AH40: =AH11-AH21 -> 0
B41: =B12-B22 -> 0 | C41: =C12-C22 -> 0 | D41: =D12-D22 -> 0 | E41: =E12-E22 -> 0 | F41: =F12-F22 -> 0 | H41: =H12-H22 -> 0 | I41: =I12-I22 -> 0 | J41: =J12-J22 -> 0 | K41: =K12-K22 -> 0 | L41: =L12-L22 -> 0 | M41: =M12-M22 -> 0 | N41: =N12-N22 -> 0 | O41: =O12-O22 -> 0 | ... Q41: =Q12-Q22 -> 0 | S41: =S12-S22 -> 0 | T41: =T12-T22 -> 0 | U41: =U12-U22 -> 0 | V41: =V12-V22 -> 0 | W41: =W12-W22 -> 0 | Y41: =Y12-Y22 -> 0 | Z41: =Z12-Z22 -> 0 | AA41: =AA12-AA22 -> 0 | AB41: =AB12-AB22 -> 0 | AC41: =AC12-AC22 -> 0 | AD41: =AD12-AD22 -> 0 | AE41: =AE12-AE22 -> 0 | AF41: =AF12-AF22 -> 0 | ... AH41: =AH12-AH22 -> 0
B42: =B13-B23 -> 0 | C42: =C13-C23 -> 0 | D42: =D13-D23 -> 0 | E42: =E13-E23 -> 0 | F42: =F13-F23 -> 0 | H42: =H13-H23 -> 0 | I42: =I13-I23 -> 0 | J42: =J13-J23 -> 0 | K42: =K13-K23 -> 0 | L42: =L13-L23 -> 0 | M42: =M13-M23 -> 0 | N42: =N13-N23 -> 0 | O42: =O13-O23 -> 0 | ... Q42: =Q13-Q23 -> 0 | S42: =S13-S23 -> 0 | T42: =T13-T23 -> 0 | U42: =U13-U23 -> 0 | V42: =V13-V23 -> 0 | W42: =W13-W23 -> 0 | Y42: =Y13-Y23 -> 0 | Z42: =Z13-Z23 -> 0 | AA42: =AA13-AA23 -> 0 | AB42: =AB13-AB23 -> 0 | AC42: =AC13-AC23 -> 0 | AD42: =AD13-AD23 -> 0 | AE42: =AE13-AE23 -> 0 | AF42: =AF13-AF23 -> 0 | ... AH42: =AH13-AH23 -> 0
A43: A side- EA | B43: =AVERAGE(B33:F37) -> 0 | C43: R | D43: =MAX(B33:F37)-MIN(B33:F37) -> 0 | E43: ER | F43: =B43/(0.975/E27) -> 0 | G43: A side- EA | H43: =AVERAGE(H33:Q37) -> 0 | I43: R | J43: =MAX(H33:Q37)-MIN(H33:Q37) -> 0 | K43: ER | L43: =H43/(0.975/K27) -> 0 | M43: % | N43: =1-(J43/2*H43) -> 1 | O43: T-R | P43: =MAX(H33:Q42)-MIN(H33:Q42) -> 0 | R43: A side- EA | S43: =AVERAGE(S33:W37) -> 0 | T43: R | U43: =MAX(S33:W37)-MIN(S33:W37) -> 0 | V43: ER | W43: =S43/(1.944/V27) -> 0 | X43: A side- EA | Y43: =AVERAGE(Y33:AH37) -> 0 | Z43: R | AA43: =MAX(Y33:AH37)-MIN(Y33:AH37) -> 0 | AB43: ER | AC43: =Y43/(2.268/AB27) -> 0 | AD43: % | AE43: =1-(AA43/2*Y43) -> 1 | AF43: T-R | AG43: =MAX(Y33:AH42)-MIN(Y33:AH42) -> 0
A44: B side- EA | B44: =AVERAGE(B39:F42) -> 0 | C44: R | D44: =MAX(B38:F42)-MIN(B38:F42) -> 0 | E44: ER | F44: =B44/(0.975/E27) -> 0 | G44: B side- EA | H44: =AVERAGE(H39:Q42) -> 0 | I44: R | J44: =MAX(H38:Q42)-MIN(H38:Q42) -> 0 | K44: ER | L44: =H44/(0.975/K27) -> 0 | M44: % | N44: =1-(J44/2*H44) -> 1 | O44: T-% | P44: =1-(P43/2*AVERAGE(H43:H44)) -> 1 | R44: B side- EA | S44: =AVERAGE(S39:W42) -> 0 | T44: R | U44: =MAX(S38:W42)-MIN(S38:W42) -> 0 | V44: ER | W44: =S44/(1.944/V27) -> 0 | X44: B side- EA | Y44: =AVERAGE(Y39:AH42) -> 0 | Z44: R | AA44: =MAX(Y38:AH42)-MIN(Y38:AH42) -> 0 | AB44: ER | AC44: =Y44/(2.268/AB27) -> 0 | AD44: % | AE44: =1-(AA44/2*Y44) -> 1 | AF44: T-% | AG44: =1-(AG43/2*AVERAGE(Y43:Y44)) -> 1
A46: PD-3-581-06B

Sheet 0824.
A1: PT咬蝕量量測記錄表 | G1: PT咬蝕量量測記錄表 | R1: QE咬蝕量量測記錄表 | X1: QE咬蝕量量測記錄表
A2: PT-01 | G2: PT-02 | R2: QE-01 | X2: QE-02
A3: OP | B3: 1 | C3: 2 | D3: 3 | E3: 4 | F3: 5 | G3: OP | H3: 1 | I3: 2 | J3: 3 | K3: 4 | L3: 5 | M3: 6 | N3: 7 | O3: 8 | P3: 9 | Q3: 10 | R3: OP | S3: 1 | T3: 2 | U3: 3 | V3: 4 | W3: 5 | X3: OP | Y3: 1 | Z3: 2 | AA3: 3 | AB3: 4 | AC3: 5 | AD3: 6 | AE3: 7 | AF3: 8 | AG3: 9 | AH3: 10
A4: BEFORE | G4: BEFORE | R4: BEFORE | X4: BEFORE
A14: AFTER | G14: AFTER | R14: AFTER | X14: AFTER
A25: 項次 | B25: 單位 | C25: 規格 | E25: 數值 | G25: 項次 | H25: 單位 | I25: 規格 | K25: 數值 | R25: 項次 | S25: 單位 | T25: 規格 | V25: 數值 | X25: 項次 | Y25: 單位 | Z25: 規格 | AB25: 數值
A26: 咬蝕量 | B26: um | C26: 0.3 | D26: ±0.1 | E26: =AVERAGE(B4:F13)-AVERAGE(B14:F23) -> #DIV/0! | G26: 咬蝕量 | H26: um | I26: 0.3 | J26: ±0.1 | K26: =AVERAGE(H4:Q13)-AVERAGE(H14:Q23) -> #DIV/0! | R26: 咬蝕量 | S26: um | T26: 1.07 | U26: ±0.21 | V26: =AVERAGE(S4:W13)-AVERAGE(S14:W23) -> #DIV/0! | X26: 咬蝕量 | Y26: um | Z26: 1.38 | AA26: ±0.23 | AB26: =AVERAGE(Y4:AH13)-AVERAGE(Y14:AH23) -> #DIV/0!
A27: 線速 | B27: M/min | C27: ="--" -> -- | E27: 1.7 | G27: 線速 | H27: M/min | I27: ="--" -> -- | K27: 1.5 | R27: 線速 | S27: M/min | T27: ="--" -> -- | V27: 1.4 | X27: 線速 | Y27: M/min | Z27: ="--" -> -- | AB27: 1.5
A28: 咬蝕速率 | B28: um/min | C28: 0.52±0.15 | E28: =(E26/(0.975/E27)) -> #DIV/0! | G28: 咬蝕速率 | H28: um/min | I28: 0.46±0.10 | K28: =(K26/(0.975/K27)) -> #DIV/0! | R28: 咬蝕速率 | S28: um/min | T28: 0.77±0.15 | V28: =(V26/(1.944/V27)) -> #DIV/0! | X28: 咬蝕速率 | Y28: um/min | Z28: 0.9±0.15 | AB28: =(AB26/(2.268/AB27)) -> #DIV/0!
A29: 生產速度(SPEED) | B29: M/min | C29: =0.972*E28/C26 -> #DIV/0! | E29: 以咬蝕量0.3um計算線速 | G29: 生產速度(SPEED) | H29: M/min | I29: =0.972*K28/I26 -> #DIV/0! | K29: 以咬蝕量0.3um計算線速 | R29: 生產速度(SPEED) | S29: M/min | T29: =1.944*V28/1.8 -> #DIV/0! | V29: 以咬蝕量1.8um計算線速 | X29: 生產速度(SPEED) | Y29: M/min | Z29: =2.268*AB28/1.5 -> #DIV/0! | AB29: 以咬蝕量1.5um計算線速
A30: 量測日期 | C30: =TODAY() -> 46251 | R30: 量測日期 | T30: =TODAY() -> 46251
A31: PT-01 | G31: PT-02 | R31: QE-01 | X31: QE-02
A32: 咬蝕量 | G32: 咬蝕量 | R32: 咬蝕量 | X32: 咬蝕量
A33: PT1+ | B33: =B4-B14 -> 0 | C33: =C4-C14 -> 0 | D33: =D4-D14 -> 0 | E33: =E4-E14 -> 0 | F33: =F4-F14 -> 0 | G33: PT2+ | H33: =H4-H14 -> 0 | I33: =I4-I14 -> 0 | J33: =J4-J14 -> 0 | K33: =K4-K14 -> 0 | L33: =L4-L14 -> 0 | M33: =M4-M14 -> 0 | N33: =N4-N14 -> 0 | O33: =O4-O14 -> 0 | ... Q33: =Q4-Q14 -> 0 | R33: PT1+ | S33: =S4-S14 -> 0 | T33: =T4-T14 -> 0 | U33: =U4-U14 -> 0 | V33: =V4-V14 -> 0 | W33: =W4-W14 -> 0 | X33: PT2+ | Y33: =Y4-Y14 -> 0 | Z33: =Z4-Z14 -> 0 | AA33: =AA4-AA14 -> 0 | AB33: =AB4-AB14 -> 0 | AC33: =AC4-AC14 -> 0 | AD33: =AD4-AD14 -> 0 | AE33: =AE4-AE14 -> 0 | AF33: =AF4-AF14 -> 0 | ... AH33: =AH4-AH14 -> 0
B34: =B5-B15 -> 0 | C34: =C5-C15 -> 0 | D34: =D5-D15 -> 0 | E34: =E5-E15 -> 0 | F34: =F5-F15 -> 0 | H34: =H5-H15 -> 0 | I34: =I5-I15 -> 0 | J34: =J5-J15 -> 0 | K34: =K5-K15 -> 0 | L34: =L5-L15 -> 0 | M34: =M5-M15 -> 0 | N34: =N5-N15 -> 0 | O34: =O5-O15 -> 0 | ... Q34: =Q5-Q15 -> 0 | S34: =S5-S15 -> 0 | T34: =T5-T15 -> 0 | U34: =U5-U15 -> 0 | V34: =V5-V15 -> 0 | W34: =W5-W15 -> 0 | Y34: =Y5-Y15 -> 0 | Z34: =Z5-Z15 -> 0 | AA34: =AA5-AA15 -> 0 | AB34: =AB5-AB15 -> 0 | AC34: =AC5-AC15 -> 0 | AD34: =AD5-AD15 -> 0 | AE34: =AE5-AE15 -> 0 | AF34: =AF5-AF15 -> 0 | ... AH34: =AH5-AH15 -> 0
B35: =B6-B16 -> 0 | C35: =C6-C16 -> 0 | D35: =D6-D16 -> 0 | E35: =E6-E16 -> 0 | F35: =F6-F16 -> 0 | H35: =H6-H16 -> 0 | I35: =I6-I16 -> 0 | J35: =J6-J16 -> 0 | K35: =K6-K16 -> 0 | L35: =L6-L16 -> 0 | M35: =M6-M16 -> 0 | N35: =N6-N16 -> 0 | O35: =O6-O16 -> 0 | ... Q35: =Q6-Q16 -> 0 | S35: =S6-S16 -> 0 | T35: =T6-T16 -> 0 | U35: =U6-U16 -> 0 | V35: =V6-V16 -> 0 | W35: =W6-W16 -> 0 | Y35: =Y6-Y16 -> 0 | Z35: =Z6-Z16 -> 0 | AA35: =AA6-AA16 -> 0 | AB35: =AB6-AB16 -> 0 | AC35: =AC6-AC16 -> 0 | AD35: =AD6-AD16 -> 0 | AE35: =AE6-AE16 -> 0 | AF35: =AF6-AF16 -> 0 | ... AH35: =AH6-AH16 -> 0
B36: =B7-B17 -> 0 | C36: =C7-C17 -> 0 | D36: =D7-D17 -> 0 | E36: =E7-E17 -> 0 | F36: =F7-F17 -> 0 | H36: =H7-H17 -> 0 | I36: =I7-I17 -> 0 | J36: =J7-J17 -> 0 | K36: =K7-K17 -> 0 | L36: =L7-L17 -> 0 | M36: =M7-M17 -> 0 | N36: =N7-N17 -> 0 | O36: =O7-O17 -> 0 | ... Q36: =Q7-Q17 -> 0 | S36: =S7-S17 -> 0 | T36: =T7-T17 -> 0 | U36: =U7-U17 -> 0 | V36: =V7-V17 -> 0 | W36: =W7-W17 -> 0 | Y36: =Y7-Y17 -> 0 | Z36: =Z7-Z17 -> 0 | AA36: =AA7-AA17 -> 0 | AB36: =AB7-AB17 -> 0 | AC36: =AC7-AC17 -> 0 | AD36: =AD7-AD17 -> 0 | AE36: =AE7-AE17 -> 0 | AF36: =AF7-AF17 -> 0 | ... AH36: =AH7-AH17 -> 0
B37: =B8-B18 -> 0 | C37: =C8-C18 -> 0 | D37: =D8-D18 -> 0 | E37: =E8-E18 -> 0 | F37: =F8-F18 -> 0 | H37: =H8-H18 -> 0 | I37: =I8-I18 -> 0 | J37: =J8-J18 -> 0 | K37: =K8-K18 -> 0 | L37: =L8-L18 -> 0 | M37: =M8-M18 -> 0 | N37: =N8-N18 -> 0 | O37: =O8-O18 -> 0 | ... Q37: =Q8-Q18 -> 0 | S37: =S8-S18 -> 0 | T37: =T8-T18 -> 0 | U37: =U8-U18 -> 0 | V37: =V8-V18 -> 0 | W37: =W8-W18 -> 0 | Y37: =Y8-Y18 -> 0 | Z37: =Z8-Z18 -> 0 | AA37: =AA8-AA18 -> 0 | AB37: =AB8-AB18 -> 0 | AC37: =AC8-AC18 -> 0 | AD37: =AD8-AD18 -> 0 | AE37: =AE8-AE18 -> 0 | AF37: =AF8-AF18 -> 0 | ... AH37: =AH8-AH18 -> 0
A38: PT1- | B38: =B9-B19 -> 0 | C38: =C9-C19 -> 0 | D38: =D9-D19 -> 0 | E38: =E9-E19 -> 0 | F38: =F9-F19 -> 0 | G38: PT2- | H38: =H9-H19 -> 0 | I38: =I9-I19 -> 0 | J38: =J9-J19 -> 0 | K38: =K9-K19 -> 0 | L38: =L9-L19 -> 0 | M38: =M9-M19 -> 0 | N38: =N9-N19 -> 0 | O38: =O9-O19 -> 0 | ... Q38: =Q9-Q19 -> 0 | R38: PT1- | S38: =S9-S19 -> 0 | T38: =T9-T19 -> 0 | U38: =U9-U19 -> 0 | V38: =V9-V19 -> 0 | W38: =W9-W19 -> 0 | X38: PT2- | Y38: =Y9-Y19 -> 0 | Z38: =Z9-Z19 -> 0 | AA38: =AA9-AA19 -> 0 | AB38: =AB9-AB19 -> 0 | AC38: =AC9-AC19 -> 0 | AD38: =AD9-AD19 -> 0 | AE38: =AE9-AE19 -> 0 | AF38: =AF9-AF19 -> 0 | ... AH38: =AH9-AH19 -> 0
B39: =B10-B20 -> 0 | C39: =C10-C20 -> 0 | D39: =D10-D20 -> 0 | E39: =E10-E20 -> 0 | F39: =F10-F20 -> 0 | H39: =H10-H20 -> 0 | I39: =I10-I20 -> 0 | J39: =J10-J20 -> 0 | K39: =K10-K20 -> 0 | L39: =L10-L20 -> 0 | M39: =M10-M20 -> 0 | N39: =N10-N20 -> 0 | O39: =O10-O20 -> 0 | ... Q39: =Q10-Q20 -> 0 | S39: =S10-S20 -> 0 | T39: =T10-T20 -> 0 | U39: =U10-U20 -> 0 | V39: =V10-V20 -> 0 | W39: =W10-W20 -> 0 | Y39: =Y10-Y20 -> 0 | Z39: =Z10-Z20 -> 0 | AA39: =AA10-AA20 -> 0 | AB39: =AB10-AB20 -> 0 | AC39: =AC10-AC20 -> 0 | AD39: =AD10-AD20 -> 0 | AE39: =AE10-AE20 -> 0 | AF39: =AF10-AF20 -> 0 | ... AH39: =AH10-AH20 -> 0
B40: =B11-B21 -> 0 | C40: =C11-C21 -> 0 | D40: =D11-D21 -> 0 | E40: =E11-E21 -> 0 | F40: =F11-F21 -> 0 | H40: =H11-H21 -> 0 | I40: =I11-I21 -> 0 | J40: =J11-J21 -> 0 | K40: =K11-K21 -> 0 | L40: =L11-L21 -> 0 | M40: =M11-M21 -> 0 | N40: =N11-N21 -> 0 | O40: =O11-O21 -> 0 | ... Q40: =Q11-Q21 -> 0 | S40: =S11-S21 -> 0 | T40: =T11-T21 -> 0 | U40: =U11-U21 -> 0 | V40: =V11-V21 -> 0 | W40: =W11-W21 -> 0 | Y40: =Y11-Y21 -> 0 | Z40: =Z11-Z21 -> 0 | AA40: =AA11-AA21 -> 0 | AB40: =AB11-AB21 -> 0 | AC40: =AC11-AC21 -> 0 | AD40: =AD11-AD21 -> 0 | AE40: =AE11-AE21 -> 0 | AF40: =AF11-AF21 -> 0 | ... AH40: =AH11-AH21 -> 0
B41: =B12-B22 -> 0 | C41: =C12-C22 -> 0 | D41: =D12-D22 -> 0 | E41: =E12-E22 -> 0 | F41: =F12-F22 -> 0 | H41: =H12-H22 -> 0 | I41: =I12-I22 -> 0 | J41: =J12-J22 -> 0 | K41: =K12-K22 -> 0 | L41: =L12-L22 -> 0 | M41: =M12-M22 -> 0 | N41: =N12-N22 -> 0 | O41: =O12-O22 -> 0 | ... Q41: =Q12-Q22 -> 0 | S41: =S12-S22 -> 0 | T41: =T12-T22 -> 0 | U41: =U12-U22 -> 0 | V41: =V12-V22 -> 0 | W41: =W12-W22 -> 0 | Y41: =Y12-Y22 -> 0 | Z41: =Z12-Z22 -> 0 | AA41: =AA12-AA22 -> 0 | AB41: =AB12-AB22 -> 0 | AC41: =AC12-AC22 -> 0 | AD41: =AD12-AD22 -> 0 | AE41: =AE12-AE22 -> 0 | AF41: =AF12-AF22 -> 0 | ... AH41: =AH12-AH22 -> 0
B42: =B13-B23 -> 0 | C42: =C13-C23 -> 0 | D42: =D13-D23 -> 0 | E42: =E13-E23 -> 0 | F42: =F13-F23 -> 0 | H42: =H13-H23 -> 0 | I42: =I13-I23 -> 0 | J42: =J13-J23 -> 0 | K42: =K13-K23 -> 0 | L42: =L13-L23 -> 0 | M42: =M13-M23 -> 0 | N42: =N13-N23 -> 0 | O42: =O13-O23 -> 0 | ... Q42: =Q13-Q23 -> 0 | S42: =S13-S23 -> 0 | T42: =T13-T23 -> 0 | U42: =U13-U23 -> 0 | V42: =V13-V23 -> 0 | W42: =W13-W23 -> 0 | Y42: =Y13-Y23 -> 0 | Z42: =Z13-Z23 -> 0 | AA42: =AA13-AA23 -> 0 | AB42: =AB13-AB23 -> 0 | AC42: =AC13-AC23 -> 0 | AD42: =AD13-AD23 -> 0 | AE42: =AE13-AE23 -> 0 | AF42: =AF13-AF23 -> 0 | ... AH42: =AH13-AH23 -> 0
A43: A side- EA | B43: =AVERAGE(B33:F37) -> 0 | C43: R | D43: =MAX(B33:F37)-MIN(B33:F37) -> 0 | E43: ER | F43: =B43/(0.975/E27) -> 0 | G43: A side- EA | H43: =AVERAGE(H33:Q37) -> 0 | I43: R | J43: =MAX(H33:Q37)-MIN(H33:Q37) -> 0 | K43: ER | L43: =H43/(0.975/K27) -> 0 | M43: % | N43: =1-(J43/2*H43) -> 1 | O43: T-R | P43: =MAX(H33:Q42)-MIN(H33:Q42) -> 0 | R43: A side- EA | S43: =AVERAGE(S33:W37) -> 0 | T43: R | U43: =MAX(S33:W37)-MIN(S33:W37) -> 0 | V43: ER | W43: =S43/(1.944/V27) -> 0 | X43: A side- EA | Y43: =AVERAGE(Y33:AH37) -> 0 | Z43: R | AA43: =MAX(Y33:AH37)-MIN(Y33:AH37) -> 0 | AB43: ER | AC43: =Y43/(2.268/AB27) -> 0 | AD43: % | AE43: =1-(AA43/2*Y43) -> 1 | AF43: T-R | AG43: =MAX(Y33:AH42)-MIN(Y33:AH42) -> 0
A44: B side- EA | B44: =AVERAGE(B39:F42) -> 0 | C44: R | D44: =MAX(B38:F42)-MIN(B38:F42) -> 0 | E44: ER | F44: =B44/(0.975/E27) -> 0 | G44: B side- EA | H44: =AVERAGE(H39:Q42) -> 0 | I44: R | J44: =MAX(H38:Q42)-MIN(H38:Q42) -> 0 | K44: ER | L44: =H44/(0.975/K27) -> 0 | M44: % | N44: =1-(J44/2*H44) -> 1 | O44: T-% | P44: =1-(P43/2*AVERAGE(H43:H44)) -> 1 | R44: B side- EA | S44: =AVERAGE(S39:W42) -> 0 | T44: R | U44: =MAX(S38:W42)-MIN(S38:W42) -> 0 | V44: ER | W44: =S44/(1.944/V27) -> 0 | X44: B side- EA | Y44: =AVERAGE(Y39:AH42) -> 0 | Z44: R | AA44: =MAX(Y38:AH42)-MIN(Y38:AH42) -> 0 | AB44: ER | AC44: =Y44/(2.268/AB27) -> 0 | AD44: % | AE44: =1-(AA44/2*Y44) -> 1 | AF44: T-% | AG44: =1-(AG43/2*AVERAGE(Y43:Y44)) -> 1
A46: PD-3-581-06B

Sheet 0821.
A1: PT咬蝕量量測記錄表 | G1: PT咬蝕量量測記錄表 | R1: QE咬蝕量量測記錄表 | X1: QE咬蝕量量測記錄表
A2: PT-01 | G2: PT-02 | R2: QE-01 | X2: QE-02
A3: OP | B3: 1 | C3: 2 | D3: 3 | E3: 4 | F3: 5 | G3: OP | H3: 1 | I3: 2 | J3: 3 | K3: 4 | L3: 5 | M3: 6 | N3: 7 | O3: 8 | P3: 9 | Q3: 10 | R3: OP | S3: 1 | T3: 2 | U3: 3 | V3: 4 | W3: 5 | X3: OP | Y3: 1 | Z3: 2 | AA3: 3 | AB3: 4 | AC3: 5 | AD3: 6 | AE3: 7 | AF3: 8 | AG3: 9 | AH3: 10
A4: BEFORE | G4: BEFORE | R4: BEFORE | X4: BEFORE
A14: AFTER | G14: AFTER | R14: AFTER | X14: AFTER
A25: 項次 | B25: 單位 | C25: 規格 | E25: 數值 | G25: 項次 | H25: 單位 | I25: 規格 | K25: 數值 | R25: 項次 | S25: 單位 | T25: 規格 | V25: 數值 | X25: 項次 | Y25: 單位 | Z25: 規格 | AB25: 數值
