Workbook
Name Slicer_管制圖號: #N/A

Sheet 0514.
A1: PT-01 | G1: QE-01 | M1: PT-02 | X1: QE-02
A2: OP | B2: 1 | C2: 2 | D2: 3 | E2: 4 | F2: 5 | G2: OP | H2: 1 | I2: 2 | J2: 3 | K2: 4 | L2: 5 | M2: OP | N2: 1 | O2: 2 | P2: 3 | Q2: 4 | R2: 5 | S2: 6 | T2: 7 | U2: 8 | V2: 9 | W2: 10 | X2: OP | Y2: 1 | Z2: 2 | AA2: 3 | AB2: 4 | AC2: 5 | AD2: 6 | AE2: 7 | AF2: 8 | AG2: 9 | AH2: 10
A3: N2522+ | G3: N2522+ | H3: 3.09 | I3: 3.15 | J3: 3.08 | K3: 2.91 | L3: 2.79 | M3: N2522+ | X3: N2522+
H4: 3.09 | I4: 3.14 | J4: 3.15 | K4: 2.96 | L4: 2.8
H5: 3.12 | I5: 3.14 | J5: 3.09 | K5: 2.95 | L5: 2.9
H6: 3.13 | I6: 3.15 | J6: 3.17 | K6: 2.92 | L6: 2.83
H7: 3.07 | I7: 3.15 | J7: 3.17 | K7: 2.85 | L7: 2.79
A8: N2522- | G8: N2522- | H8: 3.26 | I8: 3.23 | J8: 3.11 | K8: 2.91 | L8: 2.85 | M8: N2522- | X8: N2522-
H9: 3.15 | I9: 3.32 | J9: 3.19 | K9: 2.86 | L9: 2.82
H10: 3.16 | I10: 3.28 | J10: 3.15 | K10: 2.94 | L10: 2.9
H11: 3.16 | I11: 3.21 | J11: 3.11 | K11: 2.93 | L11: 2.91
H12: 3.18 | I12: 3.17 | J12: 3.09 | K12: 2.96 | L12: 2.86
A13: PT1+ | G13: QE1+ | H13: 1.81 | I13: 1.86 | J13: 1.79 | K13: 1.6 | L13: 1.49 | M13: PT2+ | X13: QE2+
H14: 1.79 | I14: 1.81 | J14: 1.8 | K14: 1.58 | L14: 1.46
H15: 1.82 | I15: 1.83 | J15: 1.78 | K15: 1.6 | L15: 1.53
H16: 1.76 | I16: 1.84 | J16: 1.81 | K16: 1.6 | L16: 1.47
H17: 1.78 | I17: 1.8 | J17: 1.75 | K17: 1.55 | L17: 1.47
A18: PT1- | G18: Q1E- | H18: 2.24 | I18: 2.27 | J18: 2.11 | K18: 1.88 | L18: 1.85 | M18: PT2- | X18: QE2-
H19: 2.2 | I19: 2.23 | J19: 2.14 | K19: 1.85 | L19: 1.81
H20: 2.27 | I20: 2.24 | J20: 2.1 | K20: 1.89 | L20: 1.81
H21: 2.22 | I21: 2.2 | J21: 2.09 | K21: 1.91 | L21: 1.86
H22: 2.23 | I22: 2.15 | J22: 2.03 | K22: 1.89 | L22: 1.8
A24: 項次 | B24: 單位 | C24: 規格 | E24: 數值 | G24: 項次 | H24: 單位 | I24: 規格 | K24: 數值 | M24: 項次 | N24: 單位 | O24: 規格 | Q24: 數值 | X24: 項次 | Y24: 單位 | Z24: 規格 | AB24: 數值
A25: 咬蝕量 | B25: um | C25: 0.3±0.1 | E25: =AVERAGE(B3:F12)-AVERAGE(B13:F22) -> #DIV/0! | G25: 咬蝕量 | H25: um | I25: 0.84±0.07 | K25: =AVERAGE(H3:L12)-AVERAGE(H13:L22) -> 1.173 | M25: 咬蝕量 | N25: um | O25: 0.3±0.1 | Q25: =AVERAGE(N3:W12)-AVERAGE(N13:W22) -> #DIV/0! | X25: 咬蝕量 | Y25: um | Z25: 0.84±0.07 | AB25: =AVERAGE(Y3:AH12)-AVERAGE(Y13:AH22) -> #DIV/0!
A26: 線速 | B26: M/min | C26: ="--" -> -- | E26: 1.7 | G26: 線速 | H26: M/min | I26: ="--" -> -- | K26: 1.4 | M26: 線速 | N26: M/min | O26: ="--" -> -- | Q26: 1.5 | X26: 線速 | Y26: M/min | Z26: ="--" -> -- | AB26: 1.5
A27: 咬蝕速率 | B27: um/min | C27: 0.55±0.17 | E27: =(E25/(0.975/E26)) -> #DIV/0! | G27: 咬蝕速率 | H27: um/min | I27: 0.75±0.07 | K27: =(K25/(1.944/K26)) -> 0.84475309 | M27: 咬蝕速率 | N27: um/min | O27: 0.55±0.17 | Q27: =(Q25/(0.975/Q26)) -> #DIV/0! | X27: 咬蝕速率 | Y27: um/min | Z27: 0.75±0.07 | AB27: =(AB25/(3.13/AB26)) -> #DIV/0!
A28: 量測日期 | C28: =TODAY() -> 46156
A29: PT-01 | G29: QE-01 | M29: PT-02 | X29: QE-02
A30: 咬蝕量 | G30: 咬蝕量 | M30: 咬蝕量 | X30: 咬蝕量
A31: PT1+ | B31: =B3-B13 -> 0 | C31: =C3-C13 -> 0 | D31: =D3-D13 -> 0 | E31: =E3-E13 -> 0 | F31: =F3-F13 -> 0 | G31: QE1+ | H31: =H3-H13 -> 1.28 | I31: =I3-I13 -> 1.29 | J31: =J3-J13 -> 1.29 | K31: =K3-K13 -> 1.31 | L31: =L3-L13 -> 1.3 | M31: PT2+ | N31: =N3-N13 -> 0 | O31: =O3-O13 -> 0 | P31: =P3-P13 -> 0 | Q31: =Q3-Q13 -> 0 | R31: =R3-R13 -> 0 | S31: =S3-S13 -> 0 | T31: =T3-T13 -> 0 | U31: =U3-U13 -> 0 | ... W31: =W3-W13 -> 0 | X31: QE2+ | Y31: =Y3-Y13 -> 0 | Z31: =Z3-Z13 -> 0 | AA31: =AA3-AA13 -> 0 | AB31: =AB3-AB13 -> 0 | AC31: =AC3-AC13 -> 0 | AD31: =AD3-AD13 -> 0 | AE31: =AE3-AE13 -> 0 | AF31: =AF3-AF13 -> 0 | ... AH31: =AH3-AH13 -> 0 | AJ31: PT | AK31: =B31 -> 0 | AL31: =B32 -> 0 | AM31: =B33 -> 0 | AN31: =B34 -> 0 | AO31: =B35 -> 0 | AP31: =C31 -> 0 | AQ31: =C32 -> 0 | AR31: =C33 -> 0 | AS31: =C34 -> 0 | AT31: =C35 -> 0 | AU31: =D31 -> 0 | AV31: =D32 -> 0 | AW31: =D33 -> 0 | AX31: =D34 -> 0 | AY31: =D35 -> 0 | AZ31: =E31 -> 0 | BA31: =E32 -> 0 | BB31: =E33 -> 0 | BC31: =E34 -> 0 | BD31: =E35 -> 0 | BE31: =F31 -> 0 | BF31: =F32 -> 0 | BG31: =F33 -> 0 | BH31: =F34 -> 0 | BI31: =F35 -> 0
B32: =B4-B14 -> 0 | C32: =C4-C14 -> 0 | D32: =D4-D14 -> 0 | E32: =E4-E14 -> 0 | F32: =F4-F14 -> 0 | H32: =H4-H14 -> 1.3 | I32: =I4-I14 -> 1.33 | J32: =J4-J14 -> 1.35 | K32: =K4-K14 -> 1.38 | L32: =L4-L14 -> 1.34 | N32: =N4-N14 -> 0 | O32: =O4-O14 -> 0 | P32: =P4-P14 -> 0 | Q32: =Q4-Q14 -> 0 | R32: =R4-R14 -> 0 | S32: =S4-S14 -> 0 | T32: =T4-T14 -> 0 | U32: =U4-U14 -> 0 | ... W32: =W4-W14 -> 0 | Y32: =Y4-Y14 -> 0 | Z32: =Z4-Z14 -> 0 | AA32: =AA4-AA14 -> 0 | AB32: =AB4-AB14 -> 0 | AC32: =AC4-AC14 -> 0 | AD32: =AD4-AD14 -> 0 | AE32: =AE4-AE14 -> 0 | AF32: =AF4-AF14 -> 0 | ... AH32: =AH4-AH14 -> 0
B33: =B5-B15 -> 0 | C33: =C5-C15 -> 0 | D33: =D5-D15 -> 0 | E33: =E5-E15 -> 0 | F33: =F5-F15 -> 0 | H33: =H5-H15 -> 1.3 | I33: =I5-I15 -> 1.31 | J33: =J5-J15 -> 1.31 | K33: =K5-K15 -> 1.35 | L33: =L5-L15 -> 1.37 | N33: =N5-N15 -> 0 | O33: =O5-O15 -> 0 | P33: =P5-P15 -> 0 | Q33: =Q5-Q15 -> 0 | R33: =R5-R15 -> 0 | S33: =S5-S15 -> 0 | T33: =T5-T15 -> 0 | U33: =U5-U15 -> 0 | ... W33: =W5-W15 -> 0 | Y33: =Y5-Y15 -> 0 | Z33: =Z5-Z15 -> 0 | AA33: =AA5-AA15 -> 0 | AB33: =AB5-AB15 -> 0 | AC33: =AC5-AC15 -> 0 | AD33: =AD5-AD15 -> 0 | AE33: =AE5-AE15 -> 0 | AF33: =AF5-AF15 -> 0 | ... AH33: =AH5-AH15 -> 0
B34: =B6-B16 -> 0 | C34: =C6-C16 -> 0 | D34: =D6-D16 -> 0 | E34: =E6-E16 -> 0 | F34: =F6-F16 -> 0 | H34: =H6-H16 -> 1.37 | I34: =I6-I16 -> 1.31 | J34: =J6-J16 -> 1.36 | K34: =K6-K16 -> 1.32 | L34: =L6-L16 -> 1.36 | N34: =N6-N16 -> 0 | O34: =O6-O16 -> 0 | P34: =P6-P16 -> 0 | Q34: =Q6-Q16 -> 0 | R34: =R6-R16 -> 0 | S34: =S6-S16 -> 0 | T34: =T6-T16 -> 0 | U34: =U6-U16 -> 0 | ... W34: =W6-W16 -> 0 | Y34: =Y6-Y16 -> 0 | Z34: =Z6-Z16 -> 0 | AA34: =AA6-AA16 -> 0 | AB34: =AB6-AB16 -> 0 | AC34: =AC6-AC16 -> 0 | AD34: =AD6-AD16 -> 0 | AE34: =AE6-AE16 -> 0 | AF34: =AF6-AF16 -> 0 | ... AH34: =AH6-AH16 -> 0
B35: =B7-B17 -> 0 | C35: =C7-C17 -> 0 | D35: =D7-D17 -> 0 | E35: =E7-E17 -> 0 | F35: =F7-F17 -> 0 | H35: =H7-H17 -> 1.29 | I35: =I7-I17 -> 1.35 | J35: =J7-J17 -> 1.42 | K35: =K7-K17 -> 1.3 | L35: =L7-L17 -> 1.32 | N35: =N7-N17 -> 0 | O35: =O7-O17 -> 0 | P35: =P7-P17 -> 0 | Q35: =Q7-Q17 -> 0 | R35: =R7-R17 -> 0 | S35: =S7-S17 -> 0 | T35: =T7-T17 -> 0 | U35: =U7-U17 -> 0 | ... W35: =W7-W17 -> 0 | Y35: =Y7-Y17 -> 0 | Z35: =Z7-Z17 -> 0 | AA35: =AA7-AA17 -> 0 | AB35: =AB7-AB17 -> 0 | AC35: =AC7-AC17 -> 0 | AD35: =AD7-AD17 -> 0 | AE35: =AE7-AE17 -> 0 | AF35: =AF7-AF17 -> 0 | ... AH35: =AH7-AH17 -> 0
A36: PT1- | B36: =B8-B18 -> 0 | C36: =C8-C18 -> 0 | D36: =D8-D18 -> 0 | E36: =E8-E18 -> 0 | F36: =F8-F18 -> 0 | G36: QE1- | H36: =H8-H18 -> 1.02 | I36: =I8-I18 -> 0.96 | J36: =J8-J18 -> 1 | K36: =K8-K18 -> 1.03 | L36: =L8-L18 -> 1 | M36: PT2- | N36: =N8-N18 -> 0 | O36: =O8-O18 -> 0 | P36: =P8-P18 -> 0 | Q36: =Q8-Q18 -> 0 | R36: =R8-R18 -> 0 | S36: =S8-S18 -> 0 | T36: =T8-T18 -> 0 | U36: =U8-U18 -> 0 | ... W36: =W8-W18 -> 0 | X36: QE2- | Y36: =Y8-Y18 -> 0 | Z36: =Z8-Z18 -> 0 | AA36: =AA8-AA18 -> 0 | AB36: =AB8-AB18 -> 0 | AC36: =AC8-AC18 -> 0 | AD36: =AD8-AD18 -> 0 | AE36: =AE8-AE18 -> 0 | AF36: =AF8-AF18 -> 0 | ... AH36: =AH8-AH18 -> 0 | AK36: =B36 -> 0 | AL36: =B37 -> 0 | AM36: =B38 -> 0 | AN36: =B39 -> 0 | AO36: =B40 -> 0 | AP36: =C36 -> 0 | AQ36: =C37 -> 0 | AR36: =C38 -> 0 | AS36: =C39 -> 0 | AT36: =C40 -> 0 | AU36: =D36 -> 0 | AV36: =D37 -> 0 | AW36: =D38 -> 0 | AX36: =D39 -> 0 | AY36: =D40 -> 0 | AZ36: =E36 -> 0 | BA36: =E37 -> 0 | BB36: =E38 -> 0 | BC36: =E39 -> 0 | BD36: =E40 -> 0 | BE36: =F36 -> 0 | BF36: =F37 -> 0 | BG36: =F38 -> 0 | BH36: =F39 -> 0 | BI36: =F40 -> 0
B37: =B9-B19 -> 0 | C37: =C9-C19 -> 0 | D37: =D9-D19 -> 0 | E37: =E9-E19 -> 0 | F37: =F9-F19 -> 0 | H37: =H9-H19 -> 0.95 | I37: =I9-I19 -> 1.09 | J37: =J9-J19 -> 1.05 | K37: =K9-K19 -> 1.01 | L37: =L9-L19 -> 1.01 | N37: =N9-N19 -> 0 | O37: =O9-O19 -> 0 | P37: =P9-P19 -> 0 | Q37: =Q9-Q19 -> 0 | R37: =R9-R19 -> 0 | S37: =S9-S19 -> 0 | T37: =T9-T19 -> 0 | U37: =U9-U19 -> 0 | ... W37: =W9-W19 -> 0 | Y37: =Y9-Y19 -> 0 | Z37: =Z9-Z19 -> 0 | AA37: =AA9-AA19 -> 0 | AB37: =AB9-AB19 -> 0 | AC37: =AC9-AC19 -> 0 | AD37: =AD9-AD19 -> 0 | AE37: =AE9-AE19 -> 0 | AF37: =AF9-AF19 -> 0 | ... AH37: =AH9-AH19 -> 0
B38: =B10-B20 -> 0 | C38: =C10-C20 -> 0 | D38: =D10-D20 -> 0 | E38: =E10-E20 -> 0 | F38: =F10-F20 -> 0 | H38: =H10-H20 -> 0.89 | I38: =I10-I20 -> 1.04 | J38: =J10-J20 -> 1.05 | K38: =K10-K20 -> 1.05 | L38: =L10-L20 -> 1.09 | N38: =N10-N20 -> 0 | O38: =O10-O20 -> 0 | P38: =P10-P20 -> 0 | Q38: =Q10-Q20 -> 0 | R38: =R10-R20 -> 0 | S38: =S10-S20 -> 0 | T38: =T10-T20 -> 0 | U38: =U10-U20 -> 0 | ... W38: =W10-W20 -> 0 | Y38: =Y10-Y20 -> 0 | Z38: =Z10-Z20 -> 0 | AA38: =AA10-AA20 -> 0 | AB38: =AB10-AB20 -> 0 | AC38: =AC10-AC20 -> 0 | AD38: =AD10-AD20 -> 0 | AE38: =AE10-AE20 -> 0 | AF38: =AF10-AF20 -> 0 | ... AH38: =AH10-AH20 -> 0 | AJ38: QE | AK38: =H31 -> 1.28 | AL38: =H32 -> 1.3 | AM38: =H33 -> 1.3 | AN38: =H34 -> 1.37 | AO38: =H35 -> 1.29 | AP38: =I31 -> 1.29 | AQ38: =I32 -> 1.33 | AR38: =I33 -> 1.31 | AS38: =I34 -> 1.31 | AT38: =I35 -> 1.35 | AU38: =J31 -> 1.29 | AV38: =J32 -> 1.35 | AW38: =J33 -> 1.31 | AX38: =J34 -> 1.36 | AY38: =J35 -> 1.42 | AZ38: =K31 -> 1.31 | BA38: =K32 -> 1.38 | BB38: =K33 -> 1.35 | BC38: =K34 -> 1.32 | BD38: =K35 -> 1.3 | BE38: =L31 -> 1.3 | BF38: =L32 -> 1.34 | BG38: =L33 -> 1.37 | BH38: =L34 -> 1.36 | BI38: =L35 -> 1.32
B39: =B11-B21 -> 0 | C39: =C11-C21 -> 0 | D39: =D11-D21 -> 0 | E39: =E11-E21 -> 0 | F39: =F11-F21 -> 0 | H39: =H11-H21 -> 0.94 | I39: =I11-I21 -> 1.01 | J39: =J11-J21 -> 1.02 | K39: =K11-K21 -> 1.02 | L39: =L11-L21 -> 1.05 | N39: =N11-N21 -> 0 | O39: =O11-O21 -> 0 | P39: =P11-P21 -> 0 | Q39: =Q11-Q21 -> 0 | R39: =R11-R21 -> 0 | S39: =S11-S21 -> 0 | T39: =T11-T21 -> 0 | U39: =U11-U21 -> 0 | ... W39: =W11-W21 -> 0 | Y39: =Y11-Y21 -> 0 | Z39: =Z11-Z21 -> 0 | AA39: =AA11-AA21 -> 0 | AB39: =AB11-AB21 -> 0 | AC39: =AC11-AC21 -> 0 | AD39: =AD11-AD21 -> 0 | AE39: =AE11-AE21 -> 0 | AF39: =AF11-AF21 -> 0 | ... AH39: =AH11-AH21 -> 0
B40: =B12-B22 -> 0 | C40: =C12-C22 -> 0 | D40: =D12-D22 -> 0 | E40: =E12-E22 -> 0 | F40: =F12-F22 -> 0 | H40: =H12-H22 -> 0.95 | I40: =I12-I22 -> 1.02 | J40: =J12-J22 -> 1.06 | K40: =K12-K22 -> 1.07 | L40: =L12-L22 -> 1.06 | N40: =N12-N22 -> 0 | O40: =O12-O22 -> 0 | P40: =P12-P22 -> 0 | Q40: =Q12-Q22 -> 0 | R40: =R12-R22 -> 0 | S40: =S12-S22 -> 0 | T40: =T12-T22 -> 0 | U40: =U12-U22 -> 0 | ... W40: =W12-W22 -> 0 | Y40: =Y12-Y22 -> 0 | Z40: =Z12-Z22 -> 0 | AA40: =AA12-AA22 -> 0 | AB40: =AB12-AB22 -> 0 | AC40: =AC12-AC22 -> 0 | AD40: =AD12-AD22 -> 0 | AE40: =AE12-AE22 -> 0 | AF40: =AF12-AF22 -> 0 | ... AH40: =AH12-AH22 -> 0
A41: A side- EA | B41: =AVERAGE(B31:F35) -> 0 | C41: R | D41: =MAX(B31:F35)-MIN(B31:F35) -> 0 | E41: ER | F41: =B41/(0.975/E26) -> 0 | G41: A side- EA | H41: =AVERAGE(H31:L35) -> 1.3284 | I41: R | J41: =MAX(H31:L35)-MIN(H31:L35) -> 0.14 | K41: ER | L41: =H41/(1.944/K26) -> 0.95666667 | M41: A side- EA | N41: =AVERAGE(N31:W35) -> 0 | O41: R | P41: =MAX(N31:W35)-MIN(N31:W35) -> 0 | Q41: ER | R41: =N41/(0.975/Q26) -> 0 | S41: % | T41: =1-(P41/2*N41) -> 1 | U41: T-R | V41: =MAX(N31:W40)-MIN(N31:W40) -> 0 | X41: A side- EA | Y41: =AVERAGE(Y31:AH35) -> 0 | Z41: R | AA41: =MAX(Y31:AH35)-MIN(Y31:AH35) -> 0 | AB41: ER | AC41: =Y41/(3.13/AB26) -> 0 | AD41: % | AE41: =1-(AA41/2*Y41) -> 1 | AF41: T-R | AG41: =MAX(Y31:AH40)-MIN(Y31:AH40) -> 0
...

Sheet 0513.
A1: PT-01 | G1: QE-01 | M1: PT-02 | X1: QE-02
A2: OP | B2: 1 | C2: 2 | D2: 3 | E2: 4 | F2: 5 | G2: OP | H2: 1 | I2: 2 | J2: 3 | K2: 4 | L2: 5 | M2: OP | N2: 1 | O2: 2 | P2: 3 | Q2: 4 | R2: 5 | S2: 6 | T2: 7 | U2: 8 | V2: 9 | W2: 10 | X2: OP | Y2: 1 | Z2: 2 | AA2: 3 | AB2: 4 | AC2: 5 | AD2: 6 | AE2: 7 | AF2: 8 | AG2: 9 | AH2: 10
A3: N2522+ | G3: N2522+ | H3: 2.87 | I3: 2.99 | J3: 3.19 | K3: 3.19 | L3: 3.13 | M3: N2522+ | X3: N2522+
H4: 2.87 | I4: 2.97 | J4: 3.2 | K4: 3.22 | L4: 3.14
H5: 2.85 | I5: 2.93 | J5: 3.15 | K5: 3.21 | L5: 3.12
H6: 2.89 | I6: 3 | J6: 3.16 | K6: 3.16 | L6: 3.08
H7: 2.84 | I7: 2.99 | J7: 3.15 | K7: 3.15 | L7: 3.17
A8: N2522- | G8: N2522- | H8: 2.86 | I8: 2.96 | J8: 3.18 | K8: 3.22 | L8: 3.14 | M8: N2522- | X8: N2522-
H9: 2.88 | I9: 2.91 | J9: 3.12 | K9: 3.24 | L9: 3.17
H10: 2.83 | I10: 2.94 | J10: 3.13 | K10: 3.21 | L10: 3.24
H11: 2.87 | I11: 2.93 | J11: 3.17 | K11: 3.25 | L11: 3.17
H12: 2.83 | I12: 2.91 | J12: 3.12 | K12: 3.27 | L12: 3.21
A13: PT1+ | G13: QE1+ | H13: 1.61 | I13: 1.71 | J13: 1.9 | K13: 1.87 | L13: 1.84 | M13: PT2+ | X13: QE2+
H14: 1.57 | I14: 1.66 | J14: 1.88 | K14: 1.88 | L14: 1.85
H15: 1.56 | I15: 1.64 | J15: 1.83 | K15: 1.87 | L15: 1.82
H16: 1.57 | I16: 1.64 | J16: 1.83 | K16: 1.85 | L16: 1.8
H17: 1.52 | I17: 1.64 | J17: 1.8 | K17: 1.83 | L17: 1.79
A18: PT1- | G18: Q1E- | H18: 1.87 | I18: 1.95 | J18: 2.22 | K18: 2.24 | L18: 2.18 | M18: PT2- | X18: QE2-
H19: 1.87 | I19: 1.92 | J19: 2.15 | K19: 2.27 | L19: 2.18
H20: 1.92 | I20: 1.94 | J20: 2.2 | K20: 2.25 | L20: 2.22
H21: 1.87 | I21: 1.93 | J21: 2.16 | K21: 2.22 | L21: 2.22
H22: 1.84 | I22: 1.87 | J22: 2.09 | K22: 2.21 | L22: 2.17
A24: 項次 | B24: 單位 | C24: 規格 | E24: 數值 | G24: 項次 | H24: 單位 | I24: 規格 | K24: 數值 | M24: 項次 | N24: 單位 | O24: 規格 | Q24: 數值 | X24: 項次 | Y24: 單位 | Z24: 規格 | AB24: 數值
A25: 咬蝕量 | B25: um | C25: 0.3±0.1 | E25: =AVERAGE(B3:F12)-AVERAGE(B13:F22) -> #DIV/0! | G25: 咬蝕量 | H25: um | I25: 0.84±0.07 | K25: =AVERAGE(H3:L12)-AVERAGE(H13:L22) -> 1.1532 | M25: 咬蝕量 | N25: um | O25: 0.3±0.1 | Q25: =AVERAGE(N3:W12)-AVERAGE(N13:W22) -> #DIV/0! | X25: 咬蝕量 | Y25: um | Z25: 0.84±0.07 | AB25: =AVERAGE(Y3:AH12)-AVERAGE(Y13:AH22) -> #DIV/0!
A26: 線速 | B26: M/min | C26: ="--" -> -- | E26: 1.7 | G26: 線速 | H26: M/min | I26: ="--" -> -- | K26: 1.4 | M26: 線速 | N26: M/min | O26: ="--" -> -- | Q26: 1.5 | X26: 線速 | Y26: M/min | Z26: ="--" -> -- | AB26: 1.5
A27: 咬蝕速率 | B27: um/min | C27: 0.55±0.17 | E27: =(E25/(0.975/E26)) -> #DIV/0! | G27: 咬蝕速率 | H27: um/min | I27: 0.75±0.07 | K27: =(K25/(1.944/K26)) -> 0.83049383 | M27: 咬蝕速率 | N27: um/min | O27: 0.55±0.17 | Q27: =(Q25/(0.975/Q26)) -> #DIV/0! | X27: 咬蝕速率 | Y27: um/min | Z27: 0.75±0.07 | AB27: =(AB25/(3.13/AB26)) -> #DIV/0!
A28: 量測日期 | C28: =TODAY() -> 46156
A29: PT-01 | G29: QE-01 | M29: PT-02 | X29: QE-02
A30: 咬蝕量 | G30: 咬蝕量 | M30: 咬蝕量 | X30: 咬蝕量
A31: PT1+ | B31: =B3-B13 -> 0 | C31: =C3-C13 -> 0 | D31: =D3-D13 -> 0 | E31: =E3-E13 -> 0 | F31: =F3-F13 -> 0 | G31: QE1+ | H31: =H3-H13 -> 1.26 | I31: =I3-I13 -> 1.28 | J31: =J3-J13 -> 1.29 | K31: =K3-K13 -> 1.32 | L31: =L3-L13 -> 1.29 | M31: PT2+ | N31: =N3-N13 -> 0 | O31: =O3-O13 -> 0 | P31: =P3-P13 -> 0 | Q31: =Q3-Q13 -> 0 | R31: =R3-R13 -> 0 | S31: =S3-S13 -> 0 | T31: =T3-T13 -> 0 | U31: =U3-U13 -> 0 | ... W31: =W3-W13 -> 0 | X31: QE2+ | Y31: =Y3-Y13 -> 0 | Z31: =Z3-Z13 -> 0 | AA31: =AA3-AA13 -> 0 | AB31: =AB3-AB13 -> 0 | AC31: =AC3-AC13 -> 0 | AD31: =AD3-AD13 -> 0 | AE31: =AE3-AE13 -> 0 | AF31: =AF3-AF13 -> 0 | ... AH31: =AH3-AH13 -> 0 | AJ31: PT | AK31: =B31 -> 0 | AL31: =B32 -> 0 | AM31: =B33 -> 0 | AN31: =B34 -> 0 | AO31: =B35 -> 0 | AP31: =C31 -> 0 | AQ31: =C32 -> 0 | AR31: =C33 -> 0 | AS31: =C34 -> 0 | AT31: =C35 -> 0 | AU31: =D31 -> 0 | AV31: =D32 -> 0 | AW31: =D33 -> 0 | AX31: =D34 -> 0 | AY31: =D35 -> 0 | AZ31: =E31 -> 0 | BA31: =E32 -> 0 | BB31: =E33 -> 0 | BC31: =E34 -> 0 | BD31: =E35 -> 0 | BE31: =F31 -> 0 | BF31: =F32 -> 0 | BG31: =F33 -> 0 | BH31: =F34 -> 0 | BI31: =F35 -> 0
B32: =B4-B14 -> 0 | C32: =C4-C14 -> 0 | D32: =D4-D14 -> 0 | E32: =E4-E14 -> 0 | F32: =F4-F14 -> 0 | H32: =H4-H14 -> 1.3 | I32: =I4-I14 -> 1.31 | J32: =J4-J14 -> 1.32 | K32: =K4-K14 -> 1.34 | L32: =L4-L14 -> 1.29 | N32: =N4-N14 -> 0 | O32: =O4-O14 -> 0 | P32: =P4-P14 -> 0 | Q32: =Q4-Q14 -> 0 | R32: =R4-R14 -> 0 | S32: =S4-S14 -> 0 | T32: =T4-T14 -> 0 | U32: =U4-U14 -> 0 | ... W32: =W4-W14 -> 0 | Y32: =Y4-Y14 -> 0 | Z32: =Z4-Z14 -> 0 | AA32: =AA4-AA14 -> 0 | AB32: =AB4-AB14 -> 0 | AC32: =AC4-AC14 -> 0 | AD32: =AD4-AD14 -> 0 | AE32: =AE4-AE14 -> 0 | AF32: =AF4-AF14 -> 0 | ... AH32: =AH4-AH14 -> 0
B33: =B5-B15 -> 0 | C33: =C5-C15 -> 0 | D33: =D5-D15 -> 0 | E33: =E5-E15 -> 0 | F33: =F5-F15 -> 0 | H33: =H5-H15 -> 1.29 | I33: =I5-I15 -> 1.29 | J33: =J5-J15 -> 1.32 | K33: =K5-K15 -> 1.34 | L33: =L5-L15 -> 1.3 | N33: =N5-N15 -> 0 | O33: =O5-O15 -> 0 | P33: =P5-P15 -> 0 | Q33: =Q5-Q15 -> 0 | R33: =R5-R15 -> 0 | S33: =S5-S15 -> 0 | T33: =T5-T15 -> 0 | U33: =U5-U15 -> 0 | ... W33: =W5-W15 -> 0 | Y33: =Y5-Y15 -> 0 | Z33: =Z5-Z15 -> 0 | AA33: =AA5-AA15 -> 0 | AB33: =AB5-AB15 -> 0 | AC33: =AC5-AC15 -> 0 | AD33: =AD5-AD15 -> 0 | AE33: =AE5-AE15 -> 0 | AF33: =AF5-AF15 -> 0 | ... AH33: =AH5-AH15 -> 0
B34: =B6-B16 -> 0 | C34: =C6-C16 -> 0 | D34: =D6-D16 -> 0 | E34: =E6-E16 -> 0 | F34: =F6-F16 -> 0 | H34: =H6-H16 -> 1.32 | I34: =I6-I16 -> 1.36 | J34: =J6-J16 -> 1.33 | K34: =K6-K16 -> 1.31 | L34: =L6-L16 -> 1.28 | N34: =N6-N16 -> 0 | O34: =O6-O16 -> 0 | P34: =P6-P16 -> 0 | Q34: =Q6-Q16 -> 0 | R34: =R6-R16 -> 0 | S34: =S6-S16 -> 0 | T34: =T6-T16 -> 0 | U34: =U6-U16 -> 0 | ... W34: =W6-W16 -> 0 | Y34: =Y6-Y16 -> 0 | Z34: =Z6-Z16 -> 0 | AA34: =AA6-AA16 -> 0 | AB34: =AB6-AB16 -> 0 | AC34: =AC6-AC16 -> 0 | AD34: =AD6-AD16 -> 0 | AE34: =AE6-AE16 -> 0 | AF34: =AF6-AF16 -> 0 | ... AH34: =AH6-AH16 -> 0
B35: =B7-B17 -> 0 | C35: =C7-C17 -> 0 | D35: =D7-D17 -> 0 | E35: =E7-E17 -> 0 | F35: =F7-F17 -> 0 | H35: =H7-H17 -> 1.32 | I35: =I7-I17 -> 1.35 | J35: =J7-J17 -> 1.35 | K35: =K7-K17 -> 1.32 | L35: =L7-L17 -> 1.38 | N35: =N7-N17 -> 0 | O35: =O7-O17 -> 0 | P35: =P7-P17 -> 0 | Q35: =Q7-Q17 -> 0 | R35: =R7-R17 -> 0 | S35: =S7-S17 -> 0 | T35: =T7-T17 -> 0 | U35: =U7-U17 -> 0 | ... W35: =W7-W17 -> 0 | Y35: =Y7-Y17 -> 0 | Z35: =Z7-Z17 -> 0 | AA35: =AA7-AA17 -> 0 | AB35: =AB7-AB17 -> 0 | AC35: =AC7-AC17 -> 0 | AD35: =AD7-AD17 -> 0 | AE35: =AE7-AE17 -> 0 | AF35: =AF7-AF17 -> 0 | ... AH35: =AH7-AH17 -> 0
A36: PT1- | B36: =B8-B18 -> 0 | C36: =C8-C18 -> 0 | D36: =D8-D18 -> 0 | E36: =E8-E18 -> 0 | F36: =F8-F18 -> 0 | G36: QE1- | H36: =H8-H18 -> 0.99 | I36: =I8-I18 -> 1.01 | J36: =J8-J18 -> 0.96 | K36: =K8-K18 -> 0.98 | L36: =L8-L18 -> 0.96 | M36: PT2- | N36: =N8-N18 -> 0 | O36: =O8-O18 -> 0 | P36: =P8-P18 -> 0 | Q36: =Q8-Q18 -> 0 | R36: =R8-R18 -> 0 | S36: =S8-S18 -> 0 | T36: =T8-T18 -> 0 | U36: =U8-U18 -> 0 | ... W36: =W8-W18 -> 0 | X36: QE2- | Y36: =Y8-Y18 -> 0 | Z36: =Z8-Z18 -> 0 | AA36: =AA8-AA18 -> 0 | AB36: =AB8-AB18 -> 0 | AC36: =AC8-AC18 -> 0 | AD36: =AD8-AD18 -> 0 | AE36: =AE8-AE18 -> 0 | AF36: =AF8-AF18 -> 0 | ... AH36: =AH8-AH18 -> 0 | AK36: =B36 -> 0 | AL36: =B37 -> 0 | AM36: =B38 -> 0 | AN36: =B39 -> 0 | AO36: =B40 -> 0 | AP36: =C36 -> 0 | AQ36: =C37 -> 0 | AR36: =C38 -> 0 | AS36: =C39 -> 0 | AT36: =C40 -> 0 | AU36: =D36 -> 0 | AV36: =D37 -> 0 | AW36: =D38 -> 0 | AX36: =D39 -> 0 | AY36: =D40 -> 0 | AZ36: =E36 -> 0 | BA36: =E37 -> 0 | BB36: =E38 -> 0 | BC36: =E39 -> 0 | BD36: =E40 -> 0 | BE36: =F36 -> 0 | BF36: =F37 -> 0 | BG36: =F38 -> 0 | BH36: =F39 -> 0 | BI36: =F40 -> 0
B37: =B9-B19 -> 0 | C37: =C9-C19 -> 0 | D37: =D9-D19 -> 0 | E37: =E9-E19 -> 0 | F37: =F9-F19 -> 0 | H37: =H9-H19 -> 1.01 | I37: =I9-I19 -> 0.99 | J37: =J9-J19 -> 0.97 | K37: =K9-K19 -> 0.97 | L37: =L9-L19 -> 0.99 | N37: =N9-N19 -> 0 | O37: =O9-O19 -> 0 | P37: =P9-P19 -> 0 | Q37: =Q9-Q19 -> 0 | R37: =R9-R19 -> 0 | S37: =S9-S19 -> 0 | T37: =T9-T19 -> 0 | U37: =U9-U19 -> 0 | ... W37: =W9-W19 -> 0 | Y37: =Y9-Y19 -> 0 | Z37: =Z9-Z19 -> 0 | AA37: =AA9-AA19 -> 0 | AB37: =AB9-AB19 -> 0 | AC37: =AC9-AC19 -> 0 | AD37: =AD9-AD19 -> 0 | AE37: =AE9-AE19 -> 0 | AF37: =AF9-AF19 -> 0 | ... AH37: =AH9-AH19 -> 0
B38: =B10-B20 -> 0 | C38: =C10-C20 -> 0 | D38: =D10-D20 -> 0 | E38: =E10-E20 -> 0 | F38: =F10-F20 -> 0 | H38: =H10-H20 -> 0.91 | I38: =I10-I20 -> 1 | J38: =J10-J20 -> 0.93 | K38: =K10-K20 -> 0.96 | L38: =L10-L20 -> 1.02 | N38: =N10-N20 -> 0 | O38: =O10-O20 -> 0 | P38: =P10-P20 -> 0 | Q38: =Q10-Q20 -> 0 | R38: =R10-R20 -> 0 | S38: =S10-S20 -> 0 | T38: =T10-T20 -> 0 | U38: =U10-U20 -> 0 | ... W38: =W10-W20 -> 0 | Y38: =Y10-Y20 -> 0 | Z38: =Z10-Z20 -> 0 | AA38: =AA10-AA20 -> 0 | AB38: =AB10-AB20 -> 0 | AC38: =AC10-AC20 -> 0 | AD38: =AD10-AD20 -> 0 | AE38: =AE10-AE20 -> 0 | AF38: =AF10-AF20 -> 0 | ... AH38: =AH10-AH20 -> 0 | AJ38: QE | AK38: =H31 -> 1.26 | AL38: =H32 -> 1.3 | AM38: =H33 -> 1.29 | AN38: =H34 -> 1.32 | AO38: =H35 -> 1.32 | AP38: =I31 -> 1.28 | AQ38: =I32 -> 1.31 | AR38: =I33 -> 1.29 | AS38: =I34 -> 1.36 | AT38: =I35 -> 1.35 | AU38: =J31 -> 1.29 | AV38: =J32 -> 1.32 | AW38: =J33 -> 1.32 | AX38: =J34 -> 1.33 | AY38: =J35 -> 1.35 | AZ38: =K31 -> 1.32 | BA38: =K32 -> 1.34 | BB38: =K33 -> 1.34 | BC38: =K34 -> 1.31 | BD38: =K35 -> 1.32 | BE38: =L31 -> 1.29 | BF38: =L32 -> 1.29 | BG38: =L33 -> 1.3 | BH38: =L34 -> 1.28 | BI38: =L35 -> 1.38
B39: =B11-B21 -> 0 | C39: =C11-C21 -> 0 | D39: =D11-D21 -> 0 | E39: =E11-E21 -> 0 | F39: =F11-F21 -> 0 | H39: =H11-H21 -> 1 | I39: =I11-I21 -> 1 | J39: =J11-J21 -> 1.01 | K39: =K11-K21 -> 1.03 | L39: =L11-L21 -> 0.95 | N39: =N11-N21 -> 0 | O39: =O11-O21 -> 0 | P39: =P11-P21 -> 0 | Q39: =Q11-Q21 -> 0 | R39: =R11-R21 -> 0 | S39: =S11-S21 -> 0 | T39: =T11-T21 -> 0 | U39: =U11-U21 -> 0 | ... W39: =W11-W21 -> 0 | Y39: =Y11-Y21 -> 0 | Z39: =Z11-Z21 -> 0 | AA39: =AA11-AA21 -> 0 | AB39: =AB11-AB21 -> 0 | AC39: =AC11-AC21 -> 0 | AD39: =AD11-AD21 -> 0 | AE39: =AE11-AE21 -> 0 | AF39: =AF11-AF21 -> 0 | ... AH39: =AH11-AH21 -> 0
B40: =B12-B22 -> 0 | C40: =C12-C22 -> 0 | D40: =D12-D22 -> 0 | E40: =E12-E22 -> 0 | F40: =F12-F22 -> 0 | H40: =H12-H22 -> 0.99 | I40: =I12-I22 -> 1.04 | J40: =J12-J22 -> 1.03 | K40: =K12-K22 -> 1.06 | L40: =L12-L22 -> 1.04 | N40: =N12-N22 -> 0 | O40: =O12-O22 -> 0 | P40: =P12-P22 -> 0 | Q40: =Q12-Q22 -> 0 | R40: =R12-R22 -> 0 | S40: =S12-S22 -> 0 | T40: =T12-T22 -> 0 | U40: =U12-U22 -> 0 | ... W40: =W12-W22 -> 0 | Y40: =Y12-Y22 -> 0 | Z40: =Z12-Z22 -> 0 | AA40: =AA12-AA22 -> 0 | AB40: =AB12-AB22 -> 0 | AC40: =AC12-AC22 -> 0 | AD40: =AD12-AD22 -> 0 | AE40: =AE12-AE22 -> 0 | AF40: =AF12-AF22 -> 0 | ... AH40: =AH12-AH22 -> 0
A41: A side- EA | B41: =AVERAGE(B31:F35) -> 0 | C41: R | D41: =MAX(B31:F35)-MIN(B31:F35) -> 0 | E41: ER | F41: =B41/(0.975/E26) -> 0 | G41: A side- EA | H41: =AVERAGE(H31:L35) -> 1.3144 | I41: R | J41: =MAX(H31:L35)-MIN(H31:L35) -> 0.12 | K41: ER | L41: =H41/(1.944/K26) -> 0.94658436 | M41: A side- EA | N41: =AVERAGE(N31:W35) -> 0 | O41: R | P41: =MAX(N31:W35)-MIN(N31:W35) -> 0 | Q41: ER | R41: =N41/(0.975/Q26) -> 0 | S41: % | T41: =1-(P41/2*N41) -> 1 | U41: T-R | V41: =MAX(N31:W40)-MIN(N31:W40) -> 0 | X41: A side- EA | Y41: =AVERAGE(Y31:AH35) -> 0 | Z41: R | AA41: =MAX(Y31:AH35)-MIN(Y31:AH35) -> 0 | AB41: ER | AC41: =Y41/(3.13/AB26) -> 0 | AD41: % | AE41: =1-(AA41/2*Y41) -> 1 | AF41: T-R | AG41: =MAX(Y31:AH40)-MIN(Y31:AH40) -> 0
...

Sheet 0512.
A1: PT-01 | G1: QE-01 | M1: PT-02 | X1: QE-02
A2: OP | B2: 1 | C2: 2 | D2: 3 | E2: 4 | F2: 5 | G2: OP | H2: 1 | I2: 2 | J2: 3 | K2: 4 | L2: 5 | M2: OP | N2: 1 | O2: 2 | P2: 3 | Q2: 4 | R2: 5 | S2: 6 | T2: 7 | U2: 8 | V2: 9 | W2: 10 | X2: OP | Y2: 1 | Z2: 2 | AA2: 3 | AB2: 4 | AC2: 5 | AD2: 6 | AE2: 7 | AF2: 8 | AG2: 9 | AH2: 10
A3: N2522+ | G3: N2522+ | H3: 2.84 | I3: 2.97 | J3: 3.19 | K3: 3.14 | L3: 3.08 | M3: N2522+ | X3: N2522+
H4: 2.82 | I4: 2.93 | J4: 3.18 | K4: 3.18 | L4: 3.13
H5: 2.85 | I5: 2.96 | J5: 3.2 | K5: 3.12 | L5: 3.15
H6: 2.79 | I6: 2.93 | J6: 3.13 | K6: 3.17 | L6: 3.11
H7: 2.76 | I7: 2.95 | J7: 3.13 | K7: 3.15 | L7: 3.17
A8: N2522- | G8: N2522- | H8: 2.82 | I8: 2.94 | J8: 3.14 | K8: 3.21 | L8: 3.24 | M8: N2522- | X8: N2522-
H9: 2.91 | I9: 2.86 | J9: 3.13 | K9: 3.22 | L9: 3.11
H10: 2.8 | I10: 2.91 | J10: 3.08 | K10: 3.23 | L10: 3.22
H11: 2.82 | I11: 2.92 | J11: 3.13 | K11: 3.28 | L11: 3.32
H12: 2.79 | I12: 2.96 | J12: 3.11 | K12: 3.26 | L12: 3.17
A13: PT1+ | G13: QE1+ | H13: 1.68 | I13: 1.73 | J13: 1.99 | K13: 1.98 | L13: 1.91 | M13: PT2+ | X13: QE2+
H14: 1.65 | I14: 1.75 | J14: 2.01 | K14: 1.97 | L14: 1.94
H15: 1.69 | I15: 1.76 | J15: 1.97 | K15: 2 | L15: 1.92
H16: 1.65 | I16: 1.74 | J16: 1.94 | K16: 2.04 | L16: 1.93
H17: 1.71 | I17: 1.75 | J17: 1.94 | K17: 1.94 | L17: 1.96
A18: PT1- | G18: Q1E- | H18: 1.93 | I18: 1.98 | J18: 2.19 | K18: 2.34 | L18: 2.28 | M18: PT2- | X18: QE2-
H19: 1.97 | I19: 2 | J19: 2.24 | K19: 2.32 | L19: 2.22
H20: 1.92 | I20: 1.98 | J20: 2.24 | K20: 2.33 | L20: 2.28
H21: 1.93 | I21: 1.97 | J21: 2.17 | K21: 2.3 | L21: 2.31
H22: 1.92 | I22: 2.03 | J22: 2.15 | K22: 2.27 | L22: 2.24
A24: 項次 | B24: 單位 | C24: 規格 | E24: 數值 | G24: 項次 | H24: 單位 | I24: 規格 | K24: 數值 | M24: 項次 | N24: 單位 | O24: 規格 | Q24: 數值 | X24: 項次 | Y24: 單位 | Z24: 規格 | AB24: 數值
A25: 咬蝕量 | B25: um | C25: 0.3±0.1 | E25: =AVERAGE(B3:F12)-AVERAGE(B13:F22) -> #DIV/0! | G25: 咬蝕量 | H25: um | I25: 0.84±0.07 | K25: =AVERAGE(H3:L12)-AVERAGE(H13:L22) -> 1.051 | M25: 咬蝕量 | N25: um | O25: 0.3±0.1 | Q25: =AVERAGE(N3:W12)-AVERAGE(N13:W22) -> #DIV/0! | X25: 咬蝕量 | Y25: um | Z25: 0.84±0.07 | AB25: =AVERAGE(Y3:AH12)-AVERAGE(Y13:AH22) -> #DIV/0!
A26: 線速 | B26: M/min | C26: ="--" -> -- | E26: 1.7 | G26: 線速 | H26: M/min | I26: ="--" -> -- | K26: 1.4 | M26: 線速 | N26: M/min | O26: ="--" -> -- | Q26: 1.5 | X26: 線速 | Y26: M/min | Z26: ="--" -> -- | AB26: 1.5
A27: 咬蝕速率 | B27: um/min | C27: 0.55±0.17 | E27: =(E25/(0.975/E26)) -> #DIV/0! | G27: 咬蝕速率 | H27: um/min | I27: 0.75±0.07 | K27: =(K25/(1.944/K26)) -> 0.756893 | M27: 咬蝕速率 | N27: um/min | O27: 0.55±0.17 | Q27: =(Q25/(0.975/Q26)) -> #DIV/0! | X27: 咬蝕速率 | Y27: um/min | Z27: 0.75±0.07 | AB27: =(AB25/(3.13/AB26)) -> #DIV/0!
A28: 量測日期 | C28: =TODAY() -> 46156
A29: PT-01 | G29: QE-01 | M29: PT-02 | X29: QE-02
A30: 咬蝕量 | G30: 咬蝕量 | M30: 咬蝕量 | X30: 咬蝕量
A31: PT1+ | B31: =B3-B13 -> 0 | C31: =C3-C13 -> 0 | D31: =D3-D13 -> 0 | E31: =E3-E13 -> 0 | F31: =F3-F13 -> 0 | G31: QE1+ | H31: =H3-H13 -> 1.16 | I31: =I3-I13 -> 1.24 | J31: =J3-J13 -> 1.2 | K31: =K3-K13 -> 1.16 | L31: =L3-L13 -> 1.17 | M31: PT2+ | N31: =N3-N13 -> 0 | O31: =O3-O13 -> 0 | P31: =P3-P13 -> 0 | Q31: =Q3-Q13 -> 0 | R31: =R3-R13 -> 0 | S31: =S3-S13 -> 0 | T31: =T3-T13 -> 0 | U31: =U3-U13 -> 0 | ... W31: =W3-W13 -> 0 | X31: QE2+ | Y31: =Y3-Y13 -> 0 | Z31: =Z3-Z13 -> 0 | AA31: =AA3-AA13 -> 0 | AB31: =AB3-AB13 -> 0 | AC31: =AC3-AC13 -> 0 | AD31: =AD3-AD13 -> 0 | AE31: =AE3-AE13 -> 0 | AF31: =AF3-AF13 -> 0 | ... AH31: =AH3-AH13 -> 0 | AJ31: PT | AK31: =B31 -> 0 | AL31: =B32 -> 0 | AM31: =B33 -> 0 | AN31: =B34 -> 0 | AO31: =B35 -> 0 | AP31: =C31 -> 0 | AQ31: =C32 -> 0 | AR31: =C33 -> 0 | AS31: =C34 -> 0 | AT31: =C35 -> 0 | AU31: =D31 -> 0 | AV31: =D32 -> 0 | AW31: =D33 -> 0 | AX31: =D34 -> 0 | AY31: =D35 -> 0 | AZ31: =E31 -> 0 | BA31: =E32 -> 0 | BB31: =E33 -> 0 | BC31: =E34 -> 0 | BD31: =E35 -> 0 | BE31: =F31 -> 0 | BF31: =F32 -> 0 | BG31: =F33 -> 0 | BH31: =F34 -> 0 | BI31: =F35 -> 0
B32: =B4-B14 -> 0 | C32: =C4-C14 -> 0 | D32: =D4-D14 -> 0 | E32: =E4-E14 -> 0 | F32: =F4-F14 -> 0 | H32: =H4-H14 -> 1.17 | I32: =I4-I14 -> 1.18 | J32: =J4-J14 -> 1.17 | K32: =K4-K14 -> 1.21 | L32: =L4-L14 -> 1.19 | N32: =N4-N14 -> 0 | O32: =O4-O14 -> 0 | P32: =P4-P14 -> 0 | Q32: =Q4-Q14 -> 0 | R32: =R4-R14 -> 0 | S32: =S4-S14 -> 0 | T32: =T4-T14 -> 0 | U32: =U4-U14 -> 0 | ... W32: =W4-W14 -> 0 | Y32: =Y4-Y14 -> 0 | Z32: =Z4-Z14 -> 0 | AA32: =AA4-AA14 -> 0 | AB32: =AB4-AB14 -> 0 | AC32: =AC4-AC14 -> 0 | AD32: =AD4-AD14 -> 0 | AE32: =AE4-AE14 -> 0 | AF32: =AF4-AF14 -> 0 | ... AH32: =AH4-AH14 -> 0
B33: =B5-B15 -> 0 | C33: =C5-C15 -> 0 | D33: =D5-D15 -> 0 | E33: =E5-E15 -> 0 | F33: =F5-F15 -> 0 | H33: =H5-H15 -> 1.16 | I33: =I5-I15 -> 1.2 | J33: =J5-J15 -> 1.23 | K33: =K5-K15 -> 1.12 | L33: =L5-L15 -> 1.23 | N33: =N5-N15 -> 0 | O33: =O5-O15 -> 0 | P33: =P5-P15 -> 0 | Q33: =Q5-Q15 -> 0 | R33: =R5-R15 -> 0 | S33: =S5-S15 -> 0 | T33: =T5-T15 -> 0 | U33: =U5-U15 -> 0 | ... W33: =W5-W15 -> 0 | Y33: =Y5-Y15 -> 0 | Z33: =Z5-Z15 -> 0 | AA33: =AA5-AA15 -> 0 | AB33: =AB5-AB15 -> 0 | AC33: =AC5-AC15 -> 0 | AD33: =AD5-AD15 -> 0 | AE33: =AE5-AE15 -> 0 | AF33: =AF5-AF15 -> 0 | ... AH33: =AH5-AH15 -> 0
B34: =B6-B16 -> 0 | C34: =C6-C16 -> 0 | D34: =D6-D16 -> 0 | E34: =E6-E16 -> 0 | F34: =F6-F16 -> 0 | H34: =H6-H16 -> 1.14 | I34: =I6-I16 -> 1.19 | J34: =J6-J16 -> 1.19 | K34: =K6-K16 -> 1.13 | L34: =L6-L16 -> 1.18 | N34: =N6-N16 -> 0 | O34: =O6-O16 -> 0 | P34: =P6-P16 -> 0 | Q34: =Q6-Q16 -> 0 | R34: =R6-R16 -> 0 | S34: =S6-S16 -> 0 | T34: =T6-T16 -> 0 | U34: =U6-U16 -> 0 | ... W34: =W6-W16 -> 0 | Y34: =Y6-Y16 -> 0 | Z34: =Z6-Z16 -> 0 | AA34: =AA6-AA16 -> 0 | AB34: =AB6-AB16 -> 0 | AC34: =AC6-AC16 -> 0 | AD34: =AD6-AD16 -> 0 | AE34: =AE6-AE16 -> 0 | AF34: =AF6-AF16 -> 0 | ... AH34: =AH6-AH16 -> 0
B35: =B7-B17 -> 0 | C35: =C7-C17 -> 0 | D35: =D7-D17 -> 0 | E35: =E7-E17 -> 0 | F35: =F7-F17 -> 0 | H35: =H7-H17 -> 1.05 | I35: =I7-I17 -> 1.2 | J35: =J7-J17 -> 1.19 | K35: =K7-K17 -> 1.21 | L35: =L7-L17 -> 1.21 | N35: =N7-N17 -> 0 | O35: =O7-O17 -> 0 | P35: =P7-P17 -> 0 | Q35: =Q7-Q17 -> 0 | R35: =R7-R17 -> 0 | S35: =S7-S17 -> 0 | T35: =T7-T17 -> 0 | U35: =U7-U17 -> 0 | ... W35: =W7-W17 -> 0 | Y35: =Y7-Y17 -> 0 | Z35: =Z7-Z17 -> 0 | AA35: =AA7-AA17 -> 0 | AB35: =AB7-AB17 -> 0 | AC35: =AC7-AC17 -> 0 | AD35: =AD7-AD17 -> 0 | AE35: =AE7-AE17 -> 0 | AF35: =AF7-AF17 -> 0 | ... AH35: =AH7-AH17 -> 0
A36: PT1- | B36: =B8-B18 -> 0 | C36: =C8-C18 -> 0 | D36: =D8-D18 -> 0 | E36: =E8-E18 -> 0 | F36: =F8-F18 -> 0 | G36: QE1- | H36: =H8-H18 -> 0.89 | I36: =I8-I18 -> 0.96 | J36: =J8-J18 -> 0.95 | K36: =K8-K18 -> 0.87 | L36: =L8-L18 -> 0.96 | M36: PT2- | N36: =N8-N18 -> 0 | O36: =O8-O18 -> 0 | P36: =P8-P18 -> 0 | Q36: =Q8-Q18 -> 0 | R36: =R8-R18 -> 0 | S36: =S8-S18 -> 0 | T36: =T8-T18 -> 0 | U36: =U8-U18 -> 0 | ... W36: =W8-W18 -> 0 | X36: QE2- | Y36: =Y8-Y18 -> 0 | Z36: =Z8-Z18 -> 0 | AA36: =AA8-AA18 -> 0 | AB36: =AB8-AB18 -> 0 | AC36: =AC8-AC18 -> 0 | AD36: =AD8-AD18 -> 0 | AE36: =AE8-AE18 -> 0 | AF36: =AF8-AF18 -> 0 | ... AH36: =AH8-AH18 -> 0 | AK36: =B36 -> 0 | AL36: =B37 -> 0 | AM36: =B38 -> 0 | AN36: =B39 -> 0 | AO36: =B40 -> 0 | AP36: =C36 -> 0 | AQ36: =C37 -> 0 | AR36: =C38 -> 0 | AS36: =C39 -> 0 | AT36: =C40 -> 0 | AU36: =D36 -> 0 | AV36: =D37 -> 0 | AW36: =D38 -> 0 | AX36: =D39 -> 0 | AY36: =D40 -> 0 | AZ36: =E36 -> 0 | BA36: =E37 -> 0 | BB36: =E38 -> 0 | BC36: =E39 -> 0 | BD36: =E40 -> 0 | BE36: =F36 -> 0 | BF36: =F37 -> 0 | BG36: =F38 -> 0 | BH36: =F39 -> 0 | BI36: =F40 -> 0
B37: =B9-B19 -> 0 | C37: =C9-C19 -> 0 | D37: =D9-D19 -> 0 | E37: =E9-E19 -> 0 | F37: =F9-F19 -> 0 | H37: =H9-H19 -> 0.94 | I37: =I9-I19 -> 0.86 | J37: =J9-J19 -> 0.89 | K37: =K9-K19 -> 0.9 | L37: =L9-L19 -> 0.89 | N37: =N9-N19 -> 0 | O37: =O9-O19 -> 0 | P37: =P9-P19 -> 0 | Q37: =Q9-Q19 -> 0 | R37: =R9-R19 -> 0 | S37: =S9-S19 -> 0 | T37: =T9-T19 -> 0 | U37: =U9-U19 -> 0 | ... W37: =W9-W19 -> 0 | Y37: =Y9-Y19 -> 0 | Z37: =Z9-Z19 -> 0 | AA37: =AA9-AA19 -> 0 | AB37: =AB9-AB19 -> 0 | AC37: =AC9-AC19 -> 0 | AD37: =AD9-AD19 -> 0 | AE37: =AE9-AE19 -> 0 | AF37: =AF9-AF19 -> 0 | ... AH37: =AH9-AH19 -> 0
B38: =B10-B20 -> 0 | C38: =C10-C20 -> 0 | D38: =D10-D20 -> 0 | E38: =E10-E20 -> 0 | F38: =F10-F20 -> 0 | H38: =H10-H20 -> 0.88 | I38: =I10-I20 -> 0.93 | J38: =J10-J20 -> 0.84 | K38: =K10-K20 -> 0.9 | L38: =L10-L20 -> 0.94 | N38: =N10-N20 -> 0 | O38: =O10-O20 -> 0 | P38: =P10-P20 -> 0 | Q38: =Q10-Q20 -> 0 | R38: =R10-R20 -> 0 | S38: =S10-S20 -> 0 | T38: =T10-T20 -> 0 | U38: =U10-U20 -> 0 | ... W38: =W10-W20 -> 0 | Y38: =Y10-Y20 -> 0 | Z38: =Z10-Z20 -> 0 | AA38: =AA10-AA20 -> 0 | AB38: =AB10-AB20 -> 0 | AC38: =AC10-AC20 -> 0 | AD38: =AD10-AD20 -> 0 | AE38: =AE10-AE20 -> 0 | AF38: =AF10-AF20 -> 0 | ... AH38: =AH10-AH20 -> 0 | AJ38: QE | AK38: =H31 -> 1.16 | AL38: =H32 -> 1.17 | AM38: =H33 -> 1.16 | AN38: =H34 -> 1.14 | AO38: =H35 -> 1.05 | AP38: =I31 -> 1.24 | AQ38: =I32 -> 1.18 | AR38: =I33 -> 1.2 | AS38: =I34 -> 1.19 | AT38: =I35 -> 1.2 | AU38: =J31 -> 1.2 | AV38: =J32 -> 1.17 | AW38: =J33 -> 1.23 | AX38: =J34 -> 1.19 | AY38: =J35 -> 1.19 | AZ38: =K31 -> 1.16 | BA38: =K32 -> 1.21 | BB38: =K33 -> 1.12 | BC38: =K34 -> 1.13 | BD38: =K35 -> 1.21 | BE38: =L31 -> 1.17 | BF38: =L32 -> 1.19 | BG38: =L33 -> 1.23 | BH38: =L34 -> 1.18 | BI38: =L35 -> 1.21
B39: =B11-B21 -> 0 | C39: =C11-C21 -> 0 | D39: =D11-D21 -> 0 | E39: =E11-E21 -> 0 | F39: =F11-F21 -> 0 | H39: =H11-H21 -> 0.89 | I39: =I11-I21 -> 0.95 | J39: =J11-J21 -> 0.96 | K39: =K11-K21 -> 0.98 | L39: =L11-L21 -> 1.01 | N39: =N11-N21 -> 0 | O39: =O11-O21 -> 0 | P39: =P11-P21 -> 0 | Q39: =Q11-Q21 -> 0 | R39: =R11-R21 -> 0 | S39: =S11-S21 -> 0 | T39: =T11-T21 -> 0 | U39: =U11-U21 -> 0 | ... W39: =W11-W21 -> 0 | Y39: =Y11-Y21 -> 0 | Z39: =Z11-Z21 -> 0 | AA39: =AA11-AA21 -> 0 | AB39: =AB11-AB21 -> 0 | AC39: =AC11-AC21 -> 0 | AD39: =AD11-AD21 -> 0 | AE39: =AE11-AE21 -> 0 | AF39: =AF11-AF21 -> 0 | ... AH39: =AH11-AH21 -> 0
B40: =B12-B22 -> 0 | C40: =C12-C22 -> 0 | D40: =D12-D22 -> 0 | E40: =E12-E22 -> 0 | F40: =F12-F22 -> 0 | H40: =H12-H22 -> 0.87 | I40: =I12-I22 -> 0.93 | J40: =J12-J22 -> 0.96 | K40: =K12-K22 -> 0.99 | L40: =L12-L22 -> 0.93 | N40: =N12-N22 -> 0 | O40: =O12-O22 -> 0 | P40: =P12-P22 -> 0 | Q40: =Q12-Q22 -> 0 | R40: =R12-R22 -> 0 | S40: =S12-S22 -> 0 | T40: =T12-T22 -> 0 | U40: =U12-U22 -> 0 | ... W40: =W12-W22 -> 0 | Y40: =Y12-Y22 -> 0 | Z40: =Z12-Z22 -> 0 | AA40: =AA12-AA22 -> 0 | AB40: =AB12-AB22 -> 0 | AC40: =AC12-AC22 -> 0 | AD40: =AD12-AD22 -> 0 | AE40: =AE12-AE22 -> 0 | AF40: =AF12-AF22 -> 0 | ... AH40: =AH12-AH22 -> 0
A41: A side- EA | B41: =AVERAGE(B31:F35) -> 0 | C41: R | D41: =MAX(B31:F35)-MIN(B31:F35) -> 0 | E41: ER | F41: =B41/(0.975/E26) -> 0 | G41: A side- EA | H41: =AVERAGE(H31:L35) -> 1.1792 | I41: R | J41: =MAX(H31:L35)-MIN(H31:L35) -> 0.19 | K41: ER | L41: =H41/(1.944/K26) -> 0.84921811 | M41: A side- EA | N41: =AVERAGE(N31:W35) -> 0 | O41: R | P41: =MAX(N31:W35)-MIN(N31:W35) -> 0 | Q41: ER | R41: =N41/(0.975/Q26) -> 0 | S41: % | T41: =1-(P41/2*N41) -> 1 | U41: T-R | V41: =MAX(N31:W40)-MIN(N31:W40) -> 0 | X41: A side- EA | Y41: =AVERAGE(Y31:AH35) -> 0 | Z41: R | AA41: =MAX(Y31:AH35)-MIN(Y31:AH35) -> 0 | AB41: ER | AC41: =Y41/(3.13/AB26) -> 0 | AD41: % | AE41: =1-(AA41/2*Y41) -> 1 | AF41: T-R | AG41: =MAX(Y31:AH40)-MIN(Y31:AH40) -> 0
...

Sheet 0511.
A1: PT-01 | G1: QE-01 | M1: PT-02 | X1: QE-02
A2: OP | B2: 1 | C2: 2 | D2: 3 | E2: 4 | F2: 5 | G2: OP | H2: 1 | I2: 2 | J2: 3 | K2: 4 | L2: 5 | M2: OP | N2: 1 | O2: 2 | P2: 3 | Q2: 4 | R2: 5 | S2: 6 | T2: 7 | U2: 8 | V2: 9 | W2: 10 | X2: OP | Y2: 1 | Z2: 2 | AA2: 3 | AB2: 4 | AC2: 5 | AD2: 6 | AE2: 7 | AF2: 8 | AG2: 9 | AH2: 10
A3: N2522+ | G3: N2522+ | H3: 2.83 | I3: 2.98 | J3: 3.15 | K3: 3.14 | L3: 3.15 | M3: N2522+ | X3: N2522+
H4: 2.79 | I4: 2.94 | J4: 3.2 | K4: 3.2 | L4: 3.08
H5: 2.79 | I5: 2.92 | J5: 3.11 | K5: 3.17 | L5: 3.23
H6: 2.85 | I6: 2.91 | J6: 3.18 | K6: 3.16 | L6: 3.09
H7: 2.82 | I7: 2.91 | J7: 3.18 | K7: 3.18 | L7: 3.12
A8: N2522- | G8: N2522- | H8: 2.84 | I8: 2.9 | J8: 3.15 | K8: 3.18 | L8: 3.18 | M8: N2522- | X8: N2522-
H9: 2.88 | I9: 2.96 | J9: 3.15 | K9: 3.3 | L9: 3.23
H10: 2.85 | I10: 2.93 | J10: 3.16 | K10: 3.29 | L10: 3.29
H11: 3.83 | I11: 2.93 | J11: 3.07 | K11: 3.17 | L11: 3.21
H12: 2.91 | I12: 2.94 | J12: 3.17 | K12: 3.28 | L12: 3.16
A13: PT1+ | G13: QE1+ | H13: 1.8 | I13: 1.89 | J13: 2.1 | K13: 2.13 | L13: 2.06 | M13: PT2+ | X13: QE2+
H14: 1.82 | I14: 1.92 | J14: 2.13 | K14: 2.1 | L14: 2.07
H15: 1.81 | I15: 1.94 | J15: 2.07 | K15: 2.11 | L15: 2.06
H16: 1.82 | I16: 1.91 | J16: 2.11 | K16: 2.14 | L16: 2.03
H17: 1.78 | I17: 1.94 | J17: 2.09 | K17: 2.11 | L17: 2.04
A18: PT1- | G18: Q1E- | H18: 2.05 | I18: 2.08 | J18: 2.34 | K18: 2.43 | L18: 2.37 | M18: PT2- | X18: QE2-
H19: 2.08 | I19: 2.14 | J19: 2.37 | K19: 2.45 | L19: 2.37
H20: 2.05 | I20: 2.15 | J20: 2.38 | K20: 2.46 | L20: 2.4
H21: 2.04 | I21: 2.11 | J21: 2.35 | K21: 2.37 | L21: 2.33
H22: 2.09 | I22: 2.08 | J22: 2.36 | K22: 2.38 | L22: 2.3
A24: 項次 | B24: 單位 | C24: 規格 | E24: 數值 | G24: 項次 | H24: 單位 | I24: 規格 | K24: 數值 | M24: 項次 | N24: 單位 | O24: 規格 | Q24: 數值 | X24: 項次 | Y24: 單位 | Z24: 規格 | AB24: 數值
A25: 咬蝕量 | B25: um | C25: 0.3±0.1 | E25: =AVERAGE(B3:F12)-AVERAGE(B13:F22) -> #DIV/0! | G25: 咬蝕量 | H25: um | I25: 0.84±0.07 | K25: =AVERAGE(H3:L12)-AVERAGE(H13:L22) -> 0.9506 | M25: 咬蝕量 | N25: um | O25: 0.3±0.1 | Q25: =AVERAGE(N3:W12)-AVERAGE(N13:W22) -> #DIV/0! | X25: 咬蝕量 | Y25: um | Z25: 0.84±0.07 | AB25: =AVERAGE(Y3:AH12)-AVERAGE(Y13:AH22) -> #DIV/0!
A26: 線速 | B26: M/min | C26: ="--" -> -- | E26: 1.7 | G26: 線速 | H26: M/min | I26: ="--" -> -- | K26: 1.4 | M26: 線速 | N26: M/min | O26: ="--" -> -- | Q26: 1.5 | X26: 線速 | Y26: M/min | Z26: ="--" -> -- | AB26: 1.5
A27: 咬蝕速率 | B27: um/min | C27: 0.55±0.17 | E27: =(E25/(0.975/E26)) -> #DIV/0! | G27: 咬蝕速率 | H27: um/min | I27: 0.75±0.07 | K27: =(K25/(1.944/K26)) -> 0.68458848 | M27: 咬蝕速率 | N27: um/min | O27: 0.55±0.17 | Q27: =(Q25/(0.975/Q26)) -> #DIV/0! | X27: 咬蝕速率 | Y27: um/min | Z27: 0.75±0.07 | AB27: =(AB25/(3.13/AB26)) -> #DIV/0!
A28: 量測日期 | C28: =TODAY() -> 46156
A29: PT-01 | G29: QE-01 | M29: PT-02 | X29: QE-02
A30: 咬蝕量 | G30: 咬蝕量 | M30: 咬蝕量 | X30: 咬蝕量
A31: PT1+ | B31: =B3-B13 -> 0 | C31: =C3-C13 -> 0 | D31: =D3-D13 -> 0 | E31: =E3-E13 -> 0 | F31: =F3-F13 -> 0 | G31: QE1+ | H31: =H3-H13 -> 1.03 | I31: =I3-I13 -> 1.09 | J31: =J3-J13 -> 1.05 | K31: =K3-K13 -> 1.01 | L31: =L3-L13 -> 1.09 | M31: PT2+ | N31: =N3-N13 -> 0 | O31: =O3-O13 -> 0 | P31: =P3-P13 -> 0 | Q31: =Q3-Q13 -> 0 | R31: =R3-R13 -> 0 | S31: =S3-S13 -> 0 | T31: =T3-T13 -> 0 | U31: =U3-U13 -> 0 | ... W31: =W3-W13 -> 0 | X31: QE2+ | Y31: =Y3-Y13 -> 0 | Z31: =Z3-Z13 -> 0 | AA31: =AA3-AA13 -> 0 | AB31: =AB3-AB13 -> 0 | AC31: =AC3-AC13 -> 0 | AD31: =AD3-AD13 -> 0 | AE31: =AE3-AE13 -> 0 | AF31: =AF3-AF13 -> 0 | ... AH31: =AH3-AH13 -> 0 | AJ31: PT | AK31: =B31 -> 0 | AL31: =B32 -> 0 | AM31: =B33 -> 0 | AN31: =B34 -> 0 | AO31: =B35 -> 0 | AP31: =C31 -> 0 | AQ31: =C32 -> 0 | AR31: =C33 -> 0 | AS31: =C34 -> 0 | AT31: =C35 -> 0 | AU31: =D31 -> 0 | AV31: =D32 -> 0 | AW31: =D33 -> 0 | AX31: =D34 -> 0 | AY31: =D35 -> 0 | AZ31: =E31 -> 0 | BA31: =E32 -> 0 | BB31: =E33 -> 0 | BC31: =E34 -> 0 | BD31: =E35 -> 0 | BE31: =F31 -> 0 | BF31: =F32 -> 0 | BG31: =F33 -> 0 | BH31: =F34 -> 0 | BI31: =F35 -> 0
B32: =B4-B14 -> 0 | C32: =C4-C14 -> 0 | D32: =D4-D14 -> 0 | E32: =E4-E14 -> 0 | F32: =F4-F14 -> 0 | H32: =H4-H14 -> 0.97 | I32: =I4-I14 -> 1.02 | J32: =J4-J14 -> 1.07 | K32: =K4-K14 -> 1.1 | L32: =L4-L14 -> 1.01 | N32: =N4-N14 -> 0 | O32: =O4-O14 -> 0 | P32: =P4-P14 -> 0 | Q32: =Q4-Q14 -> 0 | R32: =R4-R14 -> 0 | S32: =S4-S14 -> 0 | T32: =T4-T14 -> 0 | U32: =U4-U14 -> 0 | ... W32: =W4-W14 -> 0 | Y32: =Y4-Y14 -> 0 | Z32: =Z4-Z14 -> 0 | AA32: =AA4-AA14 -> 0 | AB32: =AB4-AB14 -> 0 | AC32: =AC4-AC14 -> 0 | AD32: =AD4-AD14 -> 0 | AE32: =AE4-AE14 -> 0 | AF32: =AF4-AF14 -> 0 | ... AH32: =AH4-AH14 -> 0
B33: =B5-B15 -> 0 | C33: =C5-C15 -> 0 | D33: =D5-D15 -> 0 | E33: =E5-E15 -> 0 | F33: =F5-F15 -> 0 | H33: =H5-H15 -> 0.98 | I33: =I5-I15 -> 0.98 | J33: =J5-J15 -> 1.04 | K33: =K5-K15 -> 1.06 | L33: =L5-L15 -> 1.17 | N33: =N5-N15 -> 0 | O33: =O5-O15 -> 0 | P33: =P5-P15 -> 0 | Q33: =Q5-Q15 -> 0 | R33: =R5-R15 -> 0 | S33: =S5-S15 -> 0 | T33: =T5-T15 -> 0 | U33: =U5-U15 -> 0 | ... W33: =W5-W15 -> 0 | Y33: =Y5-Y15 -> 0 | Z33: =Z5-Z15 -> 0 | AA33: =AA5-AA15 -> 0 | AB33: =AB5-AB15 -> 0 | AC33: =AC5-AC15 -> 0 | AD33: =AD5-AD15 -> 0 | AE33: =AE5-AE15 -> 0 | AF33: =AF5-AF15 -> 0 | ... AH33: =AH5-AH15 -> 0
B34: =B6-B16 -> 0 | C34: =C6-C16 -> 0 | D34: =D6-D16 -> 0 | E34: =E6-E16 -> 0 | F34: =F6-F16 -> 0 | H34: =H6-H16 -> 1.03 | I34: =I6-I16 -> 1 | J34: =J6-J16 -> 1.07 | K34: =K6-K16 -> 1.02 | L34: =L6-L16 -> 1.06 | N34: =N6-N16 -> 0 | O34: =O6-O16 -> 0 | P34: =P6-P16 -> 0 | Q34: =Q6-Q16 -> 0 | R34: =R6-R16 -> 0 | S34: =S6-S16 -> 0 | T34: =T6-T16 -> 0 | U34: =U6-U16 -> 0 | ... W34: =W6-W16 -> 0 | Y34: =Y6-Y16 -> 0 | Z34: =Z6-Z16 -> 0 | AA34: =AA6-AA16 -> 0 | AB34: =AB6-AB16 -> 0 | AC34: =AC6-AC16 -> 0 | AD34: =AD6-AD16 -> 0 | AE34: =AE6-AE16 -> 0 | AF34: =AF6-AF16 -> 0 | ... AH34: =AH6-AH16 -> 0
B35: =B7-B17 -> 0 | C35: =C7-C17 -> 0 | D35: =D7-D17 -> 0 | E35: =E7-E17 -> 0 | F35: =F7-F17 -> 0 | H35: =H7-H17 -> 1.04 | I35: =I7-I17 -> 0.97 | J35: =J7-J17 -> 1.09 | K35: =K7-K17 -> 1.07 | L35: =L7-L17 -> 1.08 | N35: =N7-N17 -> 0 | O35: =O7-O17 -> 0 | P35: =P7-P17 -> 0 | Q35: =Q7-Q17 -> 0 | R35: =R7-R17 -> 0 | S35: =S7-S17 -> 0 | T35: =T7-T17 -> 0 | U35: =U7-U17 -> 0 | ... W35: =W7-W17 -> 0 | Y35: =Y7-Y17 -> 0 | Z35: =Z7-Z17 -> 0 | AA35: =AA7-AA17 -> 0 | AB35: =AB7-AB17 -> 0 | AC35: =AC7-AC17 -> 0 | AD35: =AD7-AD17 -> 0 | AE35: =AE7-AE17 -> 0 | AF35: =AF7-AF17 -> 0 | ... AH35: =AH7-AH17 -> 0
A36: PT1- | B36: =B8-B18 -> 0 | C36: =C8-C18 -> 0 | D36: =D8-D18 -> 0 | E36: =E8-E18 -> 0 | F36: =F8-F18 -> 0 | G36: QE1- | H36: =H8-H18 -> 0.79 | I36: =I8-I18 -> 0.82 | J36: =J8-J18 -> 0.81 | K36: =K8-K18 -> 0.75 | L36: =L8-L18 -> 0.81 | M36: PT2- | N36: =N8-N18 -> 0 | O36: =O8-O18 -> 0 | P36: =P8-P18 -> 0 | Q36: =Q8-Q18 -> 0 | R36: =R8-R18 -> 0 | S36: =S8-S18 -> 0 | T36: =T8-T18 -> 0 | U36: =U8-U18 -> 0 | ... W36: =W8-W18 -> 0 | X36: QE2- | Y36: =Y8-Y18 -> 0 | Z36: =Z8-Z18 -> 0 | AA36: =AA8-AA18 -> 0 | AB36: =AB8-AB18 -> 0 | AC36: =AC8-AC18 -> 0 | AD36: =AD8-AD18 -> 0 | AE36: =AE8-AE18 -> 0 | AF36: =AF8-AF18 -> 0 | ... AH36: =AH8-AH18 -> 0 | AK36: =B36 -> 0 | AL36: =B37 -> 0 | AM36: =B38 -> 0 | AN36: =B39 -> 0 | AO36: =B40 -> 0 | AP36: =C36 -> 0 | AQ36: =C37 -> 0 | AR36: =C38 -> 0 | AS36: =C39 -> 0 | AT36: =C40 -> 0 | AU36: =D36 -> 0 | AV36: =D37 -> 0 | AW36: =D38 -> 0 | AX36: =D39 -> 0 | AY36: =D40 -> 0 | AZ36: =E36 -> 0 | BA36: =E37 -> 0 | BB36: =E38 -> 0 | BC36: =E39 -> 0 | BD36: =E40 -> 0 | BE36: =F36 -> 0 | BF36: =F37 -> 0 | BG36: =F38 -> 0 | BH36: =F39 -> 0 | BI36: =F40 -> 0
B37: =B9-B19 -> 0 | C37: =C9-C19 -> 0 | D37: =D9-D19 -> 0 | E37: =E9-E19 -> 0 | F37: =F9-F19 -> 0 | H37: =H9-H19 -> 0.8 | I37: =I9-I19 -> 0.82 | J37: =J9-J19 -> 0.78 | K37: =K9-K19 -> 0.85 | L37: =L9-L19 -> 0.86 | N37: =N9-N19 -> 0 | O37: =O9-O19 -> 0 | P37: =P9-P19 -> 0 | Q37: =Q9-Q19 -> 0 | R37: =R9-R19 -> 0 | S37: =S9-S19 -> 0 | T37: =T9-T19 -> 0 | U37: =U9-U19 -> 0 | ... W37: =W9-W19 -> 0 | Y37: =Y9-Y19 -> 0 | Z37: =Z9-Z19 -> 0 | AA37: =AA9-AA19 -> 0 | AB37: =AB9-AB19 -> 0 | AC37: =AC9-AC19 -> 0 | AD37: =AD9-AD19 -> 0 | AE37: =AE9-AE19 -> 0 | AF37: =AF9-AF19 -> 0 | ... AH37: =AH9-AH19 -> 0
B38: =B10-B20 -> 0 | C38: =C10-C20 -> 0 | D38: =D10-D20 -> 0 | E38: =E10-E20 -> 0 | F38: =F10-F20 -> 0 | H38: =H10-H20 -> 0.8 | I38: =I10-I20 -> 0.78 | J38: =J10-J20 -> 0.78 | K38: =K10-K20 -> 0.83 | L38: =L10-L20 -> 0.89 | N38: =N10-N20 -> 0 | O38: =O10-O20 -> 0 | P38: =P10-P20 -> 0 | Q38: =Q10-Q20 -> 0 | R38: =R10-R20 -> 0 | S38: =S10-S20 -> 0 | T38: =T10-T20 -> 0 | U38: =U10-U20 -> 0 | ... W38: =W10-W20 -> 0 | Y38: =Y10-Y20 -> 0 | Z38: =Z10-Z20 -> 0 | AA38: =AA10-AA20 -> 0 | AB38: =AB10-AB20 -> 0 | AC38: =AC10-AC20 -> 0 | AD38: =AD10-AD20 -> 0 | AE38: =AE10-AE20 -> 0 | AF38: =AF10-AF20 -> 0 | ... AH38: =AH10-AH20 -> 0 | AJ38: QE | AK38: =H31 -> 1.03 | AL38: =H32 -> 0.97 | AM38: =H33 -> 0.98 | AN38: =H34 -> 1.03 | AO38: =H35 -> 1.04 | AP38: =I31 -> 1.09 | AQ38: =I32 -> 1.02 | AR38: =I33 -> 0.98 | AS38: =I34 -> 1 | AT38: =I35 -> 0.97 | AU38: =J31 -> 1.05 | AV38: =J32 -> 1.07 | AW38: =J33 -> 1.04 | AX38: =J34 -> 1.07 | AY38: =J35 -> 1.09 | AZ38: =K31 -> 1.01 | BA38: =K32 -> 1.1 | BB38: =K33 -> 1.06 | BC38: =K34 -> 1.02 | BD38: =K35 -> 1.07 | BE38: =L31 -> 1.09 | BF38: =L32 -> 1.01 | BG38: =L33 -> 1.17 | BH38: =L34 -> 1.06 | BI38: =L35 -> 1.08
B39: =B11-B21 -> 0 | C39: =C11-C21 -> 0 | D39: =D11-D21 -> 0 | E39: =E11-E21 -> 0 | F39: =F11-F21 -> 0 | H39: =H11-H21 -> 1.79 | I39: =I11-I21 -> 0.82 | J39: =J11-J21 -> 0.72 | K39: =K11-K21 -> 0.8 | L39: =L11-L21 -> 0.88 | N39: =N11-N21 -> 0 | O39: =O11-O21 -> 0 | P39: =P11-P21 -> 0 | Q39: =Q11-Q21 -> 0 | R39: =R11-R21 -> 0 | S39: =S11-S21 -> 0 | T39: =T11-T21 -> 0 | U39: =U11-U21 -> 0 | ... W39: =W11-W21 -> 0 | Y39: =Y11-Y21 -> 0 | Z39: =Z11-Z21 -> 0 | AA39: =AA11-AA21 -> 0 | AB39: =AB11-AB21 -> 0 | AC39: =AC11-AC21 -> 0 | AD39: =AD11-AD21 -> 0 | AE39: =AE11-AE21 -> 0 | AF39: =AF11-AF21 -> 0 | ... AH39: =AH11-AH21 -> 0
B40: =B12-B22 -> 0 | C40: =C12-C22 -> 0 | D40: =D12-D22 -> 0 | E40: =E12-E22 -> 0 | F40: =F12-F22 -> 0 | H40: =H12-H22 -> 0.82 | I40: =I12-I22 -> 0.86 | J40: =J12-J22 -> 0.81 | K40: =K12-K22 -> 0.9 | L40: =L12-L22 -> 0.86 | N40: =N12-N22 -> 0 | O40: =O12-O22 -> 0 | P40: =P12-P22 -> 0 | Q40: =Q12-Q22 -> 0 | R40: =R12-R22 -> 0 | S40: =S12-S22 -> 0 | T40: =T12-T22 -> 0 | U40: =U12-U22 -> 0 | ... W40: =W12-W22 -> 0 | Y40: =Y12-Y22 -> 0 | Z40: =Z12-Z22 -> 0 | AA40: =AA12-AA22 -> 0 | AB40: =AB12-AB22 -> 0 | AC40: =AC12-AC22 -> 0 | AD40: =AD12-AD22 -> 0 | AE40: =AE12-AE22 -> 0 | AF40: =AF12-AF22 -> 0 | ... AH40: =AH12-AH22 -> 0
A41: A side- EA | B41: =AVERAGE(B31:F35) -> 0 | C41: R | D41: =MAX(B31:F35)-MIN(B31:F35) -> 0 | E41: ER | F41: =B41/(0.975/E26) -> 0 | G41: A side- EA | H41: =AVERAGE(H31:L35) -> 1.044 | I41: R | J41: =MAX(H31:L35)-MIN(H31:L35) -> 0.2 | K41: ER | L41: =H41/(1.944/K26) -> 0.75185185 | M41: A side- EA | N41: =AVERAGE(N31:W35) -> 0 | O41: R | P41: =MAX(N31:W35)-MIN(N31:W35) -> 0 | Q41: ER | R41: =N41/(0.975/Q26) -> 0 | S41: % | T41: =1-(P41/2*N41) -> 1 | U41: T-R | V41: =MAX(N31:W40)-MIN(N31:W40) -> 0 | X41: A side- EA | Y41: =AVERAGE(Y31:AH35) -> 0 | Z41: R | AA41: =MAX(Y31:AH35)-MIN(Y31:AH35) -> 0 | AB41: ER | AC41: =Y41/(3.13/AB26) -> 0 | AD41: % | AE41: =1-(AA41/2*Y41) -> 1 | AF41: T-R | AG41: =MAX(Y31:AH40)-MIN(Y31:AH40) -> 0
...

Sheet 0508.
A1: PT-01 | G1: QE-01 | M1: PT-02 | X1: QE-02
A2: OP | B2: 1 | C2: 2 | D2: 3 | E2: 4 | F2: 5 | G2: OP | H2: 1 | I2: 2 | J2: 3 | K2: 4 | L2: 5 | M2: OP | N2: 1 | O2: 2 | P2: 3 | Q2: 4 | R2: 5 | S2: 6 | T2: 7 | U2: 8 | V2: 9 | W2: 10 | X2: OP | Y2: 1 | Z2: 2 | AA2: 3 | AB2: 4 | AC2: 5 | AD2: 6 | AE2: 7 | AF2: 8 | AG2: 9 | AH2: 10
A3: N2522+ | G3: N2522+ | H3: 2.88 | I3: 2.95 | J3: 3.16 | K3: 3.1 | L3: 3.07 | M3: N2522+ | N3: 2.19 | O3: 2.37 | P3: 2.42 | Q3: 2.48 | R3: 2.36 | S3: 2.35 | T3: 2.38 | U3: 2.36 | V3: 2.33 | W3: 2.2 | X3: N2522+
H4: 2.84 | I4: 2.94 | J4: 3.18 | K4: 3.14 | L4: 3.1 | N4: 2.22 | O4: 2.4 | P4: 2.41 | Q4: 2.46 | R4: 2.48 | S4: 2.4 | T4: 2.43 | U4: 2.44 | V4: 2.3 | W4: 2.18
H5: 2.87 | I5: 2.98 | J5: 3.21 | K5: 3.18 | L5: 3.07 | N5: 2.22 | O5: 2.32 | P5: 2.37 | Q5: 2.47 | R5: 2.37 | S5: 2.37 | T5: 2.27 | U5: 2.27 | V5: 2.31 | W5: 2.22
H6: 2.83 | I6: 2.95 | J6: 3.15 | K6: 3.14 | L6: 3.11 | N6: 2.24 | O6: 2.42 | P6: 2.37 | Q6: 2.38 | R6: 2.36 | S6: 2.37 | T6: 2.3 | U6: 2.28 | V6: 2.29 | W6: 2.24
H7: 2.8 | I7: 2.94 | J7: 3.12 | K7: 3.13 | L7: 3.09 | N7: 2.2 | O7: 2.4 | P7: 2.47 | Q7: 2.47 | R7: 2.48 | S7: 2.43 | T7: 2.39 | U7: 2.4 | V7: 2.16 | W7: 2.14
A8: N2522- | G8: N2522- | H8: 2.88 | I8: 2.89 | J8: 3.1 | K8: 3.15 | L8: 3.25 | M8: N2522- | N8: 2.15 | O8: 2.28 | P8: 2.4 | Q8: 2.3 | R8: 2.32 | S8: 2.39 | T8: 2.43 | U8: 2.35 | V8: 2.35 | W8: 2.23 | X8: N2522-
H9: 2.87 | I9: 2.88 | J9: 3.12 | K9: 3.23 | L9: 3.22 | N9: 2.14 | O9: 2.29 | P9: 2.42 | Q9: 2.38 | R9: 2.41 | S9: 2.45 | T9: 2.4 | U9: 2.4 | V9: 2.39 | W9: 2.32
H10: 2.85 | I10: 2.91 | J10: 3.11 | K10: 3.27 | L10: 3.26 | N10: 2.2 | O10: 2.28 | P10: 2.37 | Q10: 2.4 | R10: 2.43 | S10: 2.4 | T10: 2.4 | U10: 2.37 | V10: 2.37 | W10: 2.29
H11: 2.9 | I11: 2.97 | J11: 3.04 | K11: 3.21 | L11: 3.2 | N11: 2.19 | O11: 2.3 | P11: 2.38 | Q11: 2.38 | R11: 2.39 | S11: 2.4 | T11: 2.36 | U11: 2.28 | V11: 2.27 | W11: 2.31
H12: 2.88 | I12: 2.91 | J12: 3.09 | K12: 3.23 | L12: 3.13 | N12: 2.12 | O12: 2.31 | P12: 2.39 | Q12: 2.46 | R12: 2.39 | S12: 2.35 | T12: 2.39 | U12: 2.39 | V12: 2.32 | W12: 2.22
A13: PT1+ | G13: QE1+ | H13: 1.59 | I13: 1.71 | J13: 1.87 | K13: 1.89 | L13: 1.81 | M13: PT2+ | X13: QE2+
H14: 1.6 | I14: 1.68 | J14: 1.84 | K14: 1.88 | L14: 1.81
H15: 1.59 | I15: 1.69 | J15: 1.89 | K15: 1.91 | L15: 1.84
H16: 1.58 | I16: 1.66 | J16: 1.85 | K16: 1.9 | L16: 1.86
H17: 1.54 | I17: 1.65 | J17: 1.83 | K17: 1.83 | L17: 1.81
A18: PT1- | G18: Q1E- | H18: 1.89 | I18: 1.93 | J18: 2.14 | K18: 2.22 | L18: 2.2 | M18: PT2- | X18: QE2-
H19: 1.91 | I19: 1.95 | J19: 2.18 | K19: 2.26 | L19: 2.22
H20: 1.87 | I20: 1.95 | J20: 2.2 | K20: 2.29 | L20: 2.23
H21: 1.91 | I21: 2 | J21: 2.17 | K21: 2.24 | L21: 2.18
H22: 1.88 | I22: 1.92 | J22: 2.12 | K22: 2.23 | L22: 2.15
A24: 項次 | B24: 單位 | C24: 規格 | E24: 數值 | G24: 項次 | H24: 單位 | I24: 規格 | K24: 數值 | M24: 項次 | N24: 單位 | O24: 規格 | Q24: 數值 | X24: 項次 | Y24: 單位 | Z24: 規格 | AB24: 數值
A25: 咬蝕量 | B25: um | C25: 0.3±0.1 | E25: =AVERAGE(B3:F12)-AVERAGE(B13:F22) -> #DIV/0! | G25: 咬蝕量 | H25: um | I25: 0.84±0.07 | K25: =AVERAGE(H3:L12)-AVERAGE(H13:L22) -> 1.1226 | M25: 咬蝕量 | N25: um | O25: 0.3±0.1 | Q25: =AVERAGE(N3:W12)-AVERAGE(N13:W22) -> #DIV/0! | X25: 咬蝕量 | Y25: um | Z25: 0.84±0.07 | AB25: =AVERAGE(Y3:AH12)-AVERAGE(Y13:AH22) -> #DIV/0!
A26: 線速 | B26: M/min | C26: ="--" -> -- | E26: 1.7 | G26: 線速 | H26: M/min | I26: ="--" -> -- | K26: 1.4 | M26: 線速 | N26: M/min | O26: ="--" -> -- | Q26: 1.5 | X26: 線速 | Y26: M/min | Z26: ="--" -> -- | AB26: 1.5
A27: 咬蝕速率 | B27: um/min | C27: 0.55±0.17 | E27: =(E25/(0.975/E26)) -> #DIV/0! | G27: 咬蝕速率 | H27: um/min | I27: 0.75±0.07 | K27: =(K25/(1.944/K26)) -> 0.80845679 | M27: 咬蝕速率 | N27: um/min | O27: 0.55±0.17 | Q27: =(Q25/(0.975/Q26)) -> #DIV/0! | X27: 咬蝕速率 | Y27: um/min | Z27: 0.75±0.07 | AB27: =(AB25/(3.13/AB26)) -> #DIV/0!
A28: 量測日期 | C28: =TODAY() -> 46156
A29: PT-01 | G29: QE-01 | M29: PT-02 | X29: QE-02
A30: 咬蝕量 | G30: 咬蝕量 | M30: 咬蝕量 | X30: 咬蝕量
A31: PT1+ | B31: =B3-B13 -> 0 | C31: =C3-C13 -> 0 | D31: =D3-D13 -> 0 | E31: =E3-E13 -> 0 | F31: =F3-F13 -> 0 | G31: QE1+ | H31: =H3-H13 -> 1.29 | I31: =I3-I13 -> 1.24 | J31: =J3-J13 -> 1.29 | K31: =K3-K13 -> 1.21 | L31: =L3-L13 -> 1.26 | M31: PT2+ | N31: =N3-N13 -> 2.19 | O31: =O3-O13 -> 2.37 | P31: =P3-P13 -> 2.42 | Q31: =Q3-Q13 -> 2.48 | R31: =R3-R13 -> 2.36 | S31: =S3-S13 -> 2.35 | T31: =T3-T13 -> 2.38 | U31: =U3-U13 -> 2.36 | ... W31: =W3-W13 -> 2.2 | X31: QE2+ | Y31: =Y3-Y13 -> 0 | Z31: =Z3-Z13 -> 0 | AA31: =AA3-AA13 -> 0 | AB31: =AB3-AB13 -> 0 | AC31: =AC3-AC13 -> 0 | AD31: =AD3-AD13 -> 0 | AE31: =AE3-AE13 -> 0 | AF31: =AF3-AF13 -> 0 | ... AH31: =AH3-AH13 -> 0 | AJ31: PT | AK31: =B31 -> 0 | AL31: =B32 -> 0 | AM31: =B33 -> 0 | AN31: =B34 -> 0 | AO31: =B35 -> 0 | AP31: =C31 -> 0 | AQ31: =C32 -> 0 | AR31: =C33 -> 0 | AS31: =C34 -> 0 | AT31: =C35 -> 0 | AU31: =D31 -> 0 | AV31: =D32 -> 0 | AW31: =D33 -> 0 | AX31: =D34 -> 0 | AY31: =D35 -> 0 | AZ31: =E31 -> 0 | BA31: =E32 -> 0 | BB31: =E33 -> 0 | BC31: =E34 -> 0 | BD31: =E35 -> 0 | BE31: =F31 -> 0 | BF31: =F32 -> 0 | BG31: =F33 -> 0 | BH31: =F34 -> 0 | BI31: =F35 -> 0
B32: =B4-B14 -> 0 | C32: =C4-C14 -> 0 | D32: =D4-D14 -> 0 | E32: =E4-E14 -> 0 | F32: =F4-F14 -> 0 | H32: =H4-H14 -> 1.24 | I32: =I4-I14 -> 1.26 | J32: =J4-J14 -> 1.34 | K32: =K4-K14 -> 1.26 | L32: =L4-L14 -> 1.29 | N32: =N4-N14 -> 2.22 | O32: =O4-O14 -> 2.4 | P32: =P4-P14 -> 2.41 | Q32: =Q4-Q14 -> 2.46 | R32: =R4-R14 -> 2.48 | S32: =S4-S14 -> 2.4 | T32: =T4-T14 -> 2.43 | U32: =U4-U14 -> 2.44 | ... W32: =W4-W14 -> 2.18 | Y32: =Y4-Y14 -> 0 | Z32: =Z4-Z14 -> 0 | AA32: =AA4-AA14 -> 0 | AB32: =AB4-AB14 -> 0 | AC32: =AC4-AC14 -> 0 | AD32: =AD4-AD14 -> 0 | AE32: =AE4-AE14 -> 0 | AF32: =AF4-AF14 -> 0 | ... AH32: =AH4-AH14 -> 0
B33: =B5-B15 -> 0 | C33: =C5-C15 -> 0 | D33: =D5-D15 -> 0 | E33: =E5-E15 -> 0 | F33: =F5-F15 -> 0 | H33: =H5-H15 -> 1.28 | I33: =I5-I15 -> 1.29 | J33: =J5-J15 -> 1.32 | K33: =K5-K15 -> 1.27 | L33: =L5-L15 -> 1.23 | N33: =N5-N15 -> 2.22 | O33: =O5-O15 -> 2.32 | P33: =P5-P15 -> 2.37 | Q33: =Q5-Q15 -> 2.47 | R33: =R5-R15 -> 2.37 | S33: =S5-S15 -> 2.37 | T33: =T5-T15 -> 2.27 | U33: =U5-U15 -> 2.27 | ... W33: =W5-W15 -> 2.22 | Y33: =Y5-Y15 -> 0 | Z33: =Z5-Z15 -> 0 | AA33: =AA5-AA15 -> 0 | AB33: =AB5-AB15 -> 0 | AC33: =AC5-AC15 -> 0 | AD33: =AD5-AD15 -> 0 | AE33: =AE5-AE15 -> 0 | AF33: =AF5-AF15 -> 0 | ... AH33: =AH5-AH15 -> 0
B34: =B6-B16 -> 0 | C34: =C6-C16 -> 0 | D34: =D6-D16 -> 0 | E34: =E6-E16 -> 0 | F34: =F6-F16 -> 0 | H34: =H6-H16 -> 1.25 | I34: =I6-I16 -> 1.29 | J34: =J6-J16 -> 1.3 | K34: =K6-K16 -> 1.24 | L34: =L6-L16 -> 1.25 | N34: =N6-N16 -> 2.24 | O34: =O6-O16 -> 2.42 | P34: =P6-P16 -> 2.37 | Q34: =Q6-Q16 -> 2.38 | R34: =R6-R16 -> 2.36 | S34: =S6-S16 -> 2.37 | T34: =T6-T16 -> 2.3 | U34: =U6-U16 -> 2.28 | ... W34: =W6-W16 -> 2.24 | Y34: =Y6-Y16 -> 0 | Z34: =Z6-Z16 -> 0 | AA34: =AA6-AA16 -> 0 | AB34: =AB6-AB16 -> 0 | AC34: =AC6-AC16 -> 0 | AD34: =AD6-AD16 -> 0 | AE34: =AE6-AE16 -> 0 | AF34: =AF6-AF16 -> 0 | ... AH34: =AH6-AH16 -> 0
B35: =B7-B17 -> 0 | C35: =C7-C17 -> 0 | D35: =D7-D17 -> 0 | E35: =E7-E17 -> 0 | F35: =F7-F17 -> 0 | H35: =H7-H17 -> 1.26 | I35: =I7-I17 -> 1.29 | J35: =J7-J17 -> 1.29 | K35: =K7-K17 -> 1.3 | L35: =L7-L17 -> 1.28 | N35: =N7-N17 -> 2.2 | O35: =O7-O17 -> 2.4 | P35: =P7-P17 -> 2.47 | Q35: =Q7-Q17 -> 2.47 | R35: =R7-R17 -> 2.48 | S35: =S7-S17 -> 2.43 | T35: =T7-T17 -> 2.39 | U35: =U7-U17 -> 2.4 | ... W35: =W7-W17 -> 2.14 | Y35: =Y7-Y17 -> 0 | Z35: =Z7-Z17 -> 0 | AA35: =AA7-AA17 -> 0 | AB35: =AB7-AB17 -> 0 | AC35: =AC7-AC17 -> 0 | AD35: =AD7-AD17 -> 0 | AE35: =AE7-AE17 -> 0 | AF35: =AF7-AF17 -> 0 | ... AH35: =AH7-AH17 -> 0
A36: PT1- | B36: =B8-B18 -> 0 | C36: =C8-C18 -> 0 | D36: =D8-D18 -> 0 | E36: =E8-E18 -> 0 | F36: =F8-F18 -> 0 | G36: QE1- | H36: =H8-H18 -> 0.99 | I36: =I8-I18 -> 0.96 | J36: =J8-J18 -> 0.96 | K36: =K8-K18 -> 0.93 | L36: =L8-L18 -> 1.05 | M36: PT2- | N36: =N8-N18 -> 2.15 | O36: =O8-O18 -> 2.28 | P36: =P8-P18 -> 2.4 | Q36: =Q8-Q18 -> 2.3 | R36: =R8-R18 -> 2.32 | S36: =S8-S18 -> 2.39 | T36: =T8-T18 -> 2.43 | U36: =U8-U18 -> 2.35 | ... W36: =W8-W18 -> 2.23 | X36: QE2- | Y36: =Y8-Y18 -> 0 | Z36: =Z8-Z18 -> 0 | AA36: =AA8-AA18 -> 0 | AB36: =AB8-AB18 -> 0 | AC36: =AC8-AC18 -> 0 | AD36: =AD8-AD18 -> 0 | AE36: =AE8-AE18 -> 0 | AF36: =AF8-AF18 -> 0 | ... AH36: =AH8-AH18 -> 0 | AK36: =B36 -> 0 | AL36: =B37 -> 0 | AM36: =B38 -> 0 | AN36: =B39 -> 0 | AO36: =B40 -> 0 | AP36: =C36 -> 0 | AQ36: =C37 -> 0 | AR36: =C38 -> 0 | AS36: =C39 -> 0 | AT36: =C40 -> 0 | AU36: =D36 -> 0 | AV36: =D37 -> 0 | AW36: =D38 -> 0 | AX36: =D39 -> 0 | AY36: =D40 -> 0 | AZ36: =E36 -> 0 | BA36: =E37 -> 0 | BB36: =E38 -> 0 | BC36: =E39 -> 0 | BD36: =E40 -> 0 | BE36: =F36 -> 0 | BF36: =F37 -> 0 | BG36: =F38 -> 0 | BH36: =F39 -> 0 | BI36: =F40 -> 0
B37: =B9-B19 -> 0 | C37: =C9-C19 -> 0 | D37: =D9-D19 -> 0 | E37: =E9-E19 -> 0 | F37: =F9-F19 -> 0 | H37: =H9-H19 -> 0.96 | I37: =I9-I19 -> 0.93 | J37: =J9-J19 -> 0.94 | K37: =K9-K19 -> 0.97 | L37: =L9-L19 -> 1 | N37: =N9-N19 -> 2.14 | O37: =O9-O19 -> 2.29 | P37: =P9-P19 -> 2.42 | Q37: =Q9-Q19 -> 2.38 | R37: =R9-R19 -> 2.41 | S37: =S9-S19 -> 2.45 | T37: =T9-T19 -> 2.4 | U37: =U9-U19 -> 2.4 | ... W37: =W9-W19 -> 2.32 | Y37: =Y9-Y19 -> 0 | Z37: =Z9-Z19 -> 0 | AA37: =AA9-AA19 -> 0 | AB37: =AB9-AB19 -> 0 | AC37: =AC9-AC19 -> 0 | AD37: =AD9-AD19 -> 0 | AE37: =AE9-AE19 -> 0 | AF37: =AF9-AF19 -> 0 | ... AH37: =AH9-AH19 -> 0
B38: =B10-B20 -> 0 | C38: =C10-C20 -> 0 | D38: =D10-D20 -> 0 | E38: =E10-E20 -> 0 | F38: =F10-F20 -> 0 | H38: =H10-H20 -> 0.98 | I38: =I10-I20 -> 0.96 | J38: =J10-J20 -> 0.91 | K38: =K10-K20 -> 0.98 | L38: =L10-L20 -> 1.03 | N38: =N10-N20 -> 2.2 | O38: =O10-O20 -> 2.28 | P38: =P10-P20 -> 2.37 | Q38: =Q10-Q20 -> 2.4 | R38: =R10-R20 -> 2.43 | S38: =S10-S20 -> 2.4 | T38: =T10-T20 -> 2.4 | U38: =U10-U20 -> 2.37 | ... W38: =W10-W20 -> 2.29 | Y38: =Y10-Y20 -> 0 | Z38: =Z10-Z20 -> 0 | AA38: =AA10-AA20 -> 0 | AB38: =AB10-AB20 -> 0 | AC38: =AC10-AC20 -> 0 | AD38: =AD10-AD20 -> 0 | AE38: =AE10-AE20 -> 0 | AF38: =AF10-AF20 -> 0 | ... AH38: =AH10-AH20 -> 0 | AJ38: QE | AK38: =H31 -> 1.29 | AL38: =H32 -> 1.24 | AM38: =H33 -> 1.28 | AN38: =H34 -> 1.25 | AO38: =H35 -> 1.26 | AP38: =I31 -> 1.24 | AQ38: =I32 -> 1.26 | AR38: =I33 -> 1.29 | AS38: =I34 -> 1.29 | AT38: =I35 -> 1.29 | AU38: =J31 -> 1.29 | AV38: =J32 -> 1.34 | AW38: =J33 -> 1.32 | AX38: =J34 -> 1.3 | AY38: =J35 -> 1.29 | AZ38: =K31 -> 1.21 | BA38: =K32 -> 1.26 | BB38: =K33 -> 1.27 | BC38: =K34 -> 1.24 | BD38: =K35 -> 1.3 | BE38: =L31 -> 1.26 | BF38: =L32 -> 1.29 | BG38: =L33 -> 1.23 | BH38: =L34 -> 1.25 | BI38: =L35 -> 1.28
B39: =B11-B21 -> 0 | C39: =C11-C21 -> 0 | D39: =D11-D21 -> 0 | E39: =E11-E21 -> 0 | F39: =F11-F21 -> 0 | H39: =H11-H21 -> 0.99 | I39: =I11-I21 -> 0.97 | J39: =J11-J21 -> 0.87 | K39: =K11-K21 -> 0.97 | L39: =L11-L21 -> 1.02 | N39: =N11-N21 -> 2.19 | O39: =O11-O21 -> 2.3 | P39: =P11-P21 -> 2.38 | Q39: =Q11-Q21 -> 2.38 | R39: =R11-R21 -> 2.39 | S39: =S11-S21 -> 2.4 | T39: =T11-T21 -> 2.36 | U39: =U11-U21 -> 2.28 | ... W39: =W11-W21 -> 2.31 | Y39: =Y11-Y21 -> 0 | Z39: =Z11-Z21 -> 0 | AA39: =AA11-AA21 -> 0 | AB39: =AB11-AB21 -> 0 | AC39: =AC11-AC21 -> 0 | AD39: =AD11-AD21 -> 0 | AE39: =AE11-AE21 -> 0 | AF39: =AF11-AF21 -> 0 | ... AH39: =AH11-AH21 -> 0
B40: =B12-B22 -> 0 | C40: =C12-C22 -> 0 | D40: =D12-D22 -> 0 | E40: =E12-E22 -> 0 | F40: =F12-F22 -> 0 | H40: =H12-H22 -> 1 | I40: =I12-I22 -> 0.99 | J40: =J12-J22 -> 0.97 | K40: =K12-K22 -> 1 | L40: =L12-L22 -> 0.98 | N40: =N12-N22 -> 2.12 | O40: =O12-O22 -> 2.31 | P40: =P12-P22 -> 2.39 | Q40: =Q12-Q22 -> 2.46 | R40: =R12-R22 -> 2.39 | S40: =S12-S22 -> 2.35 | T40: =T12-T22 -> 2.39 | U40: =U12-U22 -> 2.39 | ... W40: =W12-W22 -> 2.22 | Y40: =Y12-Y22 -> 0 | Z40: =Z12-Z22 -> 0 | AA40: =AA12-AA22 -> 0 | AB40: =AB12-AB22 -> 0 | AC40: =AC12-AC22 -> 0 | AD40: =AD12-AD22 -> 0 | AE40: =AE12-AE22 -> 0 | AF40: =AF12-AF22 -> 0 | ... AH40: =AH12-AH22 -> 0
A41: A side- EA | B41: =AVERAGE(B31:F35) -> 0 | C41: R | D41: =MAX(B31:F35)-MIN(B31:F35) -> 0 | E41: ER | F41: =B41/(0.975/E26) -> 0 | G41: A side- EA | H41: =AVERAGE(H31:L35) -> 1.2728 | I41: R | J41: =MAX(H31:L35)-MIN(H31:L35) -> 0.13 | K41: ER | L41: =H41/(1.944/K26) -> 0.91662551 | M41: A side- EA | N41: =AVERAGE(N31:W35) -> 2.3428 | O41: R | P41: =MAX(N31:W35)-MIN(N31:W35) -> 0.34 | Q41: ER | R41: =N41/(0.975/Q26) -> 3.6043077 | S41: % | T41: =1-(P41/2*N41) -> 0.601724 | U41: T-R | V41: =MAX(N31:W40)-MIN(N31:W40) -> 0.36 | X41: A side- EA | Y41: =AVERAGE(Y31:AH35) -> 0 | Z41: R | AA41: =MAX(Y31:AH35)-MIN(Y31:AH35) -> 0 | AB41: ER | AC41: =Y41/(3.13/AB26) -> 0 | AD41: % | AE41: =1-(AA41/2*Y41) -> 1 | AF41: T-R | AG41: =MAX(Y31:AH40)-MIN(Y31:AH40) -> 0
...

Sheet 工作表7
A11: 日期 | B11: 線速 | C11: 咬蝕速率 | D11: 管制圖號 | E11: 管制圖標題 | F11: 1 | G11: 2 | H11: 3 | I11: 4 | J11: 5 | K11: 6 | L11: 7 | M11: 8 | N11: 9 | O11: 10 | P11: 11 | Q11: 12 | R11: 13 | S11: 14 | T11: 15 | U11: 16 | V11: 17 | W11: 18 | X11: 19 | Y11: 20 | Z11: 21 | AA11: 22 | AB11: 23 | AC11: 24 | AD11: 25 | AE11: 欄1 | AF11: Uniformity
A12: 46034 | B12: 1.7 | C12: 0.52 | D12: P-001 | E12: 咬蝕量_PT-01_Top | F12: 0.26 | G12: 0.3 | H12: 0.22 | I12: 0.31 | J12: 0.17 | K12: 0.39 | L12: 0.3 | M12: 0.27 | N12: 0.31 | O12: 0.28 | P12: 0.3 | Q12: 0.3 | R12: 0.27 | S12: 0.3 | T12: 0.34 | U12: 0.25 | V12: 0.23 | W12: 0.26 | X12: 0.29 | Y12: 0.29 | Z12: 0.27 | AA12: 0.26 | AB12: 0.28 | AC12: 0.15 | AD12: 0.25 | AE12: =AVERAGE(表格1[[#This Row],[1]:[25]]) -> 0.274 | AF12: 0.55555556
A13: 46034 | B13: 1.7 | C13: 0.52 | D13: P-002 | E13: 咬蝕量_PT-01_Bottom | F13: 0.35 | G13: 0.32 | H13: 0.29 | I13: 0.37 | J13: 0.34 | K13: 0.33 | L13: 0.4 | M13: 0.38 | N13: 0.26 | O13: 0.31 | P13: 0.27 | Q13: 0.29 | R13: 0.28 | S13: 0.29 | T13: 0.32 | U13: 0.33 | V13: 0.41 | W13: 0.35 | X13: 0.29 | Y13: 0.3 | Z13: 0.3 | AA13: 0.32 | AB13: 0.26 | AC13: 0.33 | AD13: 0.34 | AE13: =AVERAGE(表格1[[#This Row],[1]:[25]]) -> 0.3212 | AF13: 0.7761194
A14: 46034 | B14: 1.4 | C14: 0.97 | D14: P-003 | E14: 咬蝕量_QE-01_Top | F14: 1.48 | G14: 1.49 | H14: 1.46 | I14: 1.5 | J14: 1.48 | K14: 1.49 | L14: 1.49 | M14: 1.57 | N14: 1.5 | O14: 1.52 | P14: 1.55 | Q14: 1.54 | R14: 1.53 | S14: 1.54 | T14: 1.57 | U14: 1.47 | V14: 1.46 | W14: 1.55 | X14: 1.53 | Y14: 1.53 | Z14: 1.49 | AA14: 1.5 | AB14: 1.52 | AC14: 1.59 | AD14: 1.43 | AE14: =AVERAGE(表格1[[#This Row],[1]:[25]]) -> 1.5112 | AF14: 0.94701987
A15: 46034 | B15: 1.4 | C15: 0.97 | D15: P-004 | E15: 咬蝕量_QE-01_Bottom | F15: 1.11 | G15: 1.12 | H15: 1.08 | I15: 1.08 | J15: 1.1 | K15: 1.23 | L15: 1.21 | M15: 1.2 | N15: 1.2 | O15: 1.07 | P15: 1.18 | Q15: 1.22 | R15: 1.21 | S15: 1.2 | T15: 1.17 | U15: 1.19 | V15: 1.19 | W15: 1.23 | X15: 1.22 | Y15: 1.23 | Z15: 1.14 | AB15: 1.15 | AC15: 1.26 | AD15: 1.11 | AE15: =AVERAGE(表格1[[#This Row],[1]:[25]]) -> 1.1708333 | AF15: 0.34076433
