Workbook

Sheet CN
A2: 藥液分析日報表
A3: 線別 | B3: CN
A4: 日期
A5: 分析者 | M5: 複驗
A6: 線別 | B6: 槽位 | C6: 分析項目 | D6: 規格 | E6: 範圍 | H6: 滴定數(ml) | I6: 濃度 | J6: 判定 | K6: 調整 | L6: 調整量 | M6: 滴定數(ml) | N6: 濃度 | O6: 判定 | P6: 藥液 | Q6: 槽容(L) | R6: 添加管制值 | S6: 稀釋管制值
A7: 清洗線 (CN) | B7: 鹼洗1 | C7: CHO ((g/L) | D7: 45±15 | E7: 30 | F7: ~ | G7: 60 | I7: =IF(H7="","",24.5*H7*F值!$B$3) | J7: =IF(I7="","",IF(OR(I7<E7,I7>G7),"NG","OK")) | K7: =IF(I7="","",IF(I7<R7,"添加",IF(I7>S7,"更槽",""))) | L7: =IF(I7<R7,"硫酸(50%)："&ROUND(((R7-I7)*Q7/1000),1)&" L","") | N7: =IF(M7="","",24.5*M7*F值!$B$3) | O7: =IF(N7="","",IF(OR(N7<E7,N7>G7),"NG","OK")) | P7: 硫酸(50%) | Q7: 1000 | R7: 45 | S7: 60
C8: BCNa ((g/L) | D8: 40±10 | E8: 30 | F8: ~ | G8: 50 | I8: =IF(H8="","",(11.905*H8*F值!$B$10)/2) | J8: =IF(I8="","",IF(OR(I8<E8,I8>G8),"NG","OK")) | K8: =IF(I8="","",IF(I8<R8,"添加",IF(I8>S8,"稀釋",""))) | L8: =IFERROR(IF(I8<R8,"SPS："&ROUND(((R8-I8)*Q8/1000),1)&" L",IF(I8>S8,"排藥："&ROUND((I8-S8)/I8*Q8,1)&" L"&" 補水："&ROUND((I8-S8)/I8*Q8,1)&" L","")),"") | N8: =IF(M8="","",(11.905*M8*F值!$B$10)/2) | O8: =IF(N8="","",IF(OR(N8<E8,N8>G8),"NG","OK")) | P8: SPS | Q8: 1000 | R8: 40 | S8: 50
B9: 鹼洗2 | C9: CHO ((g/L) | D9: 45±15 | E9: 30 | F9: ~ | G9: 60 | I9: =IF(H9="","",24.5*H9*F值!$B$3) | J9: =IF(I9="","",IF(OR(I9<E9,I9>G9),"NG","OK")) | K9: =IF(I9="","",IF(I9<R9,"添加",IF(I9>S9,"稀釋",""))) | L9: =IF(I9<R9,"硫酸(50%)："&ROUND(((R9-I9)*Q9/1000),1)&" L","") | N9: =IF(M9="","",24.5*M9*F值!$B$3) | O9: =IF(N9="","",IF(OR(N9<E9,N9>G9),"NG","OK")) | P9: 硫酸(50%) | Q9: 1000 | R9: 45 | S9: 60
C10: BCNa ((g/L) | D10: 40±10 | E10: 30 | F10: ~ | G10: 50 | I10: =IF(H10="","",(11.905*H10*F值!$B$10)/2) | J10: =IF(I10="","",IF(OR(I10<E10,I10>G10),"NG","OK")) | K10: =IF(I10="","",IF(I10<R10,"添加",IF(I10>S10,"稀釋",""))) | L10: =IFERROR(IF(I10<R10,"SPS："&ROUND(((R10-I10)*Q10/1000),1)&" L",IF(I10>S10,"排藥："&ROUND((I10-S10)/I10*Q10,1)&" L"&" 補水："&ROUND((I10-S10)/I10*Q10,1)&" L","")),"") | N10: =IF(M10="","",(11.905*M10*F值!$B$10)/2) | O10: =IF(N10="","",IF(OR(N10<E10,N10>G10),"NG","OK")) | P10: SPS | Q10: 1000 | R10: 40 | S10: 50
A11: 備註:
A15: QA-2-010-02A | C15: 核准： | H15: 確認：

Sheet N1 (開)
A2: 藥液分析日報表
A3: 線別 | B3: N1
A4: 日期
A5: 分析者 | N5: 複驗
A6: 線別 | B6: 槽位 | C6: 分析項目 | D6: 規格 | E6: 範圍 | H6: 滴定數(ml) | J6: 濃度 | K6: 判定 | L6: 調整 | M6: 調整量 | N6: 滴定數(ml) | P6: 濃度 | Q6: 判定 | R6: 藥液 | S6: 槽容(L) | T6: 添加管制值 | U6: 稀釋管制值
A7: 化鎳線 (N1) | B7: 表面處理 | C7: NKH (g/L) | D7: 20±2 | E7: 18 | F7: ~ | G7: 22 | J7: =IF(H7="","",(1.12*H7*F值!$B$4)*2) | K7: =IF(J7="","",IF(OR(J7<E7,J7>G7),"NG","OK")) | P7: =IF(N7="","",(1.12*N7*F值!$B$4)*2) | Q7: =IF(P7="","",IF(OR(P7<E7,P7>G7),"NG","OK"))
C8: NNH (%) | D8: 8±1 | E8: 7 | F8: ~ | G8: 9 | H8: - | K8: =IF(J8="","",IF(OR(J8<E8,J8>G8),"NG","OK")) | N8: - | Q8: =IF(P8="","",IF(OR(P8<E8,P8>G8),"NG","OK"))
C9: PH | D9: 13.3±0.5 | E9: 12.8 | F9: ~ | G9: 13.8 | H9: - | K9: =IF(J9="","",IF(OR(J9<E9,J9>G9),"NG","OK")) | N9: - | Q9: =IF(P9="","",IF(OR(P9<E9,P9>G9),"NG","OK"))
B10: 調節 | C10: P200 (ml/L) | D10: 150±15 | E10: 135 | F10: ~ | G10: 165 | J10: =IF(H10="","",(11.94*H10*F值!$B$8)) | K10: =IF(J10="","",IF(OR(J10<E10,J10>G10),"NG","OK")) | P10: =IF(N10="","",(11.94*N10*F值!$B$8)) | Q10: =IF(P10="","",IF(OR(P10<E10,P10>G10),"NG","OK"))
C11: PH | D11: 9.5~11 | E11: 9.5 | F11: ~ | G11: 11 | H11: - | K11: =IF(J11="","",IF(OR(J11<E11,J11>G11),"NG","OK")) | N11: - | Q11: =IF(P11="","",IF(OR(P11<E11,P11>G11),"NG","OK"))
B12: 預浸 | C12: Normality (N) | D12: 0.15±0.05 | E12: 0.1 | F12: ~ | G12: 0.2 | J12: =IF(H12="","",H12/5) | K12: =IF(J12="","",IF(OR(J12<E12,J12>G12),"NG","OK")) | P12: =IF(N12="","",N12/5) | Q12: =IF(P12="","",IF(OR(P12<E12,P12>G12),"NG","OK"))
B13: 催化 | C13: Normality (N) | D13: 0.65±0.25 | E13: 0.4 | F13: ~ | G13: 0.9 | J13: =IF(H13="","",H13/5) | K13: =IF(J13="","",IF(OR(J13<E13,J13>G13),"NG","OK")) | P13: =IF(N13="","",N13/5) | Q13: =IF(P13="","",IF(OR(P13<E13,P13>G13),"NG","OK"))
C14: SnCl2 (g/L) | D14: 10±5 | E14: 5 | F14: ~ | G14: 15 | J14: =IF(H14="","",(H14*0.1*112.85)/5) | K14: =IF(J14="","",IF(OR(J14<E14,J14>G14),"NG","OK")) | P14: =IF(N14="","",(N14*0.1*112.85)/5) | Q14: =IF(P14="","",IF(OR(P14<E14,P14>G14),"NG","OK"))
C15: AC-RF (ml/L) | D15: > 20 | E15: 20 | F15: ~ | G15: 999 | J15: =IF(H15="","",(H15*195.7)+1.7752) | K15: =IF(J15="","",IF(OR(J15<E15,J15>G15),"NG","OK")) | P15: =IF(N15="","",(N15*195.7)+1.7752) | Q15: =IF(P15="","",IF(OR(P15<E15,P15>G15),"NG","OK"))
B16: 促進 | C16: P500A (ml/L) | D16: 100±10 | E16: 90 | F16: ~ | G16: 110 | J16: =IF(H16="","",7.24*H16*F值!$B$3) | K16: =IF(J16="","",IF(OR(J16<E16,J16>G16),"NG","OK")) | P16: =IF(N16="","",7.24*N16*F值!$B$3) | Q16: =IF(P16="","",IF(OR(P16<E16,P16>G16),"NG","OK"))
C17: SnCl2 (g/L) | D17: < 0.3 | E17: 0 | F17: ~ | G17: 0.3 | J17: =IF(H17="","",2.256*H17*F值!$B$9) | K17: =IF(J17="","",IF(OR(J17<E17,J17>G17),"NG","OK")) | P17: =IF(N17="","",2.256*N17*F值!$B$9) | Q17: =IF(P17="","",IF(OR(P17<E17,P17>G17),"NG","OK"))
B18: 化鎳 | C18: Ni (g/L) | D18: 4.8±0.2 | E18: 4.6 | F18: ~ | G18: 5 | J18: =IF(H18="","",0.59*H18*F值!$B$6) | K18: =IF(J18="","",IF(OR(J18<E18,J18>G18),"NG","OK")) | P18: =IF(N18="","",0.59*N18*F值!$B$6) | Q18: =IF(P18="","",IF(OR(P18<E18,P18>G18),"NG","OK"))
C19: NaH2PO2‧H2O (g/L) | D19: 18.5±1.5 | E19: 17 | F19: ~ | G19: 20 | J19: =IF(I19="","",(H19-I19)*2.65) | K19: =IF(J19="","",IF(OR(J19<E19,J19>G19),"NG","OK")) | P19: =IF(O19="","",(N19-O19)*2.65) | Q19: =IF(P19="","",IF(OR(P19<E19,P19>G19),"NG","OK"))
C20: Na2HPO3・5H2O (g/L) | D20: < 100 | E20: 0 | F20: ~ | G20: 100 | J20: =IF(I20="","",(H20-I20)*10.8) | K20: =IF(J20="","",IF(OR(J20<E20,J20>G20),"NG","OK")) | P20: =IF(O20="","",(N20-O20)*10.8) | Q20: =IF(P20="","",IF(OR(P20<E20,P20>G20),"NG","OK"))
C21: PH | D21: 8.5±0.2 | E21: 8.3 | F21: ~ | G21: 8.7 | H21: - | K21: =IF(J21="","",IF(OR(J21<E21,J21>G21),"NG","OK")) | N21: - | Q21: =IF(P21="","",IF(OR(P21<E21,P21>G21),"NG","OK"))
A22: 備註:
A26: QA-2-010-02A | C26: 核准： | I26: 確認：

Sheet N1 (收)
A2: 藥液分析日報表
A3: 線別 | B3: N1
A4: 日期
A5: 分析者 | N5: 複驗
A6: 線別 | B6: 槽位 | C6: 分析項目 | D6: 規格 | E6: 範圍 | H6: 滴定數(ml) | J6: 濃度 | K6: 判定 | L6: 調整 | M6: 調整量 | N6: 滴定數(ml) | P6: 濃度 | Q6: 判定 | R6: 藥液 | S6: 槽容(L) | T6: 添加管制值 | U6: 稀釋管制值
A7: 化鎳線 (N1) | B7: 表面處理 | C7: NKH (g/L) | D7: 20±2 | E7: 18 | F7: ~ | G7: 22 | J7: =IF(H7="","",(1.12*H7*F值!$B$4)*2) | K7: =IF(J7="","",IF(OR(J7<E7,J7>G7),"NG","OK")) | P7: =IF(N7="","",(1.12*N7*F值!$B$4)*2) | Q7: =IF(P7="","",IF(OR(P7<E7,P7>G7),"NG","OK"))
C8: NNH (%) | D8: 8±1 | E8: 7 | F8: ~ | G8: 9 | H8: - | K8: =IF(J8="","",IF(OR(J8<E8,J8>G8),"NG","OK")) | N8: - | Q8: =IF(P8="","",IF(OR(P8<E8,P8>G8),"NG","OK"))
C9: PH | D9: 13.3±0.5 | E9: 12.8 | F9: ~ | G9: 13.8 | H9: - | K9: =IF(J9="","",IF(OR(J9<E9,J9>G9),"NG","OK")) | N9: - | Q9: =IF(P9="","",IF(OR(P9<E9,P9>G9),"NG","OK"))
B10: 調節 | C10: P200 (ml/L) | D10: 150±15 | E10: 135 | F10: ~ | G10: 165 | J10: =IF(H10="","",(11.94*H10*F值!$B$8)) | K10: =IF(J10="","",IF(OR(J10<E10,J10>G10),"NG","OK")) | P10: =IF(N10="","",(11.94*N10*F值!$B$8)) | Q10: =IF(P10="","",IF(OR(P10<E10,P10>G10),"NG","OK"))
C11: PH | D11: 9.5~11 | E11: 9.5 | F11: ~ | G11: 11 | H11: - | K11: =IF(J11="","",IF(OR(J11<E11,J11>G11),"NG","OK")) | N11: - | Q11: =IF(P11="","",IF(OR(P11<E11,P11>G11),"NG","OK"))
B12: 預浸 | C12: Normality (N) | D12: 0.15±0.05 | E12: 0.1 | F12: ~ | G12: 0.2 | J12: =IF(H12="","",H12/5) | K12: =IF(J12="","",IF(OR(J12<E12,J12>G12),"NG","OK")) | P12: =IF(N12="","",N12/5) | Q12: =IF(P12="","",IF(OR(P12<E12,P12>G12),"NG","OK"))
B13: 催化 | C13: Normality (N) | D13: 0.65±0.25 | E13: 0.4 | F13: ~ | G13: 0.9 | J13: =IF(H13="","",H13/5) | K13: =IF(J13="","",IF(OR(J13<E13,J13>G13),"NG","OK")) | P13: =IF(N13="","",N13/5) | Q13: =IF(P13="","",IF(OR(P13<E13,P13>G13),"NG","OK"))
C14: SnCl2 (g/L) | D14: 10±5 | E14: 5 | F14: ~ | G14: 15 | J14: =IF(H14="","",(H14*0.1*112.85)/5) | K14: =IF(J14="","",IF(OR(J14<E14,J14>G14),"NG","OK")) | P14: =IF(N14="","",(N14*0.1*112.85)/5) | Q14: =IF(P14="","",IF(OR(P14<E14,P14>G14),"NG","OK"))
C15: AC-RF (ml/L) | D15: > 20 | E15: 20 | F15: ~ | G15: 999 | J15: =IF(H15="","",(H15*195.7)+1.7752) | K15: =IF(J15="","",IF(OR(J15<E15,J15>G15),"NG","OK")) | P15: =IF(N15="","",(N15*195.7)+1.7752) | Q15: =IF(P15="","",IF(OR(P15<E15,P15>G15),"NG","OK"))
B16: 促進 | C16: P500A (ml/L) | D16: 100±10 | E16: 90 | F16: ~ | G16: 110 | J16: =IF(H16="","",7.24*H16*F值!$B$3) | K16: =IF(J16="","",IF(OR(J16<E16,J16>G16),"NG","OK")) | P16: =IF(N16="","",7.24*N16*F值!$B$3) | Q16: =IF(P16="","",IF(OR(P16<E16,P16>G16),"NG","OK"))
C17: SnCl2 (g/L) | D17: < 0.3 | E17: 0 | F17: ~ | G17: 0.3 | J17: =IF(H17="","",2.256*H17*F值!$B$9) | K17: =IF(J17="","",IF(OR(J17<E17,J17>G17),"NG","OK")) | P17: =IF(N17="","",2.256*N17*F值!$B$9) | Q17: =IF(P17="","",IF(OR(P17<E17,P17>G17),"NG","OK"))
B18: 化鎳 | C18: Ni (g/L) | D18: 4.8±0.2 | E18: 4.6 | F18: ~ | G18: 5 | J18: =IF(H18="","",0.59*H18*F值!$B$6) | K18: =IF(J18="","",IF(OR(J18<E18,J18>G18),"NG","OK")) | P18: =IF(N18="","",0.59*N18*F值!$B$6) | Q18: =IF(P18="","",IF(OR(P18<E18,P18>G18),"NG","OK"))
C19: NaH2PO2‧H2O (g/L) | D19: 18.5±1.5 | E19: 17 | F19: ~ | G19: 20 | J19: =IF(I19="","",(H19-I19)*2.65) | K19: =IF(J19="","",IF(OR(J19<E19,J19>G19),"NG","OK")) | P19: =IF(O19="","",(N19-O19)*2.65) | Q19: =IF(P19="","",IF(OR(P19<E19,P19>G19),"NG","OK"))
C20: Na2HPO3・5H2O (g/L) | D20: < 100 | E20: 0 | F20: ~ | G20: 100 | J20: =IF(I20="","",(H20-I20)*10.8) | K20: =IF(J20="","",IF(OR(J20<E20,J20>G20),"NG","OK")) | P20: =IF(O20="","",(N20-O20)*10.8) | Q20: =IF(P20="","",IF(OR(P20<E20,P20>G20),"NG","OK"))
C21: PH | D21: 8.5±0.2 | E21: 8.3 | F21: ~ | G21: 8.7 | H21: - | K21: =IF(J21="","",IF(OR(J21<E21,J21>G21),"NG","OK")) | N21: - | Q21: =IF(P21="","",IF(OR(P21<E21,P21>G21),"NG","OK"))
A22: 備註:
A26: QA-2-010-02A | C26: 核准： | I26: 確認：

Sheet N2 (開)
A2: 藥液分析日報表
A3: 線別 | B3: N2
A4: 日期
A5: 分析者 | N5: 複驗
A6: 線別 | B6: 槽位 | C6: 分析項目 | D6: 規格 | E6: 範圍 | H6: 滴定數(ml) | J6: 濃度 | K6: 判定 | L6: 調整 | M6: 調整量 | N6: 滴定數(ml) | P6: 濃度 | Q6: 判定 | R6: 藥液 | S6: 槽容(L) | T6: 添加管制值 | U6: 稀釋管制值
A7: 化鎳線 (N2) | B7: 表面處理 | C7: NKH (g/L) | D7: 20±2 | E7: 18 | F7: ~ | G7: 22 | J7: =IF(H7="","",(1.12*H7*F值!$B$4)*2) | K7: =IF(J7="","",IF(OR(J7<E7,J7>G7),"NG","OK")) | L7: =IF(J7="","",IF(J7<T7,"添加",IF(J7>U7,"稀釋",""))) | M7: =IFERROR(IF(J7<T7,"KOH："&ROUND(((T7-J7)*S7/0.6525/1000),1)&" L",IF(J7>U7,"排藥："&ROUND((J7-U7)/J7*S7,1)&" L"&" 補水："&ROUND((J7-U7)/J7*S7,1)&" L","")),"") | P7: =IF(N7="","",(1.12*N7*F值!$B$4)*2) | Q7: =IF(P7="","",IF(OR(P7<E7,P7>G7),"NG","OK")) | R7: KOH | S7: 1000 | T7: 20 | U7: 22
C8: NNH (%) | D8: 8±1 | E8: 7 | F8: ~ | G8: 9 | H8: - | K8: =IF(J8="","",IF(OR(J8<E8,J8>G8),"NG","OK")) | L8: =IF(J8="","",IF(J8>U8,"更槽","")) | N8: - | Q8: =IF(P8="","",IF(OR(P8<E8,P8>G8),"NG","OK")) | S8: 1000 | T8: NA | U8: NA
C9: PH | D9: 13.3±0.5 | E9: 12.8 | F9: ~ | G9: 13.8 | H9: - | K9: =IF(J9="","",IF(OR(J9<E9,J9>G9),"NG","OK")) | L9: =IF(J9="","",IF(J9>U9,"更槽","")) | N9: - | Q9: =IF(P9="","",IF(OR(P9<E9,P9>G9),"NG","OK")) | S9: 1000 | T9: NA | U9: NA
B10: 調節 | C10: P200 (ml/L) | D10: 150±15 | E10: 135 | F10: ~ | G10: 165 | J10: =IF(H10="","",(11.94*H10*F值!$B$8)) | K10: =IF(J10="","",IF(OR(J10<E10,J10>G10),"NG","OK")) | L10: =IF(J10="","",IF(J10<T10,"添加",IF(J10>U10,"稀釋",""))) | M10: =IFERROR(IF(J10<T10,"P200："&ROUND(((T10-J10)*S10/1000),1)&" L",IF(J10>U10,"排藥："&ROUND((J10-U10)/J10*S10,1)&" L"&" 補水："&ROUND((J10-U10)/J10*S10,1)&" L","")),"") | P10: =IF(N10="","",(11.94*N10*F值!$B$8)) | Q10: =IF(P10="","",IF(OR(P10<E10,P10>G10),"NG","OK")) | R10: P200 | S10: 600 | T10: 150 | U10: 165
C11: PH | D11: 9.5~11 | E11: 9.5 | F11: ~ | G11: 11 | H11: - | K11: =IF(J11="","",IF(OR(J11<E11,J11>G11),"NG","OK")) | L11: =IF(J11="","",IF(J11>U11,"更槽","")) | N11: - | Q11: =IF(P11="","",IF(OR(P11<E11,P11>G11),"NG","OK")) | S11: 600 | T11: NA | U11: NA
B12: 預浸 | C12: P300 (g/L) | D12: 260±20 | E12: 240 | F12: ~ | G12: 280 | J12: =IF(H12="","",42.14*H12*F值!$B$3) | K12: =IF(J12="","",IF(OR(J12<E12,J12>G12),"NG","OK")) | L12: =IF(J12>T12,"","添加") | M12: =IFERROR(IF(J12<T12,"P300："&ROUND(((T12-J12)*S12/1000),1)&" L",IF(J12>U12,"排藥："&ROUND((J12-U12)/J12*S12,1)&" L"&" 補水："&ROUND((J12-U12)/J12*S12,1)&" L","")),"") | P12: =IF(N12="","",42.14*N12*F值!$B$3) | Q12: =IF(P12="","",IF(OR(P12<E12,P12>G12),"NG","OK")) | R12: P300 | S12: 250 | T12: 260 | U12: 280
B13: 催化 | C13: P400 (ml/L) | D13: > 30 | E13: 30 | F13: ~ | G13: 999 | J13: =IF(H13="","",(H13*195.7)+1.7752) | K13: =IF(J13="","",IF(OR(J13<E13,J13>G13),"NG","OK")) | L13: =IF(J13="","",IF(J13<T13,"添加",IF(J13>U13,"稀釋",""))) | M13: =IFERROR(IF(J13<T13,"P400："&ROUND(((T13-J13)*S13/1000),1)&" L",IF(J13>U13,"排藥："&ROUND((J13-U13)/J13*S13,1)&" L"&" 補水："&ROUND((J13-U13)/J13*S13,1)&" L","")),"") | P13: =IF(N13="","",(N13*195.7)+1.7752) | Q13: =IF(P13="","",IF(OR(P13<E13,P13>G13),"NG","OK")) | R13: P400 | S13: 630 | T13: 31 | U13: NA
C14: SnCl2 (g/L) | D14: 15±10 | E14: 5 | F14: ~ | G14: 25 | J14: =IF(H14="","",2.256*H14*F值!$B$9) | K14: =IF(J14="","",IF(OR(J14<E14,J14>G14),"NG","OK")) | L14: =IF(J14="","",IF(J14<T14,"添加",IF(J14>U14,"稀釋",""))) | M14: =IFERROR(IF(J14<T14,"安定劑："&ROUND(((T14-J14)*S14/1000),1)&" L",IF(J14>U14,"排藥："&ROUND((J14-U14)/J14*S14,1)&" L"&" 補水："&ROUND((J14-U14)/J14*S14,1)&" L","")),"") | P14: =IF(N14="","",2.256*N14*F值!$B$9) | Q14: =IF(P14="","",IF(OR(P14<E14,P14>G14),"NG","OK")) | R14: 安定劑 | S14: 630 | T14: 5 | U14: NA
B15: 促進 | C15: P500A (ml/L) | D15: 100±10 | E15: 90 | F15: ~ | G15: 110 | J15: =IF(H15="","",7.24*H15*F值!$B$3) | K15: =IF(J15="","",IF(OR(J15<E15,J15>G15),"NG","OK")) | L15: =IF(J15="","",IF(J15<T15,"添加",IF(J15>U15,"稀釋",""))) | M15: =IFERROR(IF(J15<T15,"P500A："&ROUND(((T15-J15)*S15/1000),1)&" L",IF(J15>U15,"排藥："&ROUND((J15-U15)/J15*S15,1)&" L"&" 補水："&ROUND((J15-U15)/J15*S15,1)&" L","")),"") | P15: =IF(N15="","",7.24*N15*F值!$B$3) | Q15: =IF(P15="","",IF(OR(P15<E15,P15>G15),"NG","OK")) | R15: P500A | S15: 600 | T15: 100 | U15: 110
C16: SnCl2 (g/L) | D16: < 0.3 | E16: 0 | F16: ~ | G16: 0.3 | J16: =IF(H16="","",2.256*H16*F值!$B$9) | K16: =IF(J16="","",IF(OR(J16<E16,J16>G16),"NG","OK")) | L16: =IF(J16="","",IF(J16>U16,"更槽","")) | P16: =IF(N16="","",2.256*N16*F值!$B$9) | Q16: =IF(P16="","",IF(OR(P16<E16,P16>G16),"NG","OK")) | R16: P500B | S16: 600 | T16: NA | U16: NA
B17: 化鎳 | C17: Ni (g/L) | D17: 4.8±0.2 | E17: 4.6 | F17: ~ | G17: 5 | J17: =IF(H17="","",0.59*H17*F值!$B$6) | K17: =IF(J17="","",IF(OR(J17<E17,J17>G17),"NG","OK")) | L17: =IF(J17="","",IF(J17<T17,"添加",IF(J17>U17,"稀釋",""))) | M17: =IFERROR(IF(J17<T17,"A劑："&ROUND(((T17-J17)*S17*9.2/1000),1)&" L",IF(J17>U17,"排藥："&ROUND((J17-U17)/J17*S17,1)&" L"&" 補水："&ROUND((J17-U17)/J17*S17,1)&" L","")),"") | P17: =IF(N17="","",0.59*N17*F值!$B$6) | Q17: =IF(P17="","",IF(OR(P17<E17,P17>G17),"NG","OK")) | R17: A劑 | S17: 1200 | T17: 4.8 | U17: 5
C18: NaH2PO2‧H2O (g/L) | D18: 18.5±1.5 | E18: 17 | F18: ~ | G18: 20 | J18: =IF(I18="","",(H18-I18)*2.65) | K18: =IF(J18="","",IF(OR(J18<E18,J18>G18),"NG","OK")) | L18: =IF(J18="","",IF(J18<T18,"添加",IF(J18>U18,"稀釋",""))) | M18: =IF(J18<T18,"A劑："&ROUND(((T18-J18)*S18*1.62/1000),1)&" L",IF(J18>U18,"排藥："&ROUND((J18-U18)/J18*S18,1)&" L"&" 補水："&ROUND((J18-U18)/J18*S18,1)&" L","")) | P18: =IF(O18="","",(N18-O18)*2.65) | Q18: =IF(P18="","",IF(OR(P18<E18,P18>G18),"NG","OK")) | R18: B劑 | S18: 1200 | T18: 18.5 | U18: NA
C19: Na2HPO3・5H2O (g/L) | D19: < 100 | E19: 0 | F19: ~ | G19: 100 | J19: =IF(I19="","",(H19-I19)*10.8) | K19: =IF(J19="","",IF(OR(J19<E19,J19>G19),"NG","OK")) | L19: =IF(J19="","",IF(J19>U19,"更槽","")) | P19: =IF(O19="","",(N19-O19)*10.8) | Q19: =IF(P19="","",IF(OR(P19<E19,P19>G19),"NG","OK")) | R19: D劑 | S19: 1200 | T19: NA | U19: NA
C20: PH | D20: 8.5±0.2 | E20: 8.3 | F20: ~ | G20: 8.7 | H20: - | K20: =IF(J20="","",IF(OR(J20<E20,J20>G20),"NG","OK")) | L20: =IF(J20="","",IF(J20>T20,"","添加")) | M20: =IF(J20="","",IF(J20<T20,"氨水："&ROUND(((T20-J20)*S20*16.5/1000),1)&" L","")) | N20: - | Q20: =IF(P20="","",IF(OR(P20<E20,P20>G20),"NG","OK")) | R20: 氨水 | S20: 1200 | T20: 8.5 | U20: NA
A21: 備註:
A25: QA-2-010-02A | C25: 核准： | I25: 確認：

Sheet N2 (收)
A2: 藥液分析日報表
A3: 線別 | B3: N2
A4: 日期
A5: 分析者 | N5: 複驗
A6: 線別 | B6: 槽位 | C6: 分析項目 | D6: 規格 | E6: 範圍 | H6: 滴定數(ml) | J6: 濃度 | K6: 判定 | L6: 調整 | M6: 調整量 | N6: 滴定數(ml) | P6: 濃度 | Q6: 判定 | R6: 藥液 | S6: 槽容(L) | T6: 添加管制值 | U6: 稀釋管制值
A7: 化鎳線 (N2) | B7: 表面處理 | C7: NKH (g/L) | D7: 20±2 | E7: 18 | F7: ~ | G7: 22 | H7: 10 | J7: =IF(H7="","",(1.12*H7*F值!$B$4)*2) -> 22.4 | K7: =IF(J7="","",IF(OR(J7<E7,J7>G7),"NG","OK")) -> NG | L7: =IF(J7="","",IF(J7<T7,"添加",IF(J7>U7,"稀釋",""))) -> 稀釋 | M7: =IFERROR(IF(J7<T7,"KOH："&ROUND(((T7-J7)*S7/0.6525/1000),1)&" L",IF(J7>U7,"排藥："&ROUND((J7-U7)/J7*S7,1)&" L"&" 補水："&ROUND((J7-U7)/J7*S7,1)&" L","")),"") -> 排藥：17.9 L 補水：17.9 L | P7: =IF(N7="","",(1.12*N7*F值!$B$4)*2) | Q7: =IF(P7="","",IF(OR(P7<E7,P7>G7),"NG","OK")) | R7: KOH | S7: 1000 | T7: 20 | U7: 22
C8: NNH (%) | D8: 8±1 | E8: 7 | F8: ~ | G8: 9 | H8: - | K8: =IF(J8="","",IF(OR(J8<E8,J8>G8),"NG","OK")) | L8: =IF(J8="","",IF(J8>U8,"更槽","")) | N8: - | Q8: =IF(P8="","",IF(OR(P8<E8,P8>G8),"NG","OK")) | S8: 1000 | T8: NA | U8: NA
C9: PH | D9: 13.3±0.5 | E9: 12.8 | F9: ~ | G9: 13.8 | H9: - | K9: =IF(J9="","",IF(OR(J9<E9,J9>G9),"NG","OK")) | L9: =IF(J9="","",IF(J9>U9,"更槽","")) | N9: - | Q9: =IF(P9="","",IF(OR(P9<E9,P9>G9),"NG","OK")) | S9: 1000 | T9: NA | U9: NA
B10: 調節 | C10: P200 (ml/L) | D10: 150±15 | E10: 135 | F10: ~ | G10: 165 | J10: =IF(H10="","",(11.94*H10*F值!$B$8)) | K10: =IF(J10="","",IF(OR(J10<E10,J10>G10),"NG","OK")) | L10: =IF(J10="","",IF(J10<T10,"添加",IF(J10>U10,"稀釋",""))) | M10: =IFERROR(IF(J10<T10,"P200："&ROUND(((T10-J10)*S10/1000),1)&" L",IF(J10>U10,"排藥："&ROUND((J10-U10)/J10*S10,1)&" L"&" 補水："&ROUND((J10-U10)/J10*S10,1)&" L","")),"") | P10: =IF(N10="","",(11.94*N10*F值!$B$8)) | Q10: =IF(P10="","",IF(OR(P10<E10,P10>G10),"NG","OK")) | R10: P200 | S10: 600 | T10: 150 | U10: 165
C11: PH | D11: 9.5~11 | E11: 9.5 | F11: ~ | G11: 11 | H11: - | K11: =IF(J11="","",IF(OR(J11<E11,J11>G11),"NG","OK")) | L11: =IF(J11="","",IF(J11>U11,"更槽","")) | N11: - | Q11: =IF(P11="","",IF(OR(P11<E11,P11>G11),"NG","OK")) | S11: 600 | T11: NA | U11: NA
B12: 預浸 | C12: P300 (g/L) | D12: 260±20 | E12: 240 | F12: ~ | G12: 280 | J12: =IF(H12="","",42.14*H12*F值!$B$3) | K12: =IF(J12="","",IF(OR(J12<E12,J12>G12),"NG","OK")) | L12: =IF(J12>T12,"","添加") | M12: =IFERROR(IF(J12<T12,"P300："&ROUND(((T12-J12)*S12/1000),1)&" L",IF(J12>U12,"排藥："&ROUND((J12-U12)/J12*S12,1)&" L"&" 補水："&ROUND((J12-U12)/J12*S12,1)&" L","")),"") | P12: =IF(N12="","",42.14*N12*F值!$B$3) | Q12: =IF(P12="","",IF(OR(P12<E12,P12>G12),"NG","OK")) | R12: P300 | S12: 250 | T12: 260 | U12: 280
B13: 催化 | C13: P400 (ml/L) | D13: > 30 | E13: 30 | F13: ~ | G13: 999 | J13: =IF(H13="","",(H13*195.7)+1.7752) | K13: =IF(J13="","",IF(OR(J13<E13,J13>G13),"NG","OK")) | L13: =IF(J13="","",IF(J13<T13,"添加",IF(J13>U13,"稀釋",""))) | M13: =IFERROR(IF(J13<T13,"P400："&ROUND(((T13-J13)*S13/1000),1)&" L",IF(J13>U13,"排藥："&ROUND((J13-U13)/J13*S13,1)&" L"&" 補水："&ROUND((J13-U13)/J13*S13,1)&" L","")),"") | P13: =IF(N13="","",(N13*195.7)+1.7752) | Q13: =IF(P13="","",IF(OR(P13<E13,P13>G13),"NG","OK")) | R13: P400 | S13: 630 | T13: 31 | U13: NA
C14: SnCl2 (g/L) | D14: 15±10 | E14: 5 | F14: ~ | G14: 25 | J14: =IF(H14="","",2.256*H14*F值!$B$9) | K14: =IF(J14="","",IF(OR(J14<E14,J14>G14),"NG","OK")) | L14: =IF(J14="","",IF(J14<T14,"添加",IF(J14>U14,"稀釋",""))) | M14: =IFERROR(IF(J14<T14,"安定劑："&ROUND(((T14-J14)*S14/1000),1)&" L",IF(J14>U14,"排藥："&ROUND((J14-U14)/J14*S14,1)&" L"&" 補水："&ROUND((J14-U14)/J14*S14,1)&" L","")),"") | P14: =IF(N14="","",2.256*N14*F值!$B$9) | Q14: =IF(P14="","",IF(OR(P14<E14,P14>G14),"NG","OK")) | R14: 安定劑 | S14: 630 | T14: 5 | U14: NA
B15: 促進 | C15: P500A (ml/L) | D15: 100±10 | E15: 90 | F15: ~ | G15: 110 | J15: =IF(H15="","",7.24*H15*F值!$B$3) | K15: =IF(J15="","",IF(OR(J15<E15,J15>G15),"NG","OK")) | L15: =IF(J15="","",IF(J15<T15,"添加",IF(J15>U15,"稀釋",""))) | M15: =IFERROR(IF(J15<T15,"P500A："&ROUND(((T15-J15)*S15/1000),1)&" L",IF(J15>U15,"排藥："&ROUND((J15-U15)/J15*S15,1)&" L"&" 補水："&ROUND((J15-U15)/J15*S15,1)&" L","")),"") | P15: =IF(N15="","",7.24*N15*F值!$B$3) | Q15: =IF(P15="","",IF(OR(P15<E15,P15>G15),"NG","OK")) | R15: P500A | S15: 600 | T15: 100 | U15: 110
C16: SnCl2 (g/L) | D16: < 0.3 | E16: 0 | F16: ~ | G16: 0.3 | J16: =IF(H16="","",2.256*H16*F值!$B$9) | K16: =IF(J16="","",IF(OR(J16<E16,J16>G16),"NG","OK")) | L16: =IF(J16="","",IF(J16>U16,"更槽","")) | P16: =IF(N16="","",2.256*N16*F值!$B$9) | Q16: =IF(P16="","",IF(OR(P16<E16,P16>G16),"NG","OK")) | R16: P500B | S16: 600 | T16: NA | U16: NA
B17: 化鎳 | C17: Ni (g/L) | D17: 4.8±0.2 | E17: 4.6 | F17: ~ | G17: 5 | J17: =IF(H17="","",0.59*H17*F值!$B$6) | K17: =IF(J17="","",IF(OR(J17<E17,J17>G17),"NG","OK")) | L17: =IF(J17="","",IF(J17<T17,"添加",IF(J17>U17,"稀釋",""))) | M17: =IFERROR(IF(J17<T17,"A劑："&ROUND(((T17-J17)*S17*9.2/1000),1)&" L",IF(J17>U17,"排藥："&ROUND((J17-U17)/J17*S17,1)&" L"&" 補水："&ROUND((J17-U17)/J17*S17,1)&" L","")),"") | P17: =IF(N17="","",0.59*N17*F值!$B$6) | Q17: =IF(P17="","",IF(OR(P17<E17,P17>G17),"NG","OK")) | R17: A劑 | S17: 1200 | T17: 4.8 | U17: 5
C18: NaH2PO2‧H2O (g/L) | D18: 18.5±1.5 | E18: 17 | F18: ~ | G18: 20 | J18: =IF(I18="","",(H18-I18)*2.65) | K18: =IF(J18="","",IF(OR(J18<E18,J18>G18),"NG","OK")) | L18: =IF(J18="","",IF(J18<T18,"添加",IF(J18>U18,"稀釋",""))) | M18: =IF(J18<T18,"A劑："&ROUND(((T18-J18)*S18*1.62/1000),1)&" L",IF(J18>U18,"排藥："&ROUND((J18-U18)/J18*S18,1)&" L"&" 補水："&ROUND((J18-U18)/J18*S18,1)&" L","")) | P18: =IF(O18="","",(N18-O18)*2.65) | Q18: =IF(P18="","",IF(OR(P18<E18,P18>G18),"NG","OK")) | R18: B劑 | S18: 1200 | T18: 18.5 | U18: NA
C19: Na2HPO3・5H2O (g/L) | D19: < 100 | E19: 0 | F19: ~ | G19: 100 | J19: =IF(I19="","",(H19-I19)*10.8) | K19: =IF(J19="","",IF(OR(J19<E19,J19>G19),"NG","OK")) | L19: =IF(J19="","",IF(J19>U19,"更槽","")) | P19: =IF(O19="","",(N19-O19)*10.8) | Q19: =IF(P19="","",IF(OR(P19<E19,P19>G19),"NG","OK")) | R19: D劑 | S19: 1200 | T19: NA | U19: NA
C20: PH | D20: 8.5±0.2 | E20: 8.3 | F20: ~ | G20: 8.7 | H20: - | K20: =IF(J20="","",IF(OR(J20<E20,J20>G20),"NG","OK")) | L20: =IF(J20="","",IF(J20>T20,"","添加")) | M20: =IF(J20="","",IF(J20<T20,"氨水："&ROUND(((T20-J20)*S20*16.5/1000),1)&" L","")) | N20: - | Q20: =IF(P20="","",IF(OR(P20<E20,P20>G20),"NG","OK")) | R20: 氨水 | S20: 1200 | T20: 8.5 | U20: NA
A21: 備註:
A25: QA-2-010-02A | C25: 核准： | I25: 確認：

Sheet C1
A2: 藥液分析日報表
A3: 線別 | B3: C1
A4: 日期
A5: 分析者 | M5: 複驗
A6: 線別 | B6: 槽位 | C6: 分析項目 | D6: 規格 | E6: 範圍 | H6: 滴定數(ml) | I6: 濃度 | J6: 判定 | K6: 調整 | L6: 添加量 | M6: 滴定數(ml) | N6: 濃度 | O6: 判定 | P6: 藥液 | Q6: 槽容(L) | R6: 添加管制值 | S6: 稀釋管制值
A7: 鍍銅線 (C1) | B7: 銅1 | C7: CHO (g/L) | D7: 185±20 | E7: 165 | F7: ~ | G7: 205 | I7: =IF(H7="","",H7*24.5*F值!$B$3) | J7: =IF(I7="","",IF(OR(I7<E7,I7>G7),"NG","OK")) | K7: =IF(I7="","",IF(I7<R7,"添加",IF(I7>S7,"稀釋",""))) | L7: =IFERROR(IF(I7<R7,"硫酸(50%)："&ROUND(((R7-I7)*Q7/0.714/1000),1)&" L",IF(I7>S7,"排藥："&ROUND((I7-S7)/I7*Q7,1)&" L"&" 補水："&ROUND((I7-S7)/I7*Q7,1)&" L","")),"") | N7: =IF(M7="","",M7*24.5*F值!$B$3) | O7: =IF(N7="","",IF(OR(N7<E7,N7>G7),"NG","OK")) | P7: 硫酸(50%) | Q7: 1900 | R7: 185 | S7: 205
C8: CuSO4‧5H2O (g/L) | D8: 55±10 | E8: 45 | F8: ~ | G8: 65 | I8: =IF(H8="","",H8*6.24*F值!$B$6) | J8: =IF(I8="","",IF(OR(I8<E8,I8>G8),"NG","OK")) | K8: =IF(I8="","",IF(I8<R8,"添加",IF(I8>S8,"稀釋",""))) | L8: =IFERROR(IF(I8<R8,"氧化銅粉："&ROUND(((R8-I8)*Q8/1000),1)&" Kg",IF(I8="","",IF(I8>S8,"通知工程師 ",""))),"") | N8: =IF(M8="","",M8*6.24*F值!$B$6) | O8: =IF(N8="","",IF(OR(N8<E8,N8>G8),"NG","OK")) | P8: 氧化銅粉 | Q8: 1900 | R8: 55 | S8: 65
C9: 氯離子(ppm) | D9: 45±15 | E9: 30 | F9: ~ | G9: 60 | I9: =IF(H9="","",H9*152) | J9: =IF(I9="","",IF(OR(I9<E9,I9>G9),"NG","OK")) | K9: =IF(I9="","",IF(I9<R9,"添加",IF(I9>S9,"稀釋",""))) | L9: =IF(I9<R9,"鹽酸38%："&ROUND((((R9-I9)/1000000)*Q9*0.36*1000),1)&" ml",IF(I9="","",IF(I9>S9,"通知工程師 ",""))) | N9: =IF(M9="","",M9*152) | O9: =IF(N9="","",IF(OR(N9<E9,N9>G9),"NG","OK")) | P9: 鹽酸38% | Q9: 1900 | R9: 45 | S9: 60
C10: S RF-A (ml/L) | D10: 15±5 | E10: 10 | F10: ~ | G10: 20 | H10: - | J10: =IF(I10="","",IF(OR(I10<E10,I10>G10),"NG","OK")) | K10: =IF(I10="","",IF(I10>R10,"","添加")) | M10: - | O10: =IF(N10="","",IF(OR(N10<E10,N10>G10),"NG","OK")) | P10: S RF-A | Q10: 1900 | R10: 15 | S10: 20
C11: S RF-B (ml/L) | D11: 1±0.5 | E11: 0.5 | F11: ~ | G11: 1.5 | H11: - | J11: =IF(I11="","",IF(OR(I11<E11,I11>G11),"NG","OK")) | K11: =IF(I11="","",IF(I11>R11,"","添加")) | M11: - | O11: =IF(N11="","",IF(OR(N11<E11,N11>G11),"NG","OK")) | P11: S RF-B | Q11: 1900 | R11: 1 | S11: 1.5
B12: 銅2 | C12: CHO (g/L) | D12: 150±20 | E12: 130 | F12: ~ | G12: 170 | I12: =IF(H12="","",H12*24.5*F值!$B$3) | J12: =IF(I12="","",IF(OR(I12<E12,I12>G12),"NG","OK")) | K12: =IF(I12="","",IF(I12<R12,"添加",IF(I12>S12,"稀釋",""))) | L12: =IFERROR(IF(I12<R12,"硫酸(50%)："&ROUND(((R12-I12)*Q12/0.714/1000),1)&" L",IF(I12>S12,"排藥："&ROUND((I12-S12)/I12*Q12,1)&" L"&" 加水："&ROUND((I12-S12)/I12*Q12,1)&" L","")),"") | N12: =IF(M12="","",M12*24.5*F值!$B$3) | O12: =IF(N12="","",IF(OR(N12<E12,N12>G12),"NG","OK")) | P12: 硫酸(50%) | Q12: 3800 | R12: 150 | S12: 170
C13: CuSO4‧5H2O (g/L) | D13: 120±10 | E13: 110 | F13: ~ | G13: 130 | I13: =IF(H13="","",H13*6.24*F值!$B$6) | J13: =IF(I13="","",IF(OR(I13<E13,I13>G13),"NG","OK")) | K13: =IF(I13="","",IF(I13<R13,"添加",IF(I13>S13,"稀釋",""))) | L13: =IFERROR(IF(I13<R13,"氧化銅粉："&ROUND(((R13-I13)*Q13/1000),1)&" Kg",IF(I13="","",IF(I13>S13,"通知工程師 ",""))),"") | N13: =IF(M13="","",M13*6.24*F值!$B$6) | O13: =IF(N13="","",IF(OR(N13<E13,N13>G13),"NG","OK")) | P13: 氧化銅粉 | Q13: 3800 | R13: 120 | S13: 130
C14: 氯離子(ppm) | D14: 45±15 | E14: 30 | F14: ~ | G14: 60 | I14: =IF(H14="","",H14*152) | J14: =IF(I14="","",IF(OR(I14<E14,I14>G14),"NG","OK")) | K14: =IF(I14="","",IF(I14<R14,"添加",IF(I14>S14,"稀釋",""))) | L14: =IFERROR(IF(I14<R14,"鹽酸(38%)："&ROUND((((R14-I14)/1000000)*Q14*0.36*1000),1)&" ml",IF(I14="","",IF(I14>S14,"通知工程師 ",""))),"") | N14: =IF(M14="","",M14*152) | O14: =IF(N14="","",IF(OR(N14<E14,N14>G14),"NG","OK")) | P14: 鹽酸(38%) | Q14: 3800 | R14: 45 | S14: 60
C15: S RF-A (ml/L) | D15: 15±5 | E15: 10 | F15: ~ | G15: 20 | H15: - | J15: =IF(I15="","",IF(OR(I15<E15,I15>G15),"NG","OK")) | K15: =IF(I15="","",IF(I15>R15,"","添加")) | M15: - | O15: =IF(N15="","",IF(OR(N15<E15,N15>G15),"NG","OK")) | P15: S RF-A | Q15: 3800 | R15: 15 | S15: 20
C16: S RF-B (ml/L) | D16: 1±0.5 | E16: 0.5 | F16: ~ | G16: 1.5 | H16: - | J16: =IF(I16="","",IF(OR(I16<E16,I16>G16),"NG","OK")) | K16: =IF(I16="","",IF(I16>R16,"","添加")) | M16: - | O16: =IF(N16="","",IF(OR(N16<E16,N16>G16),"NG","OK")) | P16: S RF-B | Q16: 3800 | R16: 1 | S16: 1.5
A17: 備註:
A21: QA-2-010-02A | C21: 核准： | H21: 確認：

Sheet C3
A2: 藥液分析日報表
A3: 線別 | B3: C3
A4: 日期
A5: 分析者 | M5: 複驗
A6: 線別 | B6: 槽位 | C6: 分析項目 | D6: 規格 | E6: 範圍 | H6: 滴定數(ml) | I6: 濃度 | J6: 判定 | K6: 調整 | L6: 調整量 | M6: 滴定數(ml) | N6: 濃度 | O6: 判定 | P6: 藥液 | Q6: 槽容 | R6: 添加管制值 | S6: 稀釋管制值
A7: 鍍銅線 (C3) | B7: 清潔槽 | C7: CHO (ml/L) | D7: 20±5 | E7: 15 | F7: ~ | G7: 25 | I7: =IF(H7="","",H7*6.2*F值!$B$3) | J7: =IF(I7="","",IF(OR(I7<E7,I7>G7),"NG","OK")) | K7: =IF(I7="","",IF(I7<R7,"添加",IF(I7>S7,"稀釋",""))) | L7: =IFERROR(IF(I7>S7,"排液："&ROUND(664*(1-20/I7),0)&" L"&" 補水："&ROUND(664*(1-20/I7),0)&" L",IF(I7<R7,"硫酸："&ROUND((20-I7)*664/1000/0.5,1)&" L","")),"") | N7: =IF(M7="","",M7*6.2*F值!$B$3) | O7: =IF(N7="","",IF(OR(N7<E7,N7>G7),"NG","OK")) | P7: 硫酸 | Q7: 664 | R7: 18 | S7: 23
B8: 酸浸槽 | C8: 硫酸 (ml/L) | D8: 6±2 | E8: 4 | F8: ~ | G8: 8 | I8: =IF(H8="","",H8*2.663*F值!$B$3) | J8: =IF(I8="","",IF(OR(I8<E8,I8>G8),"NG","OK")) | K8: =IF(I8="","",IF(I8<R8,"添加",IF(I8>S8,"稀釋",""))) | L8: =IFERROR(IF(I8>S8,"排液："&ROUND(664*(1-5/I8),0)&" L"&" 補水："&ROUND(664*(1-5/I8),0)&" L",IF(I8<R8,"硫酸："&ROUND((5-I8)*664/100/0.5,1)&" L","")),"") | N8: =IF(M8="","",M8*2.663*F值!$B$3) | O8: =IF(N8="","",IF(OR(N8<E8,N8>G8),"NG","OK")) | P8: 硫酸 | Q8: 664 | R8: 4 | S8: 6
B9: 鍍銅槽 | C9: 硫酸 | D9: 180±20 | E9: 160 | F9: ~ | G9: 200 | I9: =IF(H9="","",H9*24.5*F值!$B$3) | J9: =IF(I9="","",IF(OR(I9<E9,I9>G9),"NG","OK")) | K9: =IF(I9="","",IF(I9<R9,"添加",IF(I9>S9,"稀釋",""))) | L9: =IFERROR(IF(I9>S9,"排液："&ROUND(7000*(1-180/I9),0)&" L"&" 補水："&ROUND(7000*(1-180/I9),0)&" L",IF(I9<R9,"硫酸："&ROUND((180-I9)*7000/1400/0.5,1)&" L","")),"") | N9: =IF(M9="","",M9*24.5*F值!$B$3) | O9: =IF(N9="","",IF(OR(N9<E9,N9>G9),"NG","OK")) | P9: 硫酸 | Q9: 7000 | R9: 160 | S9: 200
C10: 銅離子 | D10: 100±15 | E10: 85 | F10: ~ | G10: 115 | I10: =IF(H10="","",H10*6.25*F值!$B$6) | J10: =IF(I10="","",IF(OR(I10<E10,I10>G10),"NG","OK")) | K10: =IF(I10="","",IF(I10<R10,"添加",IF(I10>S10,"稀釋",""))) | L10: =IFERROR(IF(I10>S10,"排液："&ROUND(7000*(1-100/I10),0)&" Kg"&" 補水："&ROUND(7000*(1-100/I10),0)&" Kg",IF(I10<R10,"氧化銅："&ROUND((100-I10)*7000/1000/0.799*0.9,1)&" Kg","")),"") | N10: =IF(M10="","",M10*6.25*F值!$B$6) | O10: =IF(N10="","",IF(OR(N10<E10,N10>G10),"NG","OK")) | P10: 氧化銅粉 | Q10: 7000 | R10: 85 | S10: 115
C11: 氯離子 | D11: 50±10 | E11: 40 | F11: ~ | G11: 60 | I11: =IF(H11="","",H11*152) | J11: =IF(I11="","",IF(OR(I11<E11,I11>G11),"NG","OK")) | K11: =IF(I11="","",IF(I11<R11,"添加",IF(I11>S11,"稀釋",""))) | L11: =IFERROR(IF(I11>S11,"排液："&ROUND(7000*(1-50/I11),0)&" L"&" 補水："&ROUND(7000*(1-50/I11),0)&" L",IF(I11<R11,"鹽酸："&ROUND((50-I11)/0.0573,0)&" mL","")),"") | N11: =IF(M11="","",M11*152) | O11: =IF(N11="","",IF(OR(N11<E11,N11>G11),"NG","OK")) | P11: 鹽酸 | Q11: 7000 | R11: 40 | S11: 60
C12: SF | D12: 10±2 | E12: 8 | F12: ~ | G12: 12 | H12: - | J12: =IF(I12="","",IF(OR(I12<E12,I12>G12),"NG","OK")) | K12: =IF(I12="","",IF(I12<R12,"添加",IF(I12>S12,"稀釋",""))) | L12: =IF(I12="","",IF(I12>S12,"排液："&ROUND(7000*(1-10/I12),0)&" L"&" 補水："&ROUND(7000*(1-10/I12),0)&" L",IF(I12<R12,"51SF："&ROUND((10-I12)*7000/1000,1)&" L",""))) | M12: - | O12: =IF(N12="","",IF(OR(N12<E12,N12>G12),"NG","OK")) | P12: 51SF | Q12: 7000 | R12: 8 | S12: 12
C13: STB | D13: 1±0.3 | E13: 0.7 | F13: ~ | G13: 1.3 | H13: - | J13: =IF(I13="","",IF(OR(I13<E13,I13>G13),"NG","OK")) | K13: =IF(I13="","",IF(I13<R13,"添加",IF(I13>S13,"稀釋",""))) | L13: =IF(I13="","",IF(I13>S13,"排液："&ROUND(7000*(1-1/I13),0)&" L"&" 補水："&ROUND(7000*(1-1/I13),0)&" L",IF(I13<R13,"STB："&ROUND((1-I13)*7000,1)&" mL",""))) | M13: - | O13: =IF(N13="","",IF(OR(N13<E13,N13>G13),"NG","OK")) | P13: STB | Q13: 7000 | R13: 0.7 | S13: 1.3
B14: 剝掛槽 | C14: 硫酸 | D14: 150±50 | E14: 100 | F14: ~ | G14: 200 | I14: =IF(H14="","",H14*24.5*F值!$B$3) | J14: =IF(I14="","",IF(OR(I14<E14,I14>G14),"NG","OK")) | K14: =IF(I14="","",IF(I14<R14,"添加",IF(I14>S14,"稀釋",""))) | L14: =IFERROR(IF(I14>S14,"排液："&ROUND(813*(1-150/I14),0)&" L"&" 補水："&ROUND(813*(1-150/I14),0)&" L",IF(I14<R14,"硫酸："&ROUND((150-I14)*813/1400/0.5,1)&" L","")),"") | N14: =IF(M14="","",M14*24.5*F值!$B$3) | O14: =IF(N14="","",IF(OR(N14<E14,N14>G14),"NG","OK")) | P14: 硫酸 | Q14: 813 | R14: 100 | S14: 200
C15: 雙氧水 | D15: 140±20 | E15: 120 | F15: ~ | G15: 160 | I15: =IF(H15="","",H15*9.714*F值!$B$7) | J15: =IF(I15="","",IF(OR(I15<E15,I15>G15),"NG","OK")) | K15: =IF(I15="","",IF(I15<R15,"添加",IF(I15>S15,"稀釋",""))) | L15: =IFERROR(IF(I15>S15,"排液："&ROUND(813*(1-140/I15),0)&" L"&" 補水："&ROUND(813*(1-140/I15),0)&" L",IF(I15<R15,"雙氧水："&ROUND((140-I15)*813/1140,1)&" L","")),"") | N15: =IF(M15="","",M15*9.714*F值!$B$7) | O15: =IF(N15="","",IF(OR(N15<E15,N15>G15),"NG","OK")) | P15: 雙氧水 | Q15: 813 | R15: 120 | S15: 160
C16: 銅離子 | D16: < 100 | E16: 0 | F16: ~ | G16: 100 | I16: =IF(H16="","",H16*6.354*F值!$B$6) | J16: =IF(I16="","",IF(OR(I16<E16,I16>G16),"NG","OK")) | K16: =IF(I16="","",IF(I16>S16,"更槽","")) | N16: =IF(M16="","",M16*6.354*F值!$B$6) | O16: =IF(N16="","",IF(OR(N16<E16,N16>G16),"NG","OK")) | P16: NA | Q16: 813 | R16: NA | S16: 100
A17: 備註:
A21: QA-2-010-02A | C21: 核准： | H21: 確認：

Sheet C5
A2: 藥液分析日報表
A3: 線別 | B3: C5
A4: 日期
A5: 分析者 | M5: 複驗
A6: 線別 | B6: 槽位 | C6: 分析項目 | D6: 規格 | E6: 範圍 | H6: 滴定數(ml) | I6: 濃度 | J6: 判定 | K6: 調整 | L6: 調整量 | M6: 滴定數(ml) | N6: 濃度 | O6: 判定 | P6: 藥液 | Q6: 槽容 | R6: 添加管制值 | S6: 稀釋管制值
A7: 鍍銅線 (C5) | B7: 清潔槽 | C7: DP333 (ml/L) | D7: 100±20 | E7: 80 | F7: ~ | G7: 120 | I7: =IF(H7="","",H7*8.48*F值!$B$3) | J7: =IF(I7="","",IF(OR(I7<E7,I7>G7),"NG","OK")) | K7: =IF(I7="","",IF(I7<R7,"添加",IF(I7>S7,"稀釋",""))) | L7: =IFERROR(IF(I7>S7,"排液："&ROUND(1100*(1-100/I7),0)&" L"&" 補水："&ROUND(1100*(1-100/I7),0)&" L",IF(I7<R7,"DP333："&ROUND((100-I7)*1100/1000,1)&" L","")),"") | N7: =IF(M7="","",M7*8.48*F值!$B$3) | O7: =IF(N7="","",IF(OR(N7<E7,N7>G7),"NG","OK")) | P7: DP333 | Q7: 1100 | R7: 80 | S7: 120
B8: 酸浸槽 | C8: 硫酸 (%) | D8: 5±1 | E8: 4 | F8: ~ | G8: 6 | I8: =IF(H8="","",H8*2.663*F值!$B$3) | J8: =IF(I8="","",IF(OR(I8<E8,I8>G8),"NG","OK")) | K8: =IF(I8="","",IF(I8<R8,"添加",IF(I8>S8,"稀釋",""))) | L8: =IFERROR(IF(I8>S8,"排液："&ROUND(600*(1-5/I8),0)&" L"&" 補水："&ROUND(600*(1-5/I8),0)&" L",IF(I8<R8,"硫酸："&ROUND((5-I8)*600/100/0.5,1)&" L","")),"") | N8: =IF(M8="","",M8*2.663*F值!$B$3) | O8: =IF(N8="","",IF(OR(N8<E8,N8>G8),"NG","OK")) | P8: 硫酸 | Q8: 600 | R8: 4 | S8: 6
B9: 鍍銅槽 | C9: 硫酸 | D9: 100±10 | E9: 90 | F9: ~ | G9: 110 | I9: =IF(H9="","",H9*24.5*F值!$B$6) | J9: =IF(I9="","",IF(OR(I9<E9,I9>G9),"NG","OK")) | K9: =IF(I9="","",IF(I9<R9,"添加",IF(I9>S9,"稀釋",""))) | L9: =IFERROR(IF(I9>S9,"排液："&ROUND(14700*(1-100/I9),0)&" L"&" 補水："&ROUND(14700*(1-100/I9),0)&" L",IF(I9<R9,"硫酸："&ROUND((100-I9)*14700/1400/0.5,1)&" L","")),"") | N9: =IF(M9="","",M9*24.5*F值!$B$6) | O9: =IF(N9="","",IF(OR(N9<E9,N9>G9),"NG","OK")) | P9: 硫酸 | Q9: 14700 | R9: 90 | S9: 110
C10: 銅離子 | D10: 200±10 | E10: 190 | F10: ~ | G10: 210 | I10: =IF(H10="","",H10*6.25*F值!$B$6) | J10: =IF(I10="","",IF(OR(I10<E10,I10>G10),"NG","OK")) | K10: =IF(I10="","",IF(I10<R10,"添加",IF(I10>S10,"稀釋",""))) | L10: =IFERROR(IF(I10>S10,"排液："&ROUND(14700*(1-200/I10),0)&" Kg"&" 補水："&ROUND(14700*(1-200/I10),0)&" Kg",IF(I10<R10,"氧化銅："&ROUND((200-I10)*14700/1000/0.799*0.9,1)&" Kg","")),"") | N10: =IF(M10="","",M10*6.25*F值!$B$6) | O10: =IF(N10="","",IF(OR(N10<E10,N10>G10),"NG","OK")) | P10: 氧化銅粉 | Q10: 14700 | R10: 190 | S10: 210
C11: 氯離子 | D11: 30±5 | E11: 25 | F11: ~ | G11: 35 | I11: =IF(H11="","",H11*152) | J11: =IF(I11="","",IF(OR(I11<E11,I11>G11),"NG","OK")) | K11: =IF(I11="","",IF(I11<R11,"添加",IF(I11>S11,"稀釋",""))) | L11: =IFERROR(IF(I11>S11,"排液："&ROUND(14700*(1-30/I11),0)&" L"&" 補水："&ROUND(14700*(1-30/I11),0)&" L",IF(I11<R11,"鹽酸："&ROUND((30-I11)/0.0573,0)&" mL","")),"") | N11: =IF(M11="","",M11*152) | O11: =IF(N11="","",IF(OR(N11<E11,N11>G11),"NG","OK")) | P11: 鹽酸 | Q11: 14700 | R11: 25 | S11: 35
C12: GAP-1 | D12: 4±2 | E12: 2 | F12: ~ | G12: 6 | H12: - | J12: =IF(I12="","",IF(OR(I12<E12,I12>G12),"NG","OK")) | K12: =IF(I12="","",IF(I12<R12,"添加",IF(I12>S12,"稀釋",""))) | L12: =IF(K12="","",IF(I12>S12,"排液："&ROUND(14700*(1-4/I12),0)&" L"&" 補水："&ROUND(14700*(1-4/I12),0)&" L",IF(I12<R12,"GAP-1："&ROUND((4-I12)*14700/1000,1)&" L",""))) | M12: - | O12: =IF(N12="","",IF(OR(N12<E12,N12>G12),"NG","OK")) | P12: GAP-1 | Q12: 14700 | R12: 2 | S12: 6
C13: GAP-2 | D13: 3±1 | E13: 2 | F13: ~ | G13: 4 | H13: - | J13: =IF(I13="","",IF(OR(I13<E13,I13>G13),"NG","OK")) | K13: =IF(I13="","",IF(I13<R13,"添加",IF(I13>S13,"稀釋",""))) | L13: =IF(K13="","",IF(I13>S13,"排液："&ROUND(14700*(1-3/I13),0)&" L"&" 補水："&ROUND(14700*(1-3/I13),0)&" L",IF(I13<R13,"GAP-2："&ROUND((3-I13)*14700/1000,1)&" L",""))) | M13: - | O13: =IF(N13="","",IF(OR(N13<E13,N13>G13),"NG","OK")) | P13: GAP-2 | Q13: 14700 | R13: 2 | S13: 4
C14: GAP-3 | D14: 12±3 | E14: 9 | F14: ~ | G14: 15 | H14: - | J14: =IF(I14="","",IF(OR(I14<E14,I14>G14),"NG","OK")) | K14: =IF(I14="","",IF(I14<R14,"添加",IF(I14>S14,"稀釋",""))) | L14: =IF(K14="","",IF(I14>S14,"排液："&ROUND(14700*(1-12/I14),0)&" L"&" 補水："&ROUND(14700*(1-12/I14),0)&" L",IF(I14<R14,"GAP-3："&ROUND((12-I14)*14700/1000,1)&" L",""))) | M14: - | O14: =IF(N14="","",IF(OR(N14<E14,N14>G14),"NG","OK")) | P14: GAP-3 | Q14: 14700 | R14: 9 | S14: 15
B15: 剝掛槽 | C15: 硫酸 | D15: 150±50 | E15: 100 | F15: ~ | G15: 200 | I15: =IF(H15="","",H15*24.5*F值!$B$3) | J15: =IF(I15="","",IF(OR(I15<E15,I15>G15),"NG","OK")) | K15: =IF(I15="","",IF(I15<R15,"添加",IF(I15>S15,"稀釋",""))) | L15: =IFERROR(IF(I15>S15,"排液："&ROUND(430*(1-150/I15),0)&" L"&" 補水："&ROUND(430*(1-150/I15),0)&" L",IF(I15<R15,"硫酸："&ROUND((150-I15)*430/1400/0.5,1)&" L","")),"") | N15: =IF(M15="","",M15*24.5*F值!$B$3) | O15: =IF(N15="","",IF(OR(N15<E15,N15>G15),"NG","OK")) | P15: 硫酸 | Q15: 430 | R15: 100 | S15: 200
C16: 雙氧水 | D16: 140±20 | E16: 120 | F16: ~ | G16: 160 | I16: =IF(H16="","",H16*9.714*F值!$B$7) | J16: =IF(I16="","",IF(OR(I16<E16,I16>G16),"NG","OK")) | K16: =IF(I16="","",IF(I16<R16,"添加",IF(I16>S16,"稀釋",""))) | L16: =IFERROR(IF(I16>S16,"排液："&ROUND(430*(1-140/I16),0)&" L"&" 補水："&ROUND(430*(1-140/I16),0)&" L",IF(I16<R16,"雙氧水："&ROUND((140-I16)*430/1140,1)&" L","")),"") | N16: =IF(M16="","",M16*9.714*F值!$B$7) | O16: =IF(N16="","",IF(OR(N16<E16,N16>G16),"NG","OK")) | P16: 雙氧水 | Q16: 430 | R16: 120 | S16: 160
C17: 銅離子 | D17: < 100 | E17: 0 | F17: ~ | G17: 100 | I17: =IF(H17="","",H17*6.354*F值!$B$3) | J17: =IF(I17="","",IF(OR(I17<E17,I17>G17),"NG","OK")) | K17: =IF(I17="","",IF(I17>S17,"更槽","")) | N17: =IF(M17="","",M17*6.354*F值!$B$3) | O17: =IF(N17="","",IF(OR(N17<E17,N17>G17),"NG","OK")) | P17: NA | Q17: 430 | R17: NA | S17: 100
A18: 備註:
A22: QA-2-010-02A | C22: 核准： | H22: 確認：

Sheet DP
A2: 藥液分析日報表
A3: 線別 | B3: DP
A4: 日期
A5: 分析者 | M5: 複驗 | T5: 工程變更
A6: 線別 | B6: 槽位 | C6: 分析項目 | D6: 規格 | E6: 範圍 | H6: 滴定數(ml) | I6: 濃度 | J6: 判定 | K6: 調整 | L6: 調整量 | M6: 滴定數(ml) | N6: 濃度 | O6: 判定 | P6: 藥液 | Q6: 槽容 | R6: 添加管制值 | S6: 稀釋管制值 | T6: ECR編號 | U6: 申請日期 | V6: 截止日期
A7: 除鈀線 (DP) | B7: 除鈀槽 | C7: 主劑 (%) | D7: 275±125 | E7: 150 | F7: ~ | G7: 400 | I7: =IF(H7="","",(25-H7)*13.3) | J7: =IF(I7="","",IF(OR(I7<E7,I7>G7),"NG","OK")) | K7: =IF(I7="","",IF(I7<R7,"添加",IF(I7>S7,"稀釋",""))) | L7: =IFERROR(IF(I7>S7,"排液："&ROUND(600*(1-S7/I7),0)&" L"&" 補水："&ROUND(600*(1-S7/I7),0)&" L",IF(I7<R7,"OPC PARRADELETE："&ROUND((240-I7)*600/1000,1)&" L","")),"") | N7: =IF(M7="","",(25-M7)*13.3) | O7: =IF(N7="","",IF(OR(N7<E7,N7>G7),"NG","OK")) | P7: OPC PARRADELETE | Q7: 600 | R7: 220 | S7: 260
C8: SPS (g/L) | D8: 0.55±0.25 | E8: 0.3 | F8: ~ | G8: 0.8 | I8: =IF(H8="","",H8*0.93) | J8: =IF(I8="","",IF(OR(I8<E8,I8>G8),"NG","OK")) | K8: =IF(I8="","",IF(I8<R8,"添加",IF(I8>S8,"稀釋",""))) | L8: =IFERROR(IF(I8>S8,"排液："&ROUND(600*(1-S8/I8),0)&" L"&" 補水："&ROUND(600*(1-S8/I8),0)&" L",IF(I8<R8,"SPS："&ROUND((0.55-I8)*600,1)&" g","")),"") | N8: =IF(M8="","",M8*0.93) | O8: =IF(N8="","",IF(OR(N8<E8,N8>G8),"NG","OK")) | P8: SPS | Q8: 600 | R8: 0.4 | S8: 0.8
C9: 曝氣 | D9: - | H9: - | T9: ECR-2603001 | U9: 46086 | V9: 46203
C10: 打氣 | D10: - | H10: - | T10: ECR-2603001 | U10: 46086 | V10: 46203
C11: PH | D11: 10±0.2 | E11: 9.8 | F11: ~ | G11: 10.2 | H11: - | J11: =IF(I11="","",IF(OR(I11<E11,I11>G11),"NG","OK")) | K11: =IF(I11="","",IF(I11<R11,"添加",IF(I11>S11,"稀釋",""))) | L11: =IFERROR(IF(I11>S11,"排液："&ROUND(600*(1-S11/I11),0)&" L，補水："&ROUND(600*(1-S11/I11),0)&" L",IF(I11="","",IF(I11<R11,"NaOH："&ROUND((10-I11)*600*10,1)&" ml",""))),"") | M11: - | O11: =IF(N11="","",IF(OR(N11<E11,N11>G11),"NG","OK")) | P11: NaOH | Q11: 600 | R11: 9.9 | S11: 10.15
B12: 清潔槽 | C12: 鹼洗 (%) | D12: 100±20 | E12: 80 | F12: ~ | G12: 120 | I12: =IF(H12="","",H12*7.5*4*F值!$B$3) | J12: =IF(I12="","",IF(OR(I12<E12,I12>G12),"NG","OK")) | K12: =IF(I12="","",IF(I12<R12,"添加",IF(I12>S12,"稀釋",""))) | L12: =IFERROR(IF(I12>S12,"排液："&ROUND(500*(1-S12/I12),0)&" L"&" 補水："&ROUND(500*(1-S12/I12),0)&" L",IF(I12<R12,"OPC PARRARINSE："&ROUND((100-I12)*500/500,1)&" L","")),"") | N12: =IF(M12="","",M12*7.5*4*F值!$B$3) | O12: =IF(N12="","",IF(OR(N12<E12,N12>G12),"NG","OK")) | P12: OPC PARRARINSE | Q12: 500 | R12: 90 | S12: 119
B13: 酸洗槽 | C13: 酸洗 (%) | D13: 5±1 | E13: 4 | F13: ~ | G13: 6 | I13: =IF(H13="","",H13*3.2*F值!$B$7) | J13: =IF(I13="","",IF(OR(I13<E13,I13>G13),"NG","OK")) | K13: =IF(I13="","",IF(I13<R13,"添加",IF(I13>S13,"稀釋",""))) | L13: =IFERROR(IF(I13>S13,"排液："&ROUND(70*(1-S13/I13),0)&" L"&" 補水："&ROUND(70*(1-S13/I13),0)&" L",IF(I13<R13,"硫酸(50%)："&ROUND((5-I13)/0.5,0)&"L","")),"") | N13: =IF(M13="","",M13*3.2*F值!$B$7) | O13: =IF(N13="","",IF(OR(N13<E13,N13>G13),"NG","OK")) | P13: 硫酸(50%) | Q13: 70 | R13: 4.5 | S13: 5.9
B14: 抗氧化 | C14: PH | D14: > 5 | E14: 5 | F14: ~ | G14: 999 | H14: - | J14: =IF(I14="","",IF(OR(I14<E14,I14>G14),"NG","OK")) | K14: =IF(I14="","",IF(I14<R14,"更槽","")) | M14: - | O14: =IF(N14="","",IF(OR(N14<E14,N14>G14),"NG","OK")) | P14: GC | Q14: 400 | R14: 5 | S14: 7
A15: 備註:
A19: QA-2-010-02A | C19: 核准： | H19: 確認：

Sheet 舊線
A2: 藥液分析日報表
A3: 線別 | B3: 舊線
A4: 日期
A5: 分析者 | M5: 複驗
A6: 線別 | B6: 槽位 | C6: 分析項目 | D6: 規格 | E6: 範圍 | H6: 滴定數(ml) | I6: 濃度 | J6: 判定 | K6: 調整 | L6: 調整量 | M6: 滴定數(ml) | N6: 濃度 | O6: 判定 | P6: 藥液 | Q6: 槽容(L) | R6: 添加管制值 | S6: 稀釋管制值
A7: 粗化線 (PT) | B7: 脫脂槽 Degreasing | C7: CHO (%) | D7: 3±1 | E7: 2 | F7: ~ | G7: 4 | I7: =IF(H7="","",3.2*H7*F值!$B$3) | J7: =IF(I7="","",IF(OR(I7<E7,I7>G7),"NG","OK")) | K7: =IF(I7="","",IF(I7<R7,"添加",IF(I7>S7,"稀釋",""))) | L7: =IFERROR(IF(I7>S7, "排液："&ROUND(70*(1-3/I7)*0.5,1)&" L"&" 補水："&ROUND(70*(1-3/I7)*0.5,1)&" L", IF(I7<R7, "藥液(50%)："&ROUND(((3-I7)*70/100)/0.5, 2)&" L", "")), "") | N7: =IF(M7="","",3.2*M7*F值!$B$3) | O7: =IF(N7="","",IF(OR(N7<E7,N7>G7),"NG","OK")) | P7: 硫酸(50%) | Q7: 70 | R7: 2.5 | S7: 3.9
B8: 銅 Copper | C8: 銅離子 (g/L) | D8: < 42 | E8: 0 | F8: ~ | G8: 42 | I8: =IF(H8="","",3.177*H8*F值!$B$6) | J8: =IF(I8="","",IF(OR(I8<E8,I8>G8),"NG","OK")) | K8: =IF(I8="","",IF(I8<R8,"添加",IF(I8>S8,"稀釋",""))) | L8: =IFERROR(IF(I8>S8, "排液："&ROUND(300*(1-39/I8), 0)&" L"&" 補UT-4100RC(RC:水 4:1)："&ROUND(300*(1-39/I8), 0)&" L", IF(I8<R8, "UT-4100M："&ROUND(((39-I8)*300/1000), 2)&" L", "")), "") | N8: =IF(M8="","",3.177*M8*F值!$B$6) | O8: =IF(N8="","",IF(OR(N8<E8,N8>G8),"NG","OK")) | P8: UT4100-M UT4100-RC | Q8: 300 | R8: 37 | S8: 42
C9: 比重 | D9: 1.1±0.05 | E9: 1.05 | F9: ~ | G9: 1.15 | H9: - | J9: =IF(I9="","",IF(OR(I9<E9,I9>G9),"NG","OK")) | K9: =IF(I9="","",IF(I9<R9,"添加",IF(I9>S9,"稀釋",""))) | L9: =IFERROR(IF(I9>S9, "排液："&ROUND(400*(1-1.07/I9), 0)&" L"&" 補UT-4100RC(RC:水 4:1)："&ROUND(400*(1-1.07/I9), 0)&" L",IF(I9="","", IF(I9<R9, "UT-4100M："&ROUND(((1.07-I9)*400), 2)&" L", ""))), "") | M9: - | O9: =IF(N9="","",IF(OR(N9<E9,N9>G9),"NG","OK")) | R9: 1.07 | S9: 1.13
B10: 鹽酸洗 HCL | C10: CHO (%) | D10: 3±1 | E10: 2 | F10: ~ | G10: 4 | I10: =IF(H10="","",3.2*H10*F值!$B$3) | J10: =IF(I10="","",IF(OR(I10<E10,I10>G10),"NG","OK")) | K10: =IF(I10="","",IF(I10<R10,"添加",IF(I10>S10,"稀釋",""))) | L10: =IFERROR(IF(I10>S10, "排液："&ROUND(70*(1-3/I10)*0.32,1)&" L"&" 補水："&ROUND(70*(1-3/I10)*0.32,1)&" L", IF(I10<R10, "鹽酸(32%)："&ROUND(((3-I10)*70/100)/0.32, 2)&" L", "")), "") | N10: =IF(M10="","",3.2*M10*F值!$B$3) | O10: =IF(N10="","",IF(OR(N10<E10,N10>G10),"NG","OK")) | P10: 鹽酸(32%) | Q10: 70 | R10: 2.5 | S10: 3.9
C11: 銅離子 (g/L) | D11: < 300 | E11: 0 | F11: ~ | G11: 300 | I11: =IF(H11="","",H11*1.5885*2/25*1000) | J11: =IF(I11="","",IF(OR(I11<E11,I11>G11),"NG","OK")) | K11: =IF(I11="","",IF(I11>S11,"更槽","")) | N11: =IF(M11="","",M11*1.5885*2/25*1000) | O11: =IF(N11="","",IF(OR(N11<E11,N11>G11),"NG","OK")) | R11: NA | S11: 300
B12: 抗氧化 Anti-oxidation | C12: PH | D12: > 5 | E12: 5 | F12: ~ | G12: 999 | H12: - | J12: =IF(I12="","",IF(OR(I12<E12,I12>G12),"NG","OK")) | K12: =IF(I12="","",IF(I12<S12,"更槽","")) | M12: - | O12: =IF(N12="","",IF(OR(N12<E12,N12>G12),"NG","OK")) | P12: GS | Q12: 70 | R12: NA | S12: 5
A13: 顯影線 (DV) | B13: 液洗 Liquid washing | C13: 碳酸鈉 (%) | D13: 1±0.2 | E13: 0.8 | F13: ~ | G13: 1.2 | I13: =IF(H13="","",0.0212*4*H13*F值!$B$5) | J13: =IF(I13="","",IF(OR(I13<E13,I13>G13),"NG","OK")) | K13: =IF(I13="","",IF(I13<R13,"添加",IF(I13>S13,"稀釋",""))) | L13: =IFERROR(IF(I13>S13, "排液："&ROUND(340*(1-1/I13), 0)&" L"&" 補水："&ROUND(340*(1-1/I13), 0)&" L", IF(I13<R13, "碳酸鈉(15%)："&ROUND(((1-I13)*340/100)/0.15, 1)&" L", "")), "") | N13: =IF(M13="","",0.0212*4*M13*F值!$B$5) | O13: =IF(N13="","",IF(OR(N13<E13,N13>G13),"NG","OK")) | P13: 碳酸鈉(15%) | Q13: 600 | R13: 0.9 | S13: 1.1
C14: PH | D14: > 10.7 | E14: 10.7 | F14: ~ | G14: 999 | H14: - | J14: =IF(I14="","",IF(OR(I14<E14,I14>G14),"NG","OK")) | K14: =IF(I14="","",IF(I14<S14,"更槽","")) | M14: - | O14: =IF(N14="","",IF(OR(N14<E14,N14>G14),"NG","OK")) | R14: NA | S14: 10.7
B15: 新液洗 New liquid washing | C15: 碳酸鈉 (%) | D15: 1±0.2 | E15: 0.8 | F15: ~ | G15: 1.2 | I15: =IF(H15="","",0.0212*4*H15*F值!$B$5) | J15: =IF(I15="","",IF(OR(I15<E15,I15>G15),"NG","OK")) | K15: =IF(I15="","",IF(I15<R15,"添加",IF(I15>S15,"稀釋",""))) | L15: =IFERROR(IF(I15>S15, "排液："&ROUND(100*(1-1/I15), 0)&" L"&" 補水："&ROUND(100*(1-1/I15), 0)&" L", IF(I15<R15, "碳酸鈉(15%)："&ROUND(((1-I15)*100/100)/0.15, 1)&" L", "")), "") | N15: =IF(M15="","",0.0212*4*M15*F值!$B$5) | O15: =IF(N15="","",IF(OR(N15<E15,N15>G15),"NG","OK")) | P15: 碳酸鈉(15%) | Q15: 160 | R15: 0.9 | S15: 1.1
C16: PH | D16: > 10.7 | E16: 10.7 | F16: ~ | G16: 999 | H16: - | J16: =IF(I16="","",IF(OR(I16<E16,I16>G16),"NG","OK")) | K16: =IF(I16="","",IF(I16<S16,"更槽","")) | M16: - | O16: =IF(N16="","",IF(OR(N16<E16,N16>G16),"NG","OK")) | R16: NA | S16: 10.7
A17: 剝膜線 (ST) | B17: 剝膜 (1) 槽 Stripping Tank (1) | C17: HO (%) | D17: 12±2 | E17: 10 | F17: ~ | G17: 14 | I17: =IF(H17="","",H17/5*6.98*F值!$B$5) | J17: =IF(I17="","",IF(OR(I17<E17,I17>G17),"NG","OK")) | K17: =IF(I17="","",IF(I17<R17,"添加",IF(I17>S17,"稀釋",""))) | L17: =IFERROR(IF(I17>S17, "排液："&ROUND(540*(1-12/I17), 0)&" L"&" 補水："&ROUND(540*(1-12/I17), 0)&" L", IF(I17<R17, "CXW-PS318(A/B)："&ROUND(((12-I17)*540/100/2), 1)&" L", "")), "") | N17: =IF(M17="","",M17/5*6.98*F值!$B$5) | O17: =IF(N17="","",IF(OR(N17<E17,N17>G17),"NG","OK")) | P17: CXW-PS318(A/B) | Q17: 540 | R17: 11 | S17: 13.9
B18: 剝膜 (2) 槽Stripping Tank (2) | C18: HO (%) | D18: 12±2 | E18: 10 | F18: ~ | G18: 14 | I18: =IF(H18="","",H18/5*6.98*F值!$B$5) | J18: =IF(I18="","",IF(OR(I18<E18,I18>G18),"NG","OK")) | K18: =IF(I18="","",IF(I18<R18,"添加",IF(I18>S18,"稀釋",""))) | L18: =IFERROR(IF(I18>S18, "排液："&ROUND(160*(1-12/I18), 0)&" L"&" 補水："&ROUND(160*(1-12/I18), 0)&" L", IF(I18<R18, "CXW-PS318(A/B)："&ROUND(((12-I18)*160/100/2), 1)&" L", "")), "") | N18: =IF(M18="","",M18/5*6.98*F值!$B$5) | O18: =IF(N18="","",IF(OR(N18<E18,N18>G18),"NG","OK")) | P18: CXW-PS318(A/B) | Q18: 160 | R18: 11 | S18: 13.9
B19: 硫酸洗 H2SO4 | C19: CHO (%) | D19: 5±1 | E19: 4 | F19: ~ | G19: 6 | I19: =IF(H19="","",3.2*H19*F值!$B$3) | J19: =IF(I19="","",IF(OR(I19<E19,I19>G19),"NG","OK")) | K19: =IF(I19="","",IF(I19<R19,"添加",IF(I19>S19,"稀釋",""))) | L19: =IFERROR(IF(I19>S19, "排液："&ROUND(60*(1-5/I19)*0.5,1)&" L"&" 補水："&ROUND(60*(1-5/I19)*0.5,1)&" L", IF(I19<R19, "硫酸(50%)："&ROUND(((5-I19)*60/100)/0.5, 1)&" L", "")), "") | N19: =IF(M19="","",3.2*M19*F值!$B$3) | O19: =IF(N19="","",IF(OR(N19<E19,N19>G19),"NG","OK")) | P19: 硫酸(50%) | Q19: 60 | R19: 4.5 | S19: 5.95
B20: 剝膜 添加桶 Resist Stripping Additive Tank | C20: HO (%) | D20: 12±2 | E20: 10 | F20: ~ | G20: 14 | I20: =IF(H20="","",H20/5*6.98*F值!$B$5) | J20: =IF(I20="","",IF(OR(I20<E20,I20>G20),"NG","OK")) | K20: =IF(I20="","",IF(I20<R20,"添加",IF(I20>S20,"稀釋",""))) | L20: =IFERROR(IF(I20>S20, "排液："&ROUND(100*(1-12/I20), 0)&" L"&" 補水："&ROUND(100*(1-12/I20), 0)&" L", IF(I20<R20, "CXW-PS318(A/B)："&ROUND(((12-I20)*100/100/2), 1)&" L", "")), "") | N20: =IF(M20="","",M20/5*6.98*F值!$B$5) | O20: =IF(N20="","",IF(OR(N20<E20,N20>G20),"NG","OK")) | P20: CXW-PS318(A/B) | Q20: 100 | R20: 11 | S20: 13.9
B21: 剝膜 小槽Resist Stripping Small Tank | C21: HO (%) | D21: 12±2 | E21: 10 | F21: ~ | G21: 14 | I21: =IF(H21="","",H21/5*6.98*F值!$B$6) | J21: =IF(I21="","",IF(OR(I21<E21,I21>G21),"NG","OK")) | K21: =IF(I21="","",IF(I21<R21,"添加",IF(I21>S21,"稀釋",""))) | L21: =IFERROR(IF(I21>S21, "排液："&ROUND(100*(1-12/I21), 0)&" L"&" 補水："&ROUND(100*(1-12/I21), 0)&" L", IF(I21<R21, "CXW-PS318(A/B)："&ROUND(((12-I21)*100/100/2), 1)&" L", "")), "") | N21: =IF(M21="","",M21/5*6.98*F值!$B$6) | O21: =IF(N21="","",IF(OR(N21<E21,N21>G21),"NG","OK")) | P21: CXW-PS318(A/B) | Q21: 100 | R21: 11 | S21: 13.9
A22: 快蝕線 (QE) | B22: 蝕刻主槽 Main Etching Tank | C22: 酸 (%) | D22: 3±1 | E22: 2 | F22: ~ | G22: 4 | I22: =IF(H22="","",2.7*H22/5*F值!$B$3) | J22: =IF(I22="","",IF(OR(I22<E22,I22>G22),"NG","OK")) | K22: =IF(I22="","",IF(I22<R22,"添加",IF(I22>S22,"稀釋",""))) | L22: =IFERROR(IF(I22>S22, "排液："&ROUND(650*(1-3/I22)*0.5,1)&" L"&" 補水："&ROUND(650*(1-3/I22)*0.5,1)&" L", IF(I22<R22, "硫酸(50%)："&ROUND(((3-I22)*650/100)/0.5, 2)&" L", "")), "") | N22: =IF(M22="","",2.7*M22/5*F值!$B$3) | O22: =IF(N22="","",IF(OR(N22<E22,N22>G22),"NG","OK")) | P22: 硫酸(50%) | Q22: 650 | R22: 2.5 | S22: 3.8
C23: 銅離子 (g/L) | D23: 22.5±12.5 | E23: 10 | F23: ~ | G23: 35 | I23: =IF(H23="","",3.18*H23*F值!$B$6) | J23: =IF(I23="","",IF(OR(I23<E23,I23>G23),"NG","OK")) | K23: =IF(I23="","",IF(I23<R23,"添加",IF(I23>S23,"稀釋",""))) | L23: =IFERROR(IF(I23>S23, "排液："&ROUND(650*(1-25/I23)*0.5,1)&" L"&" 補水："&ROUND(650*(1-25/I23)*0.5,1)&" L", IF(I23<R23, "CuSO4．5H2O："&ROUND(((25-I23)*650/100)/0.5, 2)&" L", "")), "") | N23: =IF(M23="","",3.18*M23*F值!$B$6) | O23: =IF(N23="","",IF(OR(N23<E23,N23>G23),"NG","OK")) | P23: CuSO4．5H2O | R23: 11 | S23: 34
C24: 雙氧水 (%) | D24: 6±1.5 | E24: 4.5 | F24: ~ | G24: 7.5 | I24: =IF(H24="","",0.428*2*H24*F值!$B$7) | J24: =IF(I24="","",IF(OR(I24<E24,I24>G24),"NG","OK")) | K24: =IF(I24="","",IF(I24<R24,"添加",IF(I24>S24,"稀釋",""))) | L24: =IFERROR(IF(I24>S24, "排液："&ROUND(650*(1-6/I24)*0.5,1)&" L"&" 補水："&ROUND(650*(1-6/I24)*0.5,1)&" L", IF(I24<R24, "H2O2："&ROUND(((6-I24)*650/100)/0.5, 2)&" L", "")), "") | N24: =IF(M24="","",0.428*2*M24*F值!$B$7) | O24: =IF(N24="","",IF(OR(N24<E24,N24>G24),"NG","OK")) | P24: H2O2 | R24: 5.5 | S24: 7.4
B25: 硫酸洗 H2SO4 | C25: CHO (%) | D25: 5±1 | E25: 4 | F25: ~ | G25: 6 | I25: =IF(H25="","",3.2*H25*F值!$B$3) | J25: =IF(I25="","",IF(OR(I25<E25,I25>G25),"NG","OK")) | K25: =IF(I25="","",IF(I25<R25,"添加",IF(I25>S25,"稀釋",""))) | L25: =IFERROR(IF(I25>S25, "排液："&ROUND(55*(1-5/I25)*0.5,1)&" L"&" 補水："&ROUND(55*(1-5/I25)*0.5,1)&" L", IF(I25<R25, "硫酸(50%)："&ROUND(((5-I25)*55/100)/0.5, 2)&" L", "")), "") | N25: =IF(M25="","",3.2*M25*F值!$B$3) | O25: =IF(N25="","",IF(OR(N25<E25,N25>G25),"NG","OK")) | P25: 硫酸(50%) | Q25: 55 | R25: 4.5 | S25: 5.9
B26: 抗氧化 Anti-oxidation | C26: PH | D26: > 5 | E26: 5 | F26: ~ | G26: 999 | H26: - | J26: =IF(I26="","",IF(OR(I26<E26,I26>G26),"NG","OK")) | K26: =IF(I26="","",IF(I26>R26,"","更槽")) | M26: - | O26: =IF(N26="","",IF(OR(N26<E26,N26>G26),"NG","OK")) | P26: GC | Q26: 70 | R26: 5 | S26: NA
A27: 備註:
A31: QA-2-010-02A | C31: 核准： | H31: 確認：

Sheet 新線
A2: 藥液分析日報表
A3: 線別 | B3: 新線
A4: 日期
A5: 分析者 | M5: 複驗 | T5: 工程變更
A6: 線別 | B6: 槽位 | C6: 分析項目 | D6: 規格 | E6: 範圍 | H6: 滴定數(ml) | I6: 濃度 | J6: 判定 | K6: 調整 | L6: 調整量 | M6: 滴定數(ml) | N6: 濃度 | O6: 判定 | P6: 藥液 | Q6: 槽容(L) | R6: 添加管制值 | S6: 稀釋管制值 | T6: ECR編號 | U6: 申請日期 | V6: 截止日期
A7: 粗化線 (PT2) | B7: 脫脂槽 Degreasing | C7: CHO (%) | D7: 3±1 | E7: 2 | F7: ~ | G7: 4 | I7: =IF(H7="","",3.2*H7*F值!$B$3) | J7: =IF(I7="","",IF(OR(I7<E7,I7>G7),"NG","OK")) | K7: =IF(I7="","",IF(I7<R7,"添加",IF(I7>S7,"稀釋",""))) | L7: =IFERROR(IF(I7>S7, "排液："&ROUND(120*(1-3.2/I7)*0.5,1)&" L"&" 補水："&ROUND(120*(1-3.2/I7)*0.5,1)&" L", IF(I7<R7, "硫酸50%："&ROUND(((3.2-I7)*120/100)/0.5, 2)&" L", "")), "") | N7: =IF(M7="","",3.2*M7*F值!$B$3) | O7: =IF(N7="","",IF(OR(N7<E7,N7>G7),"NG","OK")) | P7: 硫酸50% | Q7: 120 | R7: 2.5 | S7: 3.9
B8: 銅 Copper | C8: 銅離子 (g/L) | D8: < 42 | E8: 0 | F8: ~ | G8: 42 | I8: =IF(H8="","",3.177*H8*F值!$B$6) | J8: =IF(I8="","",IF(OR(I8<E8,I8>G8),"NG","OK")) | K8: =IF(I8="","",IF(I8<R8,"添加",IF(I8>S8,"稀釋",""))) | L8: =IFERROR(IF(I8>S8, "排液："&ROUND(400*(1-39/I8), 0)&" L"&" 補CS3302R："&ROUND(400*(1-39/I8), 0)&" L", IF(I8<R8, "CS-3302M："&ROUND(((39-I8)*400/1000), 2)&" L", "")), "") | N8: =IF(M8="","",3.177*M8*F值!$B$6) | O8: =IF(N8="","",IF(OR(N8<E8,N8>G8),"NG","OK")) | P8: CS-3202M CS-3202R | Q8: 400 | R8: 12 | S8: 22
C9: 比重 | D9: 1.1±0.05 | E9: 1.05 | F9: ~ | G9: 1.15 | H9: - | J9: =IF(I9="","",IF(OR(I9<E9,I9>G9),"NG","OK")) | K9: =IF(I9="","",IF(I9<R9,"添加",IF(I9>S9,"稀釋",""))) | L9: =IFERROR(IF(I9>S9, "排液："&ROUND(400*(1-1.07/I9), 0)&" L"&" 補CS3302R："&ROUND(400*(1-1.07/I9), 0)&" L", IF(I9="","",IF(I9<R9, "CS-3302M："&ROUND(((1.07-I9)*400), 2)&" L", ""))), "") | M9: - | O9: =IF(N9="","",IF(OR(N9<E9,N9>G9),"NG","OK")) | R9: 1.07 | S9: 1.13
B10: 鹽酸洗 HCL | C10: CHO (%) | D10: 3±1 | E10: 2 | F10: ~ | G10: 4 | I10: =IF(H10="","",3.2*H10*F值!$B$3) | J10: =IF(I10="","",IF(OR(I10<E10,I10>G10),"NG","OK")) | K10: =IF(I10="","",IF(I10<R10,"添加",IF(I10>S10,"稀釋",""))) | L10: =IFERROR(IF(I10>S10, "排液："&ROUND(120*(1-3.2/I10)*0.32,1)&" L"&" 補水："&ROUND(120*(1-3.2/I10)*0.32,1)&" L", IF(I10<R10, "鹽酸50%："&ROUND(((3.2-I10)*120/100)/0.32, 2)&" L", "")), "") | N10: =IF(M10="","",3.2*M10*F值!$B$3) | O10: =IF(N10="","",IF(OR(N10<E10,N10>G10),"NG","OK")) | P10: HCL | Q10: 120 | R10: 2.5 | S10: 3.9
C11: 銅離子 (g/L) | D11: < 300 | E11: 0 | F11: ~ | G11: 300 | I11: =IF(H11="","",H11*1.5885*2/25*1000) | J11: =IF(I11="","",IF(OR(I11<E11,I11>G11),"NG","OK")) | K11: =IF(I11="","",IF(I11>S11,"更槽","")) | N11: =IF(M11="","",M11*1.5885*2/25*1000) | O11: =IF(N11="","",IF(OR(N11<E11,N11>G11),"NG","OK")) | R11: NA | S11: 300
B12: 抗氧化 Anti-oxidation | C12: PH | D12: > 5 | E12: 5 | F12: ~ | G12: 999 | H12: - | J12: =IF(I12="","",IF(OR(I12<E12,I12>G12),"NG","OK")) | K12: =IF(I12="","",IF(I12<S12,"更槽","")) | M12: - | O12: =IF(N12="","",IF(OR(N12<E12,N12>G12),"NG","OK")) | P12: GC | Q12: 120 | R12: NA | S12: 5
A13: 顯影線 (DV2) | B13: 液洗 Liquid washing | C13: 碳酸鈉 (%) | D13: 1±0.2 | E13: 0.8 | F13: ~ | G13: 1.2 | I13: =IF(H13="","",0.0212*4*H13*F值!$B$5) | J13: =IF(I13="","",IF(OR(I13<E13,I13>G13),"NG","OK")) | K13: =IF(I13="","",IF(I13<R13,"添加",IF(I13>S13,"稀釋",""))) | L13: =IFERROR(IF(I13>S13, "排液："&ROUND(600*(1-1/I13), 0)&" L"&" 補水："&ROUND(600*(1-1/I13), 0)&" L", IF(I13<R13, "碳酸鈉(15%)："&ROUND(((1-I13)*600/100)/0.15, 2)&" L", "")), "") | N13: =IF(M13="","",0.0212*4*M13*F值!$B$5) | O13: =IF(N13="","",IF(OR(N13<E13,N13>G13),"NG","OK")) | P13: 碳酸鈉(15%) | Q13: 600 | R13: 0.9 | S13: 1.15
C14: PH | D14: > 10.7 | E14: 10.7 | F14: ~ | G14: 999 | H14: - | J14: =IF(I14="","",IF(OR(I14<E14,I14>G14),"NG","OK")) | K14: =IF(I14="","",IF(I14<S14,"更槽","")) | M14: - | O14: =IF(N14="","",IF(OR(N14<E14,N14>G14),"NG","OK")) | R14: NA | S14: 10.7
B15: 新液洗 New liquid washing | C15: 碳酸鈉 (%) | D15: 1±0.2 | E15: 0.8 | F15: ~ | G15: 1.2 | I15: =IF(H15="","",0.0212*4*H15*F值!$B$5) | J15: =IF(I15="","",IF(OR(I15<E15,I15>G15),"NG","OK")) | K15: =IF(I15="","",IF(I15<R15,"添加",IF(I15>S15,"稀釋",""))) | L15: =IFERROR(IF(I15>S15, "排液："&ROUND(160*(1-1/I15), 0)&" L"&" 補水："&ROUND(160*(1-1/I15), 0)&" L", IF(I15<R15, "碳酸鈉(15%)："&ROUND(((1-I15)*160/100)/0.15, 2)&" L", "")), "") | N15: =IF(M15="","",0.0212*4*M15*F值!$B$5) | O15: =IF(N15="","",IF(OR(N15<E15,N15>G15),"NG","OK")) | P15: 碳酸鈉(15%) | Q15: 160 | R15: 0.9 | S15: 1.15
C16: PH | D16: > 10.7 | E16: 10.7 | F16: ~ | G16: 999 | H16: - | J16: =IF(I16="","",IF(OR(I16<E16,I16>G16),"NG","OK")) | K16: =IF(I16="","",IF(I16<S16,"更槽","")) | M16: - | O16: =IF(N16="","",IF(OR(N16<E16,N16>G16),"NG","OK")) | R16: NA | S16: 10.7
A17: 剝膜線 (ST2) | B17: 剝膜 (1) 槽 Stripping Tank (1) | C17: HO (%) | D17: 15±2 | E17: 13 | F17: ~ | G17: 17 | I17: =IF(H17="","",H17/5*11.45*F值!$B$5) | J17: =IF(I17="","",IF(OR(I17<E17,I17>G17),"NG","OK")) | K17: =IF(I17="","",IF(I17<R17,"添加",IF(I17>S17,"稀釋",""))) | L17: =IFERROR(IF(I17>S17, "排液：" & ROUND(Q17*(1-I2/I17),0) & " L", IF(I17<R17, "CXW-PS318(A)：" & ROUND(((15-I17)/15)*Q17*10%,0) & " L" & " CXW-PS318(B)：" & ROUND(((15-I17)/15)*Q17*5%,0) & " L", "")),"") | N17: =IF(M17="","",M17/5*11.45*F值!$B$5) | O17: =IF(N17="","",IF(OR(N17<E17,N17>G17),"NG","OK")) | P17: CXW-PS318(A/B) | Q17: 900 | R17: 14 | S17: 16.9 | T17: ECR-2604004 | U17: 46146 | V17: 46234
B18: 剝膜 (2) 槽 Stripping Tank (2) | C18: HO (%) | D18: 15±2 | E18: 13 | F18: ~ | G18: 17 | I18: =IF(H18="","",H18/5*11.45*F值!$B$5) | J18: =IF(I18="","",IF(OR(I18<E18,I18>G18),"NG","OK")) | K18: =IF(I18="","",IF(I18<R18,"添加",IF(I18>S18,"稀釋",""))) | L18: =IFERROR(IF(I18>S18,"排液：" & ROUND(Q18*(1-I3/I18),0) & " L",IF(I18<R18,"CXW-PS318(A): " & ROUND(((15-I18)/15)*Q18*10%,0) & " L" &" CXW-PS318(B): " & ROUND(((15-I18)/15)*Q18*5%,0) & " L","")),"") | N18: =IF(M18="","",M18/5*11.45*F值!$B$5) | O18: =IF(N18="","",IF(OR(N18<E18,N18>G18),"NG","OK")) | P18: CXW-PS318(A/B) | Q18: 1250 | R18: 14 | S18: 16.9 | T18: ECR-2604004 | U18: 46146 | V18: 46234
B19: 剝膜 (3) 槽 Stripping Tank (3) | C19: HO (%) | D19: 15±2 | E19: 13 | F19: ~ | G19: 17 | I19: =IF(H19="","",H19/5*11.45*F值!$B$5) | J19: =IF(I19="","",IF(OR(I19<E19,I19>G19),"NG","OK")) | K19: =IF(I19="","",IF(I19<R19,"添加",IF(I19>S19,"稀釋",""))) | L19: =IFERROR(IF(I19>S19,"排液：" & ROUND(Q19*(1-I4/I19),0) & " L",IF(I19<R19,"CXW-PS318(A)：" & ROUND(((15-I19)/15)*Q19*10%,0) & " L" &" CXW-PS318(B)：" & ROUND(((15-I19)/15)*Q19*5%,0) & " L","")),"") | N19: =IF(M19="","",M19/5*11.45*F值!$B$5) | O19: =IF(N19="","",IF(OR(N19<E19,N19>G19),"NG","OK")) | P19: CXW-PS318(A/B) | Q19: 350 | R19: 14 | S19: 16.9 | T19: ECR-2604004 | U19: 46146 | V19: 46234
B20: 硫酸洗(4) H2SO3 | C20: CHO (%) | D20: 5±1 | E20: 4 | F20: ~ | G20: 6 | I20: =IF(H20="","",H20*3.2*F值!$B$3) | J20: =IF(I20="","",IF(OR(I20<E20,I20>G20),"NG","OK")) | K20: =IF(I20="","",IF(I20<R20,"添加",IF(I20>S20,"稀釋",""))) | L20: =IFERROR(IF(I20>S20, "排液："&ROUND(250*(1-5/I20)*0.5,1)&" L" &" 補水："&ROUND(250*(1-5/I20)*0.5,1)&" L", IF(I20<R20, "硫酸(50%)："&ROUND(((5-I20)*250/100)/0.5, 1)&" L", "")), "") | N20: =IF(M20="","",M20*3.2*F值!$B$3) | O20: =IF(N20="","",IF(OR(N20<E20,N20>G20),"NG","OK")) | P20: 硫酸(50%) | Q20: 250 | R20: 4.5 | S20: 5.9
B21: 剝膜 添加桶(5) Resist Stripping Additive Tank(5) | C21: HO (%) | D21: 15±2 | E21: 13 | F21: ~ | G21: 17 | I21: =IF(H21="","",H21/5*11.45*F值!$B$5) | J21: =IF(I21="","",IF(OR(I21<E21,I21>G21),"NG","OK")) | L21: =IFERROR(IF(I21>S21,"排液：" & ROUND(Q21*(1-I6/I21),0) & " L",IF(I21<R21,"CXW-PS318(A)：" & ROUND(((15-I21)/15)*Q21*10%,0) & " L" &" CXW-PS318(B)：" & ROUND(((15-I21)/15)*Q21*5%,0) & " L","")),"") | N21: =IF(M21="","",M21/5*11.45*F值!$B$5) | O21: =IF(N21="","",IF(OR(N21<E21,N21>G21),"NG","OK")) | P21: CXW-PS318(A/B) | Q21: 150 | R21: 14 | S21: 16.9 | T21: ECR-2604004 | U21: 46146 | V21: 46234
B22: 剝膜 添加桶(6) Resist Stripping Additive Tank(6) | C22: HO (%) | D22: 15±2 | E22: 13 | F22: ~ | G22: 17 | I22: =IF(H22="","",H22/5*11.45*F值!$B$5) | J22: =IF(I22="","",IF(OR(I22<E22,I22>G22),"NG","OK")) | K22: =IF(I22="","",IF(I22<R22,"添加",IF(I22>S22,"稀釋",""))) | L22: =IFERROR(IF(I22>S22,"排液：" & ROUND(Q22*(1-I7/I22),0) & " L",IF(I22<R22,"CXW-PS318(A)：" & ROUND(((15-I22)/15)*Q22*10%,0) & " L" &" CXW-PS318(B)：" & ROUND(((15-I22)/15)*Q22*5%,0) & " L","")),"") | N22: =IF(M22="","",M22/5*11.45*F值!$B$5) | O22: =IF(N22="","",IF(OR(N22<E22,N22>G22),"NG","OK")) | P22: CXW-PS318(A/B) | Q22: 150 | R22: 14 | S22: 16.9 | T22: ECR-2604004 | U22: 46146 | V22: 46234
A23: 快蝕線 (QE2) | B23: 蝕刻主槽(銅) Main Etching Tank | C23: 酸 (%) | D23: 3±1 | E23: 2 | F23: ~ | G23: 4 | I23: =IF(H23="","",2.7*H23/5*F值!$B$3) | J23: =IF(I23="","",IF(OR(I23<E23,I23>G23),"NG","OK")) | K23: =IF(I23="","",IF(I23<R23,"添加",IF(I23>S23,"稀釋",""))) | L23: =IFERROR(IF(I23>S23, "排液："&ROUND(1050*(1-3/I23)*0.5,1)&" L"&" 補水："&ROUND(1050*(1-3/I23)*0.5,1)&" L", IF(I23<R23, "硫酸(50%)："&ROUND(((3-I23)*1050/100)/0.5, 2)&" L", "")), "") | N23: =IF(M23="","",2.7*M23/5*F值!$B$3) | O23: =IF(N23="","",IF(OR(N23<E23,N23>G23),"NG","OK")) | P23: 硫酸(50%) | Q23: 1050 | R23: 2.5 | S23: 3.8 | T23: ECR-2604007 | U23: 46146 | V23: 46234
C24: 銅離子 (g/L) | D24: 22.5±12.5 | E24: 10 | F24: ~ | G24: 35 | I24: =IF(H24="","",3.18*H24*F值!$B$6) | J24: =IF(I24="","",IF(OR(I24<E24,I24>G24),"NG","OK")) | K24: =IF(I24="","",IF(I24<R24,"添加",IF(I24>S24,"稀釋",""))) | L24: =IFERROR(IF(I24>S24, "排液："&ROUND(1050*(1-25/I24)*0.5,1)&" L"&" 補水："&ROUND(1050*(1-25/I24)*0.5,1)&" L", IF(I24<R24, "CuSO4．5H2O："&ROUND(((25-I24)*1050/100)/0.5, 2)&" L", "")), "") | N24: =IF(M24="","",3.18*M24*F值!$B$6) | O24: =IF(N24="","",IF(OR(N24<E24,N24>G24),"NG","OK")) | P24: CuSO4．5H2O | R24: 11 | S24: 34
C25: 雙氧水 (%) | D25: 5±1.5 | E25: 3.5 | F25: ~ | G25: 6.5 | I25: =IF(H25="","",0.428*2*H25*F值!$B$7) | J25: =IF(I25="","",IF(OR(I25<E25,I25>G25),"NG","OK")) | K25: =IF(I25="","",IF(I25<R25,"添加",IF(I25>S25,"稀釋",""))) | L25: =IFERROR(IF(I25>S25, "排液："&ROUND(1050*(1-5/I25)*0.5,1)&" L"&" 補水："&ROUND(1050*(1-5/I25)*0.5,1)&" L", IF(I25<R25, "CuSO4．5H2O："&ROUND(((5-I25)*1050/100)/0.5, 2)&" L", "")), "") | N25: =IF(M25="","",0.428*2*M25*F值!$B$7) | O25: =IF(N25="","",IF(OR(N25<E25,N25>G25),"NG","OK")) | P25: H2O2 | R25: 4 | S25: 6 | T25: ECR-2604007 | U25: 46146 | V25: 46234
